Workbook

Sheet Задание
B1: Занятие № | C1: 4
B2: группа | C2: ПМ-2541
B3: студент | C3: Петров ГА
B4: вариант | C4: 0
A6: 0 | B6: Авторизовать файл: | N6: ="Например: "&SUBSTITUTE(C2,"-","")&" "&RIGHT("0"&C1,2)&" "&SUBSTITUTE(SUBSTITUTE(C3,".","")," ","") -> Например: ПМ2541 04 ПетровГА
B7: - сохранить файл, дав ему название по шаблону: <Группа_без_тире> <номер_занятия_двумя_цифрами> <ФамилияИО>
B8: - исправить внутри файла группу и фамилию
B10: Тема: | C10: Регрессии с запаздыванием
B11: В предыдущей работе для прогнозирования по (обычной) регрессии требовались прогнозные (трендовые) значения факторов. Теперь получим прогнозы по регрессии без использования прогнозов по трендам.
B12: Задачи: | C12: - (обычная) авторегрессия
C13: - рефлексивная регрессия
C14: - множественная рефлексивная регрессия
B16: Порядок работы:
A17: Тренировочные примеры
A18: Авторегрессия (лист "AR") - рис.1 | J18: Структура таблицы на листе AR отличается от структуры на рисунах всвязи с изменеием длины исходных данных.
A19: 1 | B19: Из исходных данных взять [любой] один ряд, например ВВП. | J19: Если взят не ряд ВВП или ВДС - скорректировать разбиение на базу/горизонт
A20: 2 | B20: В качестве фактора использовать сдвинутую на k периодов копию этого ряда.
B21: - можно сдвинуть сами данные (пример)
B22: - можно сдвигать рамки аргументов в функции ТЕНДЕНЦИЯ
B23: - желательно при этом сделать из k управляющий параметр (см. предыдущую работу)
A24: 3 | B24: Построить авторегрессию и прогноз по ней на k периодов
A25: 4 | B25: Считая прогноз продолжением изучаемого ряда, продлить ряды для получения прогноза на 10 лет. | L25: Для отслеживания "эффектов" авторегрессии горизонт желательно иметь больше 2k.
A26: 5 | B26: Подбирая k, получить правдоподобный прогноз.
A27: 6 | B27: Записать выводы о влиянии k на прогноз.
A29: Рефлексивная регрессия (лист "Refl_R") - рис.2
A30: 1 | B30: Из исходных данных взять [любые] два ряда, например ВВП и Численность. | J30: Структуру таблицы на листе скорректировать с учётом актуальной длины исходных данных.
A31: 2 | B31: Построить две регрессии: каждого ряда к сдвинутому другому.
A32: 3 | B32: Считая прогноз продолжением изучаемых рядов, продлить ряды для получения прогноза на 10 лет.
A33: 4 | B33: Подбирая периоды сдвигов, получить правдоподобный прогноз.
A34: 5 | B34: Записать выводы.
A36: Основная модель
A37: Множественная рефлексивная регрессия (лист "Модель")
A38: рис.3:
A39: 1 | B39: Для всех 5 рядов исходных данных построить сдвинутые ряды на 1-3 года | J39: Структуру таблицы на листе скорректировать с учётом актуальной длины исходных данных.
A40: 2 | B40: Подбирая длину базы, для каждого исходного ряда найти 1-2 фактора среди сдвинутых рядов, такие - что:
B41: - в качестве фактора не может быть использована копия именно изучаемого ряда (т.е. исключается авторегрессия)
B42: - модуль корреляции исходного ряда и фактора должен быть бо́льшим
B43: - каждое явление (его сдвинутые ряды) должно быть фактором других явлений (на графе факторных зависимостей не должно быть стоков)
A44: рис.4:
A45: 3 | B45: Построить 5 регрессий и дать прогноз на период сдвига факторов
...

Sheet AR
D1: Вход | L1: Выход | N1: Осмысленность
L2: Точность | M2: Адекватность | N2: уд.влияние | O2: св.член
E3: лаг запаздывания влияния k= | F3: 5 | G3: Адекватный интервал прогноза | L3: R^2 | N3: 1 | O3: 2
L4: =CORREL(OFFSET($D$8,$F$3,0):$D$31,OFFSET($F$8,$F$3,0):$F$31)^2 -> 0.8432135 | M4: =PRODUCT(I32:I36) -> 0 | N4: {=INDEX(LINEST(OFFSET($D$8,$F$3,0):$D$31,OFFSET($E$8,$F$3,0):$E$31),N3)} -> 1.6566165 | O4: {=INDEX(LINEST(OFFSET($D$8,$F$3,0):$D$31,OFFSET($E$8,$F$3,0):$E$31),O3)} -> 714954.92
D5: Y | E5: X | F5: Y^ | G5: Y min | H5: X max | I5: Адекватность
B6: t | D6: Yt | E6: Yt+k | F6: f (X)
B7: № | C7: года | D7: ВВП | E7: =D7 & " t+" & F3 -> ВВП t+5 | F7: AR | G7: низ | H7: верх | L7: Функция
A8: база | B8: 1 | C8: 2002 | D8: 1523670.1 | E8: =IF(B8>$F$3,OFFSET(D8,-$F$3,0),"") | F8: {=IF(B8>$F$3,TREND(OFFSET($D$8,$F$3,0):$D$31,OFFSET($E$8,$F$3,0):$E$31,E8),"")} | G8: -1956201.5 | H8: 3739941.1 | L8: Таблицы подстановки
B9: 2 | C9: 2003 | D9: 1899714.3 | E9: =IF(B9>$F$3,OFFSET(D9,-$F$3,0),"") | F9: {=IF(B9>$F$3,TREND(OFFSET($D$8,$F$3,0):$D$31,OFFSET($E$8,$F$3,0):$E$31,E9),"")} | G9: -1286877.2 | H9: 4213046.8 | K9: k | L9: =L3 -> R^2 | M9: =M2 -> Адекватность | N9: =N2 -> уд.влияние | O9: =O2 -> св.член
B10: 3 | C10: 2004 | D10: 2271976.8 | E10: =IF(B10>$F$3,OFFSET(D10,-$F$3,0),"") | F10: {=IF(B10>$F$3,TREND(OFFSET($D$8,$F$3,0):$D$31,OFFSET($E$8,$F$3,0):$E$31,E10),"")} | G10: -580604.82 | H10: 4718164 | L10: =L4 -> 0.8432135 | M10: =M4 -> 0 | N10: =N4 -> 1.6566165 | O10: =O4 -> 714954.92
B11: 4 | C11: 2005 | D11: 2745199.6 | E11: =IF(B11>$F$3,OFFSET(D11,-$F$3,0),"") | F11: {=IF(B11>$F$3,TREND(OFFSET($D$8,$F$3,0):$D$31,OFFSET($E$8,$F$3,0):$E$31,E11),"")} | G11: 162595.71 | H11: 5258485.4 | K11: 1 | L11: 0.98924977 | M11: 0 | N11: 1.1445852 | O11: -143503.39
B12: 5 | C12: 2006 | D12: 3476075.5 | E12: =IF(B12>$F$3,OFFSET(D12,-$F$3,0),"") | F12: {=IF(B12>$F$3,TREND(OFFSET($D$8,$F$3,0):$D$31,OFFSET($E$8,$F$3,0):$E$31,E12),"")} | G12: 942176.77 | H12: 5837861.6 | K12: 2 | L12: 0.95944751 | M12: 0 | N12: 1.3257597 | O12: -428363.35
B13: 6 | C13: 2007 | D13: 4183589 | E13: =IF(B13>$F$3,OFFSET(D13,-$F$3,0),"") -> 1523670.1 | F13: {=IF(B13>$F$3,TREND(OFFSET($D$8,$F$3,0):$D$31,OFFSET($E$8,$F$3,0):$E$31,E13),"")} -> 3239092 | G13: 1756902.1 | H13: 6460967.4 | K13: 3 | L13: 0.911829 | M13: 0 | N13: 1.488461 | O13: -440471.51
B14: 7 | C14: 2008 | D14: 5380452.4 | E14: =IF(B14>$F$3,OFFSET(D14,-$F$3,0),"") -> 1899714.3 | F14: {=IF(B14>$F$3,TREND(OFFSET($D$8,$F$3,0):$D$31,OFFSET($E$8,$F$3,0):$E$31,E14),"")} -> 3862052.9 | G14: 2604677.3 | H14: 7133476 | K14: 4 | L14: 0.86498327 | M14: 0 | N14: 1.5918007 | O14: 24122.524
B15: 8 | C15: 2009 | D15: 5857652.2 | E15: =IF(B15>$F$3,OFFSET(D15,-$F$3,0),"") -> 2271976.8 | F15: {=IF(B15>$F$3,TREND(OFFSET($D$8,$F$3,0):$D$31,OFFSET($E$8,$F$3,0):$E$31,E15),"")} -> 4478749.1 | G15: 3482415.6 | H15: 7862198.9 | K15: 5 | L15: 0.8432135 | M15: 0 | N15: 1.6566165 | O15: 714954.92
B16: 9 | C16: 2010 | D16: 6511019.6 | E16: =IF(B16>$F$3,OFFSET(D16,-$F$3,0),"") -> 2745199.6 | F16: {=IF(B16>$F$3,TREND(OFFSET($D$8,$F$3,0):$D$31,OFFSET($E$8,$F$3,0):$E$31,E16),"")} -> 5262697.8 | G16: 4386021.8 | H16: 8655108 | K16: 6 | L16: 0.84376161 | M16: 0 | N16: 1.713076 | O16: 1444870.6
B17: 10 | C17: 2011 | D17: 7448243.4 | E17: =IF(B17>$F$3,OFFSET(D17,-$F$3,0),"") -> 3476075.5 | F17: {=IF(B17>$F$3,TREND(OFFSET($D$8,$F$3,0):$D$31,OFFSET($E$8,$F$3,0):$E$31,E17),"")} -> 6473478.9 | G17: 5310614.4 | H17: 9521118.2 | K17: 7 | L17: 0.85548717 | M17: 1 | N17: 1.7858641 | O17: 2075859.7
B18: 11 | C18: 2012 | D18: 8915955.3 | E18: =IF(B18>$F$3,OFFSET(D18,-$F$3,0),"") -> 4183589 | F18: {=IF(B18>$F$3,TREND(OFFSET($D$8,$F$3,0):$D$31,OFFSET($E$8,$F$3,0):$E$31,E18),"")} -> 7645557.5 | G18: 6251096.5 | H18: 10469524 | K18: 8 | L18: 0.85000093 | M18: 1 | N18: 1.876694 | O18: 2749277.3
B19: 12 | C19: 2013 | D19: 10017462 | E19: =IF(B19>$F$3,OFFSET(D19,-$F$3,0),"") -> 5380452.4 | F19: {=IF(B19>$F$3,TREND(OFFSET($D$8,$F$3,0):$D$31,OFFSET($E$8,$F$3,0):$E$31,E19),"")} -> 9628301 | G19: 7203056.2 | H19: 11509103 | K19: 9 | L19: 0.84645537 | M19: 1 | N19: 1.9881859 | O19: 3406550.7
B20: 13 | C20: 2014 | D20: 9925208.1 | E20: =IF(B20>$F$3,OFFSET(D20,-$F$3,0),"") -> 5857652.2 | F20: {=IF(B20>$F$3,TREND(OFFSET($D$8,$F$3,0):$D$31,OFFSET($E$8,$F$3,0):$E$31,E20),"")} -> 10418838 | G20: 8163748.2 | H20: 12647144 | K20: 10 | L20: 0.855967 | M20: 1 | N20: 2.1341664 | O20: 3957953.7
B21: 14 | C21: 2015 | D21: 10706582 | E21: =IF(B21>$F$3,OFFSET(D21,-$F$3,0),"") -> 6511019.6 | F21: {=IF(B21>$F$3,TREND(OFFSET($D$8,$F$3,0):$D$31,OFFSET($E$8,$F$3,0):$E$31,E21),"")} -> 11501217 | G21: 9132743.5 | H21: 13888801 | K21: 11 | L21: 0.89049145 | M21: 1 | N21: 2.3234125 | O21: 4312941.3
B22: 15 | C22: 2016 | D22: 11852882 | E22: =IF(B22>$F$3,OFFSET(D22,-$F$3,0),"") -> 7448243.4 | F22: {=IF(B22>$F$3,TREND(OFFSET($D$8,$F$3,0):$D$31,OFFSET($E$8,$F$3,0):$E$31,E22),"")} -> 13053838 | G22: 10111954 | H22: 15237079 | K22: 12 | L22: 0.92563835 | M22: 1 | N22: 2.5509266 | O22: 4617310.2
... B24: 17 | C24: 2018 | D24: 13515794 | E24: =IF(B24>$F$3,OFFSET(D24,-$F$3,0),"") -> 10017462 | F24: {=IF(B24>$F$3,TREND(OFFSET($D$8,$F$3,0):$D$31,OFFSET($E$8,$F$3,0):$E$31,E24),"")} -> 17310047 | G24: 12116896 | H24: 18258272 | K24: 14 | L24: 0.91810037 | M24: 0 | N24: 3.4026864 | O24: 4789806
B25: 18 | C25: 2019 | D25: 13615272 | E25: =IF(B25>$F$3,OFFSET(D25,-$F$3,0),"") -> 9925208.1 | F25: {=IF(B25>$F$3,TREND(OFFSET($D$8,$F$3,0):$D$31,OFFSET($E$8,$F$3,0):$E$31,E25),"")} -> 17157218 | G25: 13152465 | H25: 19932197
B26: 19 | C26: 2020 | D26: 14544326 | E26: =IF(B26>$F$3,OFFSET(D26,-$F$3,0),"") -> 10706582 | F26: {=IF(B26>$F$3,TREND(OFFSET($D$8,$F$3,0):$D$31,OFFSET($E$8,$F$3,0):$E$31,E26),"")} -> 18451655 | G26: 14216798 | H26: 21715899
B27: 20 | C27: 2021 | D27: 16406490 | E27: =IF(B27>$F$3,OFFSET(D27,-$F$3,0),"") -> 11852882 | F27: {=IF(B27>$F$3,TREND(OFFSET($D$8,$F$3,0):$D$31,OFFSET($E$8,$F$3,0):$E$31,E27),"")} -> 20350634 | G27: 15314593 | H27: 23610661
B28: 21 | C28: 2022 | D28: 19738623 | E28: =IF(B28>$F$3,OFFSET(D28,-$F$3,0),"") -> 12766003 | F28: {=IF(B28>$F$3,TREND(OFFSET($D$8,$F$3,0):$D$31,OFFSET($E$8,$F$3,0):$E$31,E28),"")} -> 21863325 | G28: 16450177 | H28: 25618370
B29: 22 | C29: 2023 | D29: 24340433 | E29: =IF(B29>$F$3,OFFSET(D29,-$F$3,0),"") -> 13515794 | F29: {=IF(B29>$F$3,TREND(OFFSET($D$8,$F$3,0):$D$31,OFFSET($E$8,$F$3,0):$E$31,E29),"")} -> 23105442 | G29: 17627529 | H29: 27741507
B30: 23 | C30: 2024 | D30: 29177254 | E30: =IF(B30>$F$3,OFFSET(D30,-$F$3,0),"") -> 13615272 | F30: {=IF(B30>$F$3,TREND(OFFSET($D$8,$F$3,0):$D$31,OFFSET($E$8,$F$3,0):$E$31,E30),"")} -> 23270239 | G30: 18850342 | H30: 29983098
B31: 24 | C31: 2025 | D31: 32463741 | E31: =IF(B31>$F$3,OFFSET(D31,-$F$3,0),"") -> 14544326 | F31: {=IF(B31>$F$3,TREND(OFFSET($D$8,$F$3,0):$D$31,OFFSET($E$8,$F$3,0):$E$31,E31),"")} -> 24809324 | G31: 20122083 | H31: 32346658
A32: горизонт | B32: 25 | C32: 2026 | E32: =IF(B32>$F$3,OFFSET(D32,-$F$3,0),"") -> 16406490 | F32: {=IF(B32>$F$3,TREND(OFFSET($D$8,$F$3,0):$D$31,OFFSET($E$8,$F$3,0):$E$31,E32),"")} -> 27894217 | G32: 21446056 | H32: 34836138 | I32: =IF(AND(F32>=G32,F32<=H32),1,0) -> 1
B33: 26 | C33: 2027 | E33: =IF(B33>$F$3,OFFSET(D33,-$F$3,0),"") -> 19738623 | F33: {=IF(B33>$F$3,TREND(OFFSET($D$8,$F$3,0):$D$31,OFFSET($E$8,$F$3,0):$E$31,E33),"")} -> 33414282 | G33: 22825458 | H33: 37455885 | I33: =IF(AND(F33>=G33,F33<=H33),1,0) -> 1
B34: 27 | C34: 2028 | E34: =IF(B34>$F$3,OFFSET(D34,-$F$3,0),"") -> 24340433 | F34: {=IF(B34>$F$3,TREND(OFFSET($D$8,$F$3,0):$D$31,OFFSET($E$8,$F$3,0):$E$31,E34),"")} -> 41037718 | G34: 24263420 | H34: 40210606 | I34: =IF(AND(F34>=G34,F34<=H34),1,0) -> 0
B35: 28 | C35: 2029 | E35: =IF(B35>$F$3,OFFSET(D35,-$F$3,0),"") -> 29177254 | F35: {=IF(B35>$F$3,TREND(OFFSET($D$8,$F$3,0):$D$31,OFFSET($E$8,$F$3,0):$E$31,E35),"")} -> 49050474 | G35: 25763045 | H35: 43105345 | I35: =IF(AND(F35>=G35,F35<=H35),1,0) -> 0
B36: 29 | C36: 2030 | E36: =IF(B36>$F$3,OFFSET(D36,-$F$3,0),"") -> 32463741 | F36: {=IF(B36>$F$3,TREND(OFFSET($D$8,$F$3,0):$D$31,OFFSET($E$8,$F$3,0):$E$31,E36),"")} -> 54494923 | G36: 27327436 | H36: 46145462 | I36: =IF(AND(F36>=G36,F36<=H36),1,0) -> 0
B37: 30 | C37: 2031 | E37: =IF(B37>$F$3,OFFSET(D37,-$F$3,0),"") -> 0 | F37: {=IF(B37>$F$3,TREND(OFFSET($D$8,$F$3,0):$D$31,OFFSET($E$8,$F$3,0):$E$31,E37),"")} -> 714954.92
B38: 31 | C38: 2032 | E38: =IF(B38>$F$3,OFFSET(D38,-$F$3,0),"") -> 0 | F38: {=IF(B38>$F$3,TREND(OFFSET($D$8,$F$3,0):$D$31,OFFSET($E$8,$F$3,0):$E$31,E38),"")} -> 714954.92
B39: 32 | C39: 2033 | E39: =IF(B39>$F$3,OFFSET(D39,-$F$3,0),"") -> 0 | F39: {=IF(B39>$F$3,TREND(OFFSET($D$8,$F$3,0):$D$31,OFFSET($E$8,$F$3,0):$E$31,E39),"")} -> 714954.92
B40: 33 | C40: 2034 | E40: =IF(B40>$F$3,OFFSET(D40,-$F$3,0),"") -> 0 | F40: {=IF(B40>$F$3,TREND(OFFSET($D$8,$F$3,0):$D$31,OFFSET($E$8,$F$3,0):$E$31,E40),"")} -> 714954.92
B41: 34 | C41: 2035 | E41: =IF(B41>$F$3,OFFSET(D41,-$F$3,0),"") -> 0 | F41: {=IF(B41>$F$3,TREND(OFFSET($D$8,$F$3,0):$D$31,OFFSET($E$8,$F$3,0):$E$31,E41),"")} -> 714954.92

Sheet Refl_R
L1: Выход
E3: лаги запаздывания влияния k1= | F3: 1 | I3: k2= | J3: 10 | M3: R^2
L4: Y^1 | M4: =CORREL(OFFSET($D$8,$F$3,0):$D$31,OFFSET($F$8,$F$3,0):$F$31)^2 -> 0.9760422
D5: Y1 | E5: X1 | F5: Y1^ | H5: Y2 | I5: X2 | J5: Y2^ | L5: Y^2 | M5: =CORREL(OFFSET($H$8,$J$3,0):$H$31,OFFSET($J$8,$J$3,0):$J$31)^2 -> 0.86532592
B6: t | D6: Vt | E6: Ct+k | F6: f (X1) | H6: Ct | I6: Vt+k | J6: f (X2) | L6: Итого | M6: =AVERAGE(M4:M5) -> 0.92068406
B7: № | C7: года | D7: =AR!D7 -> ВВП | E7: =H7 & " t+" & F3 -> ОФ t+1 | F7: =D7&"( "&E7&")" -> ВВП( ОФ t+1) | H7: ОФ | I7: =D7 & " t+" & J3 -> ВВП t+10 | J7: =H7&"( "&I7&")" -> ОФ( ВВП t+10)
A8: база | B8: 1 | C8: 2002 | D8: =AR!D8 -> 1523670.1 | E8: =IF(B8>$F$3,OFFSET(H8,-$F$3,0),"") | F8: {=IF(B8>$F$3,TREND(OFFSET($D$8,$F$3,0):$D$31,OFFSET($E$8,$F$3,0):$E$31,E8),"")} | H8: 663998.76 | I8: =IF(B8>$J$3,OFFSET(D8,-$J$3,0),"") | J8: {=IF(B8>$J$3,TREND(OFFSET($H$8,$J$3,0):$H$31,OFFSET($I$8,$J$3,0):$I$31,I8),"")} | L8: Функция
B9: 2 | C9: 2003 | D9: =AR!D9 -> 1899714.3 | E9: =IF(B9>$F$3,OFFSET(H9,-$F$3,0),"") -> 663998.76 | F9: {=IF(B9>$F$3,TREND(OFFSET($D$8,$F$3,0):$D$31,OFFSET($E$8,$F$3,0):$E$31,E9),"")} -> 2162803.2 | H9: 884858.7 | I9: =IF(B9>$J$3,OFFSET(D9,-$J$3,0),"") | J9: {=IF(B9>$J$3,TREND(OFFSET($H$8,$J$3,0):$H$31,OFFSET($I$8,$J$3,0):$I$31,I9),"")} | L9: Таблицы подстановки
B10: 3 | C10: 2004 | D10: =AR!D10 -> 2271976.8 | E10: =IF(B10>$F$3,OFFSET(H10,-$F$3,0),"") -> 884858.7 | F10: {=IF(B10>$F$3,TREND(OFFSET($D$8,$F$3,0):$D$31,OFFSET($E$8,$F$3,0):$E$31,E10),"")} -> 2506353.3 | H10: 1090317.1 | I10: =IF(B10>$J$3,OFFSET(D10,-$J$3,0),"") | J10: {=IF(B10>$J$3,TREND(OFFSET($H$8,$J$3,0):$H$31,OFFSET($I$8,$J$3,0):$I$31,I10),"")} | M10: k2
B11: 4 | C11: 2005 | D11: =AR!D11 -> 2745199.6 | E11: =IF(B11>$F$3,OFFSET(H11,-$F$3,0),"") -> 1090317.1 | F11: {=IF(B11>$F$3,TREND(OFFSET($D$8,$F$3,0):$D$31,OFFSET($E$8,$F$3,0):$E$31,E11),"")} -> 2825946.1 | H11: 1303045.7 | I11: =IF(B11>$J$3,OFFSET(D11,-$J$3,0),"") | J11: {=IF(B11>$J$3,TREND(OFFSET($H$8,$J$3,0):$H$31,OFFSET($I$8,$J$3,0):$I$31,I11),"")} | L11: =M6 -> 0.92068406 | M11: 1 | N11: 2 | O11: 3 | P11: 4 | Q11: 5 | R11: 6 | S11: 7 | T11: 8 | U11: 9 | V11: 10 | W11: 11 | X11: 12
B12: 5 | C12: 2006 | D12: =AR!D12 -> 3476075.5 | E12: =IF(B12>$F$3,OFFSET(H12,-$F$3,0),"") -> 1303045.7 | F12: {=IF(B12>$F$3,TREND(OFFSET($D$8,$F$3,0):$D$31,OFFSET($E$8,$F$3,0):$E$31,E12),"")} -> 3156847.8 | H12: 1615629.4 | I12: =IF(B12>$J$3,OFFSET(D12,-$J$3,0),"") | J12: {=IF(B12>$J$3,TREND(OFFSET($H$8,$J$3,0):$H$31,OFFSET($I$8,$J$3,0):$I$31,I12),"")} | K12: k1 | L12: 1 | M12: 0.96914521 | N12: 0.96058665 | O12: 0.94850992 | P12: 0.93738564 | Q12: 0.93193892 | R12: 0.93430494 | S12: 0.93044517 | T12: 0.92062544 | U12: 0.91439412 | V12: 0.92068406 | W12: 0.94103707 | X12: 0.93804434
B13: 6 | C13: 2007 | D13: =AR!D13 -> 4183589 | E13: =IF(B13>$F$3,OFFSET(H13,-$F$3,0),"") -> 1615629.4 | F13: {=IF(B13>$F$3,TREND(OFFSET($D$8,$F$3,0):$D$31,OFFSET($E$8,$F$3,0):$E$31,E13),"")} -> 3643075.2 | H13: 1992232.6 | I13: =IF(B13>$J$3,OFFSET(D13,-$J$3,0),"") | J13: {=IF(B13>$J$3,TREND(OFFSET($H$8,$J$3,0):$H$31,OFFSET($I$8,$J$3,0):$I$31,I13),"")} | L13: 2 | M13: 0.9492387 | N13: 0.94068014 | O13: 0.92860341 | P13: 0.91747913 | Q13: 0.91203242 | R13: 0.91439843 | S13: 0.91053866 | T13: 0.90071893 | U13: 0.89448761 | V13: 0.90077755 | W13: 0.92113056 | X13: 0.91813783
B14: 7 | C14: 2008 | D14: =AR!D14 -> 5380452.4 | E14: =IF(B14>$F$3,OFFSET(H14,-$F$3,0),"") -> 1992232.6 | F14: {=IF(B14>$F$3,TREND(OFFSET($D$8,$F$3,0):$D$31,OFFSET($E$8,$F$3,0):$E$31,E14),"")} -> 4228885.6 | H14: 2560198.8 | I14: =IF(B14>$J$3,OFFSET(D14,-$J$3,0),"") | J14: {=IF(B14>$J$3,TREND(OFFSET($H$8,$J$3,0):$H$31,OFFSET($I$8,$J$3,0):$I$31,I14),"")} | L14: 3 | M14: 0.9215116 | N14: 0.91295304 | O14: 0.90087631 | P14: 0.88975203 | Q14: 0.88430531 | R14: 0.88667133 | S14: 0.88281156 | T14: 0.87299183 | U14: 0.86676051 | V14: 0.87305045 | W14: 0.89340346 | X14: 0.89041073
B15: 8 | C15: 2009 | D15: =AR!D15 -> 5857652.2 | E15: =IF(B15>$F$3,OFFSET(H15,-$F$3,0),"") -> 2560198.8 | F15: {=IF(B15>$F$3,TREND(OFFSET($D$8,$F$3,0):$D$31,OFFSET($E$8,$F$3,0):$E$31,E15),"")} -> 5112363.4 | H15: 2993345.6 | I15: =IF(B15>$J$3,OFFSET(D15,-$J$3,0),"") | J15: {=IF(B15>$J$3,TREND(OFFSET($H$8,$J$3,0):$H$31,OFFSET($I$8,$J$3,0):$I$31,I15),"")} | L15: 4 | M15: 0.89257984 | N15: 0.88402128 | O15: 0.87194455 | P15: 0.86082027 | Q15: 0.85537356 | R15: 0.85773957 | S15: 0.8538798 | T15: 0.84406008 | U15: 0.83782875 | V15: 0.84411869 | W15: 0.8644717 | X15: 0.86147897
B16: 9 | C16: 2010 | D16: =AR!D16 -> 6511019.6 | E16: =IF(B16>$F$3,OFFSET(H16,-$F$3,0),"") -> 2993345.6 | F16: {=IF(B16>$F$3,TREND(OFFSET($D$8,$F$3,0):$D$31,OFFSET($E$8,$F$3,0):$E$31,E16),"")} -> 5786128 | H16: 3292699.1 | I16: =IF(B16>$J$3,OFFSET(D16,-$J$3,0),"") | J16: {=IF(B16>$J$3,TREND(OFFSET($H$8,$J$3,0):$H$31,OFFSET($I$8,$J$3,0):$I$31,I16),"")} | L16: 5 | M16: 0.88034529 | N16: 0.87178673 | O16: 0.85971 | P16: 0.84858572 | Q16: 0.843139 | R16: 0.84550502 | S16: 0.84164525 | T16: 0.83182552 | U16: 0.8255942 | V16: 0.83188414 | W16: 0.85223715 | X16: 0.84924442
B17: 10 | C17: 2011 | D17: =AR!D17 -> 7448243.4 | E17: =IF(B17>$F$3,OFFSET(H17,-$F$3,0),"") -> 3292699.1 | F17: {=IF(B17>$F$3,TREND(OFFSET($D$8,$F$3,0):$D$31,OFFSET($E$8,$F$3,0):$E$31,E17),"")} -> 6251775.8 | H17: 3631807.6 | I17: =IF(B17>$J$3,OFFSET(D17,-$J$3,0),"") | J17: {=IF(B17>$J$3,TREND(OFFSET($H$8,$J$3,0):$H$31,OFFSET($I$8,$J$3,0):$I$31,I17),"")} | L17: 6 | M17: 0.87621145 | N17: 0.86765289 | O17: 0.85557616 | P17: 0.84445188 | Q17: 0.83900517 | R17: 0.84137118 | S17: 0.83751141 | T17: 0.82769169 | U17: 0.82146036 | V17: 0.8277503 | W17: 0.84810331 | X17: 0.84511058
B18: 11 | C18: 2012 | D18: =AR!D18 -> 8915955.3 | E18: =IF(B18>$F$3,OFFSET(H18,-$F$3,0),"") -> 3631807.6 | F18: {=IF(B18>$F$3,TREND(OFFSET($D$8,$F$3,0):$D$31,OFFSET($E$8,$F$3,0):$E$31,E18),"")} -> 6779262.8 | H18: 6188755.7 | I18: =IF(B18>$J$3,OFFSET(D18,-$J$3,0),"") -> 1523670.1 | J18: {=IF(B18>$J$3,TREND(OFFSET($H$8,$J$3,0):$H$31,OFFSET($I$8,$J$3,0):$I$31,I18),"")} -> 5452194.1 | L18: 7 | M18: 0.87992628 | N18: 0.87136773 | O18: 0.85929099 | P18: 0.84816672 | Q18: 0.84272 | R18: 0.84508602 | S18: 0.84122625 | T18: 0.83140652 | U18: 0.82517519 | V18: 0.83146514 | W18: 0.85181814 | X18: 0.84882542
B19: 12 | C19: 2013 | D19: =AR!D19 -> 10017462 | E19: =IF(B19>$F$3,OFFSET(H19,-$F$3,0),"") -> 6188755.7 | F19: {=IF(B19>$F$3,TREND(OFFSET($D$8,$F$3,0):$D$31,OFFSET($E$8,$F$3,0):$E$31,E19),"")} -> 10756624 | H19: 7066670.2 | I19: =IF(B19>$J$3,OFFSET(D19,-$J$3,0),"") -> 1899714.3 | J19: {=IF(B19>$J$3,TREND(OFFSET($H$8,$J$3,0):$H$31,OFFSET($I$8,$J$3,0):$I$31,I19),"")} -> 5942779.7 | L19: 8 | M19: 0.89708416 | N19: 0.88852561 | O19: 0.87644887 | P19: 0.8653246 | Q19: 0.85987788 | R19: 0.86224389 | S19: 0.85838412 | T19: 0.8485644 | U19: 0.84233307 | V19: 0.84862301 | W19: 0.86897602 | X19: 0.86598329
B20: 13 | C20: 2014 | D20: =AR!D20 -> 9925208.1 | E20: =IF(B20>$F$3,OFFSET(H20,-$F$3,0),"") -> 7066670.2 | F20: {=IF(B20>$F$3,TREND(OFFSET($D$8,$F$3,0):$D$31,OFFSET($E$8,$F$3,0):$E$31,E20),"")} -> 12122230 | H20: 7517411.3 | I20: =IF(B20>$J$3,OFFSET(D20,-$J$3,0),"") -> 2271976.8 | J20: {=IF(B20>$J$3,TREND(OFFSET($H$8,$J$3,0):$H$31,OFFSET($I$8,$J$3,0):$I$31,I20),"")} -> 6428431.8 | L20: 9 | M20: 0.92431738 | N20: 0.91575882 | O20: 0.90368209 | P20: 0.89255781 | Q20: 0.88711109 | R20: 0.88947711 | S20: 0.88561734 | T20: 0.87579761 | U20: 0.86956629 | V20: 0.87585623 | W20: 0.89620924 | X20: 0.89321651
B21: 14 | C21: 2015 | D21: =AR!D21 -> 10706582 | E21: =IF(B21>$F$3,OFFSET(H21,-$F$3,0),"") -> 7517411.3 | F21: {=IF(B21>$F$3,TREND(OFFSET($D$8,$F$3,0):$D$31,OFFSET($E$8,$F$3,0):$E$31,E21),"")} -> 12823362 | H21: 7806214.9 | I21: =IF(B21>$J$3,OFFSET(D21,-$J$3,0),"") -> 2745199.6 | J21: {=IF(B21>$J$3,TREND(OFFSET($H$8,$J$3,0):$H$31,OFFSET($I$8,$J$3,0):$I$31,I21),"")} -> 7045796.3 | L21: 10 | M21: 0.94915849 | N21: 0.94059994 | O21: 0.9285232 | P21: 0.91739893 | Q21: 0.91195221 | R21: 0.91431822 | S21: 0.91045845 | T21: 0.90063873 | U21: 0.8944074 | V21: 0.90069735 | W21: 0.92105035 | X21: 0.91805763
B22: 15 | C22: 2016 | D22: =AR!D22 -> 11852882 | E22: =IF(B22>$F$3,OFFSET(H22,-$F$3,0),"") -> 7806214.9 | F22: {=IF(B22>$F$3,TREND(OFFSET($D$8,$F$3,0):$D$31,OFFSET($E$8,$F$3,0):$E$31,E22),"")} -> 13272600 | H22: 8342022.6 | I22: =IF(B22>$J$3,OFFSET(D22,-$J$3,0),"") -> 3476075.5 | J22: {=IF(B22>$J$3,TREND(OFFSET($H$8,$J$3,0):$H$31,OFFSET($I$8,$J$3,0):$I$31,I22),"")} -> 7999293.9 | L22: 11 | M22: 0.96755589 | N22: 0.95899734 | O22: 0.9469206 | P22: 0.93579633 | Q22: 0.93034961 | R22: 0.93271562 | S22: 0.92885585 | T22: 0.91903613 | U22: 0.9128048 | V22: 0.91909474 | W22: 0.93944775 | X22: 0.93645503
B23: 16 | C23: 2017 | D23: =AR!D23 -> 12766003 | E23: =IF(B23>$F$3,OFFSET(H23,-$F$3,0),"") -> 8342022.6 | F23: {=IF(B23>$F$3,TREND(OFFSET($D$8,$F$3,0):$D$31,OFFSET($E$8,$F$3,0):$E$31,E23),"")} -> 14106054 | H23: 8435287.1 | I23: =IF(B23>$J$3,OFFSET(D23,-$J$3,0),"") -> 4183589 | J23: {=IF(B23>$J$3,TREND(OFFSET($H$8,$J$3,0):$H$31,OFFSET($I$8,$J$3,0):$I$31,I23),"")} -> 8922313.1 | L23: 12 | M23: 0.96090684 | N23: 0.95234829 | O23: 0.94027155 | P23: 0.92914728 | Q23: 0.92370056 | R23: 0.92606657 | S23: 0.9222068 | T23: 0.91238708 | U23: 0.90615575 | V23: 0.91244569 | W23: 0.9327987 | X23: 0.92980597
B24: 17 | C24: 2018 | D24: =AR!D24 -> 13515794 | E24: =IF(B24>$F$3,OFFSET(H24,-$F$3,0),"") -> 8435287.1 | F24: {=IF(B24>$F$3,TREND(OFFSET($D$8,$F$3,0):$D$31,OFFSET($E$8,$F$3,0):$E$31,E24),"")} -> 14251128 | H24: 8889867.7 | I24: =IF(B24>$J$3,OFFSET(D24,-$J$3,0),"") -> 5380452.4 | J24: {=IF(B24>$J$3,TREND(OFFSET($H$8,$J$3,0):$H$31,OFFSET($I$8,$J$3,0):$I$31,I24),"")} -> 10483736
B25: 18 | C25: 2019 | D25: =AR!D25 -> 13615272 | E25: =IF(B25>$F$3,OFFSET(H25,-$F$3,0),"") -> 8889867.7 | F25: {=IF(B25>$F$3,TREND(OFFSET($D$8,$F$3,0):$D$31,OFFSET($E$8,$F$3,0):$E$31,E25),"")} -> 14958234 | H25: 9438926.1 | I25: =IF(B25>$J$3,OFFSET(D25,-$J$3,0),"") -> 5857652.2 | J25: {=IF(B25>$J$3,TREND(OFFSET($H$8,$J$3,0):$H$31,OFFSET($I$8,$J$3,0):$I$31,I25),"")} -> 11106289
B26: 19 | C26: 2020 | D26: =AR!D26 -> 14544326 | E26: =IF(B26>$F$3,OFFSET(H26,-$F$3,0),"") -> 9438926.1 | F26: {=IF(B26>$F$3,TREND(OFFSET($D$8,$F$3,0):$D$31,OFFSET($E$8,$F$3,0):$E$31,E26),"")} -> 15812300 | H26: 9987984.4 | I26: =IF(B26>$J$3,OFFSET(D26,-$J$3,0),"") -> 6511019.6 | J26: {=IF(B26>$J$3,TREND(OFFSET($H$8,$J$3,0):$H$31,OFFSET($I$8,$J$3,0):$I$31,I26),"")} -> 11958669
B27: 20 | C27: 2021 | D27: =AR!D27 -> 16406490 | E27: =IF(B27>$F$3,OFFSET(H27,-$F$3,0),"") -> 9987984.4 | F27: {=IF(B27>$F$3,TREND(OFFSET($D$8,$F$3,0):$D$31,OFFSET($E$8,$F$3,0):$E$31,E27),"")} -> 16666366 | H27: 10979480 | I27: =IF(B27>$J$3,OFFSET(D27,-$J$3,0),"") -> 7448243.4 | J27: {=IF(B27>$J$3,TREND(OFFSET($H$8,$J$3,0):$H$31,OFFSET($I$8,$J$3,0):$I$31,I27),"")} -> 13181367
B28: 21 | C28: 2022 | D28: =AR!D28 -> 19738623 | E28: =IF(B28>$F$3,OFFSET(H28,-$F$3,0),"") -> 10979480 | F28: {=IF(B28>$F$3,TREND(OFFSET($D$8,$F$3,0):$D$31,OFFSET($E$8,$F$3,0):$E$31,E28),"")} -> 18208648 | H28: 13819986 | I28: =IF(B28>$J$3,OFFSET(D28,-$J$3,0),"") -> 8915955.3 | J28: {=IF(B28>$J$3,TREND(OFFSET($H$8,$J$3,0):$H$31,OFFSET($I$8,$J$3,0):$I$31,I28),"")} -> 15096138
B29: 22 | C29: 2023 | D29: =AR!D29 -> 24340433 | E29: =IF(B29>$F$3,OFFSET(H29,-$F$3,0),"") -> 13819986 | F29: {=IF(B29>$F$3,TREND(OFFSET($D$8,$F$3,0):$D$31,OFFSET($E$8,$F$3,0):$E$31,E29),"")} -> 22627088 | H29: 16660494 | I29: =IF(B29>$J$3,OFFSET(D29,-$J$3,0),"") -> 10017462 | J29: {=IF(B29>$J$3,TREND(OFFSET($H$8,$J$3,0):$H$31,OFFSET($I$8,$J$3,0):$I$31,I29),"")} -> 16533159
B30: 23 | C30: 2024 | D30: =AR!D30 -> 29177254 | E30: =IF(B30>$F$3,OFFSET(H30,-$F$3,0),"") -> 16660494 | F30: {=IF(B30>$F$3,TREND(OFFSET($D$8,$F$3,0):$D$31,OFFSET($E$8,$F$3,0):$E$31,E30),"")} -> 27045528 | H30: 20267550 | I30: =IF(B30>$J$3,OFFSET(D30,-$J$3,0),"") -> 9925208.1 | J30: {=IF(B30>$J$3,TREND(OFFSET($H$8,$J$3,0):$H$31,OFFSET($I$8,$J$3,0):$I$31,I30),"")} -> 16412805
B31: 24 | C31: 2025 | D31: =AR!D31 -> 32463741 | E31: =IF(B31>$F$3,OFFSET(H31,-$F$3,0),"") -> 20267550 | F31: {=IF(B31>$F$3,TREND(OFFSET($D$8,$F$3,0):$D$31,OFFSET($E$8,$F$3,0):$E$31,E31),"")} -> 32656344 | H31: 18594505 | I31: =IF(B31>$J$3,OFFSET(D31,-$J$3,0),"") -> 10706582 | J31: {=IF(B31>$J$3,TREND(OFFSET($H$8,$J$3,0):$H$31,OFFSET($I$8,$J$3,0):$I$31,I31),"")} -> 17432182
A32: горизонт | B32: 25 | C32: 2026 | D32: =F32 -> 30053905 | E32: =IF(B32>$F$3,OFFSET(H32,-$F$3,0),"") -> 18594505 | F32: {=IF(B32>$F$3,TREND(OFFSET($D$8,$F$3,0):$D$31,OFFSET($E$8,$F$3,0):$E$31,E32),"")} -> 30053905 | H32: =J32 -> 18927640 | I32: =IF(B32>$J$3,OFFSET(D32,-$J$3,0),"") -> 11852882 | J32: {=IF(B32>$J$3,TREND(OFFSET($H$8,$J$3,0):$H$31,OFFSET($I$8,$J$3,0):$I$31,I32),"")} -> 18927640
B33: 26 | C33: 2027 | D33: =F33 -> 30572099 | E33: =IF(B33>$F$3,OFFSET(H33,-$F$3,0),"") -> 18927640 | F33: {=IF(B33>$F$3,TREND(OFFSET($D$8,$F$3,0):$D$31,OFFSET($E$8,$F$3,0):$E$31,E33),"")} -> 30572099 | H33: =J33 -> 20118894 | I33: =IF(B33>$J$3,OFFSET(D33,-$J$3,0),"") -> 12766003 | J33: {=IF(B33>$J$3,TREND(OFFSET($H$8,$J$3,0):$H$31,OFFSET($I$8,$J$3,0):$I$31,I33),"")} -> 20118894
B34: 27 | C34: 2028 | D34: =F34 -> 32425108 | E34: =IF(B34>$F$3,OFFSET(H34,-$F$3,0),"") -> 20118894 | F34: {=IF(B34>$F$3,TREND(OFFSET($D$8,$F$3,0):$D$31,OFFSET($E$8,$F$3,0):$E$31,E34),"")} -> 32425108 | H34: =J34 -> 21097068 | I34: =IF(B34>$J$3,OFFSET(D34,-$J$3,0),"") -> 13515794 | J34: {=IF(B34>$J$3,TREND(OFFSET($H$8,$J$3,0):$H$31,OFFSET($I$8,$J$3,0):$I$31,I34),"")} -> 21097068
B35: 28 | C35: 2029 | D35: =F35 -> 33946669 | E35: =IF(B35>$F$3,OFFSET(H35,-$F$3,0),"") -> 21097068 | F35: {=IF(B35>$F$3,TREND(OFFSET($D$8,$F$3,0):$D$31,OFFSET($E$8,$F$3,0):$E$31,E35),"")} -> 33946669 | H35: =J35 -> 21226847 | I35: =IF(B35>$J$3,OFFSET(D35,-$J$3,0),"") -> 13615272 | J35: {=IF(B35>$J$3,TREND(OFFSET($H$8,$J$3,0):$H$31,OFFSET($I$8,$J$3,0):$I$31,I35),"")} -> 21226847
B36: 29 | C36: 2030 | D36: =F36 -> 34148541 | E36: =IF(B36>$F$3,OFFSET(H36,-$F$3,0),"") -> 21226847 | F36: {=IF(B36>$F$3,TREND(OFFSET($D$8,$F$3,0):$D$31,OFFSET($E$8,$F$3,0):$E$31,E36),"")} -> 34148541 | H36: =J36 -> 22438886 | I36: =IF(B36>$J$3,OFFSET(D36,-$J$3,0),"") -> 14544326 | J36: {=IF(B36>$J$3,TREND(OFFSET($H$8,$J$3,0):$H$31,OFFSET($I$8,$J$3,0):$I$31,I36),"")} -> 22438886
B37: 30 | C37: 2031 | D37: =F37 -> 36033882 | E37: =IF(B37>$F$3,OFFSET(H37,-$F$3,0),"") -> 22438886 | F37: {=IF(B37>$F$3,TREND(OFFSET($D$8,$F$3,0):$D$31,OFFSET($E$8,$F$3,0):$E$31,E37),"")} -> 36033882 | H37: =J37 -> 24868259 | I37: =IF(B37>$J$3,OFFSET(D37,-$J$3,0),"") -> 16406490 | J37: {=IF(B37>$J$3,TREND(OFFSET($H$8,$J$3,0):$H$31,OFFSET($I$8,$J$3,0):$I$31,I37),"")} -> 24868259
B38: 31 | C38: 2032 | D38: =F38 -> 39812798 | E38: =IF(B38>$F$3,OFFSET(H38,-$F$3,0),"") -> 24868259 | F38: {=IF(B38>$F$3,TREND(OFFSET($D$8,$F$3,0):$D$31,OFFSET($E$8,$F$3,0):$E$31,E38),"")} -> 39812798 | H38: =J38 -> 29215344 | I38: =IF(B38>$J$3,OFFSET(D38,-$J$3,0),"") -> 19738623 | J38: {=IF(B38>$J$3,TREND(OFFSET($H$8,$J$3,0):$H$31,OFFSET($I$8,$J$3,0):$I$31,I38),"")} -> 29215344
B39: 32 | C39: 2033 | D39: =F39 -> 46574737 | E39: =IF(B39>$F$3,OFFSET(H39,-$F$3,0),"") -> 29215344 | F39: {=IF(B39>$F$3,TREND(OFFSET($D$8,$F$3,0):$D$31,OFFSET($E$8,$F$3,0):$E$31,E39),"")} -> 46574737 | H39: =J39 -> 35218847 | I39: =IF(B39>$J$3,OFFSET(D39,-$J$3,0),"") -> 24340433 | J39: {=IF(B39>$J$3,TREND(OFFSET($H$8,$J$3,0):$H$31,OFFSET($I$8,$J$3,0):$I$31,I39),"")} -> 35218847
B40: 33 | C40: 2034 | D40: =F40 -> 55913252 | E40: =IF(B40>$F$3,OFFSET(H40,-$F$3,0),"") -> 35218847 | F40: {=IF(B40>$F$3,TREND(OFFSET($D$8,$F$3,0):$D$31,OFFSET($E$8,$F$3,0):$E$31,E40),"")} -> 55913252 | H40: =J40 -> 41528942 | I40: =IF(B40>$J$3,OFFSET(D40,-$J$3,0),"") -> 29177254 | J40: {=IF(B40>$J$3,TREND(OFFSET($H$8,$J$3,0):$H$31,OFFSET($I$8,$J$3,0):$I$31,I40),"")} -> 41528942
B41: 34 | C41: 2035 | D41: =F41 -> 65728676 | E41: =IF(B41>$F$3,OFFSET(H41,-$F$3,0),"") -> 41528942 | F41: {=IF(B41>$F$3,TREND(OFFSET($D$8,$F$3,0):$D$31,OFFSET($E$8,$F$3,0):$E$31,E41),"")} -> 65728676 | H41: =J41 -> 45816480 | I41: =IF(B41>$J$3,OFFSET(D41,-$J$3,0),"") -> 32463741 | J41: {=IF(B41>$J$3,TREND(OFFSET($H$8,$J$3,0):$H$31,OFFSET($I$8,$J$3,0):$I$31,I41),"")} -> 45816480

Sheet Итого
F1: 1 | J1: 1 | O1: 1 | S1: 1 | W1: 1 | AA1: Выход
E3: лаги запаздывания влияния k1= | F3: 1 | I3: k2= | J3: 9 | N3: k3= | O3: 7 | R3: k4= | S3: 17 | V3: k5= | W3: 10 | AB3: R^2
AA4: Y^ 1 | AB4: =CORREL(OFFSET($D$8,$F$3,0):$D$31,OFFSET($F$8,$F$3,0):$F$31)^2 -> 0.9760422
D5: Y1 | E5: X1 | F5: Y1^ | H5: Y2 | I5: X2 | J5: Y2^ | L5: Y3 | M5: X4 | N5: X3 | O5: Y3^ | Q5: Y4 | R5: X4 | S5: Y4^ | U5: Y5 | V5: X5 | W5: Y5^ | AA5: Y^ 2 | AB5: =CORREL(OFFSET($H$8,$J$3,0):$H$31,OFFSET($J$8,$J$3,0):$J$31)^2 -> 0.8429533
B6: t | D6: Vt | E6: Ct+k | F6: f (X1) | H6: Ct | I6: Vt+k | J6: f (X2) | L6: Ct | M6: Vt+k | N6: Vt+k | O6: f (X2) | Q6: Ct | R6: Vt+k | S6: f (X2) | U6: Ct | V6: Vt+k | W6: f (X2) | AA6: Y^ 3 | AB6: =CORREL(OFFSET($L$8,$O$3,0):$L$31,OFFSET($O$8,$O$3,0):$O$31)^2 -> 0.96272624
B7: № | C7: года | D7: =AR!D7 -> ВВП | E7: =H7 & " t+" & F3 -> ОФ t+1 | F7: =D7&"( "&E7&")" -> ВВП( ОФ t+1) | H7: ОФ | I7: =D7 & " t+" & J3 -> ВВП t+9 | J7: =H7&"( "&I7&")" -> ОФ( ВВП t+9) | L7: ЗП | M7: ССЧ t+7 | N7: =H7 & " t+" & O3 -> ОФ t+7 | O7: =L7&"( "&N7&")" -> ЗП( ОФ t+7) | Q7: ССЧ | R7: =U7 & " t+" & S3 -> ВДС t+17 | S7: =Q7&"( "&R7&")" -> ССЧ( ВДС t+17) | U7: ВДС | V7: =Q7 & " t+" & W3 -> ССЧ t+10 | W7: =U7&"( "&V7&")" -> ВДС( ССЧ t+10) | AA7: Y^ 4 | AB7: =CORREL(OFFSET($Q$8,$S$3,0):$Q$31,OFFSET($S$8,$S$3,0):$S$31)^2 -> 0.84623689
A8: база | B8: 1 | C8: 2002 | D8: =AR!D8 -> 1523670.1 | E8: =IF($B8>$F$3, OFFSET(H8, - $F$3, 0), "") | F8: =IF($B8>$F$3, TREND(OFFSET($D$8,$F$3,0):$D$31,OFFSET($E$8,$F$3,0):$E$31,E8,$F$1),"") | H8: 663998.76 | I8: =IF($B8>$J$3, OFFSET(L8, - $J$3, 0), "") | J8: =IF($B8>$J$3, TREND(OFFSET($H$8,$J$3,0):$H$31,OFFSET($I$8,$J$3,0):$I$31,I8),"") | L8: 7124.9669 | M8: =IF($B8>$O$3, OFFSET(Q8, - $O$3, 0), "") | N8: =IF($B8>$O$3, OFFSET(H8, - $O$3, 0), "") | O8: =IF($B8>$O$3, TREND(OFFSET($L$8,$O$3,0):$L$31,(OFFSET($M$8,$O$3,0):$N$31),M8:N8,$O$1),"") | Q8: 3013.1798 | R8: =IF($B8>$S$3, OFFSET(U8, - $S$3, 0), "") | S8: =IF($B8>$S$3, TREND(OFFSET($Q$8,$S$3,0):$Q$31,OFFSET($R$8,$S$3,0):$R$31,R8,$S$1),"") | U8: 854871.15 | V8: =IF($B8>$W$3, OFFSET(D8, - $W$3, 0), "") | W8: =IF($B8>$W$3, TREND(OFFSET($U$8,$W$3,0):$U$31,OFFSET($V$8,$W$3,0):$V$31,V8),"") | AA8: Y^ 5 | AB8: =CORREL(OFFSET($U$8,$W$3,0):$U$31,OFFSET($W$8,$W$3,0):$W$31)^2 -> 0.88498166
B9: 2 | C9: 2003 | D9: =AR!D9 -> 1899714.3 | E9: =IF($B9>$F$3, OFFSET(H9, - $F$3, 0), "") -> 663998.76 | F9: =IF($B9>$F$3, TREND(OFFSET($D$8,$F$3,0):$D$31,OFFSET($E$8,$F$3,0):$E$31,E9,$F$1),"") -> 2162803.2 | H9: 884858.7 | I9: =IF($B9>$J$3, OFFSET(L9, - $J$3, 0), "") | J9: =IF($B9>$J$3, TREND(OFFSET($H$8,$J$3,0):$H$31,OFFSET($I$8,$J$3,0):$I$31,I9),"") | L9: 9472.4629 | M9: =IF($B9>$O$3, OFFSET(Q9, - $O$3, 0), "") | N9: =IF($B9>$O$3, OFFSET(H9, - $O$3, 0), "") | O9: =IF($B9>$O$3, TREND(OFFSET($L$8,$O$3,0):$L$31,(OFFSET($M$8,$O$3,0):$N$31),M9:N9,$O$1),"") | Q9: 3063.7504 | R9: =IF($B9>$S$3, OFFSET(U9, - $S$3, 0), "") | S9: =IF($B9>$S$3, TREND(OFFSET($Q$8,$S$3,0):$Q$31,OFFSET($R$8,$S$3,0):$R$31,R9,$S$1),"") | U9: 1139219.2 | V9: =IF($B9>$W$3, OFFSET(D9, - $W$3, 0), "") | W9: =IF($B9>$W$3, TREND(OFFSET($U$8,$W$3,0):$U$31,OFFSET($V$8,$W$3,0):$V$31,V9),"")
B10: 3 | C10: 2004 | D10: =AR!D10 -> 2271976.8 | E10: =IF($B10>$F$3, OFFSET(H10, - $F$3, 0), "") -> 884858.7 | F10: =IF($B10>$F$3, TREND(OFFSET($D$8,$F$3,0):$D$31,OFFSET($E$8,$F$3,0):$E$31,E10,$F$1),"") -> 2506353.3 | H10: 1090317.1 | I10: =IF($B10>$J$3, OFFSET(L10, - $J$3, 0), "") | J10: =IF($B10>$J$3, TREND(OFFSET($H$8,$J$3,0):$H$31,OFFSET($I$8,$J$3,0):$I$31,I10),"") | L10: 10821.718 | M10: =IF($B10>$O$3, OFFSET(Q10, - $O$3, 0), "") | N10: =IF($B10>$O$3, OFFSET(H10, - $O$3, 0), "") | O10: =IF($B10>$O$3, TREND(OFFSET($L$8,$O$3,0):$L$31,(OFFSET($M$8,$O$3,0):$N$31),M10:N10,$O$1),"") | Q10: 3114.321 | R10: =IF($B10>$S$3, OFFSET(U10, - $S$3, 0), "") | S10: =IF($B10>$S$3, TREND(OFFSET($Q$8,$S$3,0):$Q$31,OFFSET($R$8,$S$3,0):$R$31,R10,$S$1),"") | U10: 1403738.5 | V10: =IF($B10>$W$3, OFFSET(D10, - $W$3, 0), "") | W10: =IF($B10>$W$3, TREND(OFFSET($U$8,$W$3,0):$U$31,OFFSET($V$8,$W$3,0):$V$31,V10),"") | AA10: Среднее | AB10: =AVERAGE(AB4:AB8) -> 0.90258806
B11: 4 | C11: 2005 | D11: =AR!D11 -> 2745199.6 | E11: =IF($B11>$F$3, OFFSET(H11, - $F$3, 0), "") -> 1090317.1 | F11: =IF($B11>$F$3, TREND(OFFSET($D$8,$F$3,0):$D$31,OFFSET($E$8,$F$3,0):$E$31,E11,$F$1),"") -> 2825946.1 | H11: 1303045.7 | I11: =IF($B11>$J$3, OFFSET(L11, - $J$3, 0), "") | J11: =IF($B11>$J$3, TREND(OFFSET($H$8,$J$3,0):$H$31,OFFSET($I$8,$J$3,0):$I$31,I11),"") | L11: 15014.028 | M11: =IF($B11>$O$3, OFFSET(Q11, - $O$3, 0), "") | N11: =IF($B11>$O$3, OFFSET(H11, - $O$3, 0), "") | O11: =IF($B11>$O$3, TREND(OFFSET($L$8,$O$3,0):$L$31,(OFFSET($M$8,$O$3,0):$N$31),M11:N11,$O$1),"") | Q11: 3164.8915 | R11: =IF($B11>$S$3, OFFSET(U11, - $S$3, 0), "") | S11: =IF($B11>$S$3, TREND(OFFSET($Q$8,$S$3,0):$Q$31,OFFSET($R$8,$S$3,0):$R$31,R11,$S$1),"") | U11: 1677617.8 | V11: =IF($B11>$W$3, OFFSET(D11, - $W$3, 0), "") | W11: =IF($B11>$W$3, TREND(OFFSET($U$8,$W$3,0):$U$31,OFFSET($V$8,$W$3,0):$V$31,V11),"")
B12: 5 | C12: 2006 | D12: =AR!D12 -> 3476075.5 | E12: =IF($B12>$F$3, OFFSET(H12, - $F$3, 0), "") -> 1303045.7 | F12: =IF($B12>$F$3, TREND(OFFSET($D$8,$F$3,0):$D$31,OFFSET($E$8,$F$3,0):$E$31,E12,$F$1),"") -> 3156847.8 | H12: 1615629.4 | I12: =IF($B12>$J$3, OFFSET(L12, - $J$3, 0), "") | J12: =IF($B12>$J$3, TREND(OFFSET($H$8,$J$3,0):$H$31,OFFSET($I$8,$J$3,0):$I$31,I12),"") | K12: k1 | L12: 18464.987 | M12: =IF($B12>$O$3, OFFSET(Q12, - $O$3, 0), "") | N12: =IF($B12>$O$3, OFFSET(H12, - $O$3, 0), "") | O12: =IF($B12>$O$3, TREND(OFFSET($L$8,$O$3,0):$L$31,(OFFSET($M$8,$O$3,0):$N$31),M12:N12,$O$1),"") | Q12: 3262.6488 | R12: =IF($B12>$S$3, OFFSET(U12, - $S$3, 0), "") | S12: =IF($B12>$S$3, TREND(OFFSET($Q$8,$S$3,0):$Q$31,OFFSET($R$8,$S$3,0):$R$31,R12,$S$1),"") | U12: 2080056.5 | V12: =IF($B12>$W$3, OFFSET(D12, - $W$3, 0), "") | W12: =IF($B12>$W$3, TREND(OFFSET($U$8,$W$3,0):$U$31,OFFSET($V$8,$W$3,0):$V$31,V12),"")
B13: 6 | C13: 2007 | D13: =AR!D13 -> 4183589 | E13: =IF($B13>$F$3, OFFSET(H13, - $F$3, 0), "") -> 1615629.4 | F13: =IF($B13>$F$3, TREND(OFFSET($D$8,$F$3,0):$D$31,OFFSET($E$8,$F$3,0):$E$31,E13,$F$1),"") -> 3643075.2 | H13: 1992232.6 | I13: =IF($B13>$J$3, OFFSET(L13, - $J$3, 0), "") | J13: =IF($B13>$J$3, TREND(OFFSET($H$8,$J$3,0):$H$31,OFFSET($I$8,$J$3,0):$I$31,I13),"") | L13: 23149.292 | M13: =IF($B13>$O$3, OFFSET(Q13, - $O$3, 0), "") | N13: =IF($B13>$O$3, OFFSET(H13, - $O$3, 0), "") | O13: =IF($B13>$O$3, TREND(OFFSET($L$8,$O$3,0):$L$31,(OFFSET($M$8,$O$3,0):$N$31),M13:N13,$O$1),"") | Q13: 3415.8645 | R13: =IF($B13>$S$3, OFFSET(U13, - $S$3, 0), "") | S13: =IF($B13>$S$3, TREND(OFFSET($Q$8,$S$3,0):$Q$31,OFFSET($R$8,$S$3,0):$R$31,R13,$S$1),"") | U13: 2564917.6 | V13: =IF($B13>$W$3, OFFSET(D13, - $W$3, 0), "") | W13: =IF($B13>$W$3, TREND(OFFSET($U$8,$W$3,0):$U$31,OFFSET($V$8,$W$3,0):$V$31,V13),"")
B14: 7 | C14: 2008 | D14: =AR!D14 -> 5380452.4 | E14: =IF($B14>$F$3, OFFSET(H14, - $F$3, 0), "") -> 1992232.6 | F14: =IF($B14>$F$3, TREND(OFFSET($D$8,$F$3,0):$D$31,OFFSET($E$8,$F$3,0):$E$31,E14,$F$1),"") -> 4228885.6 | H14: 2560198.8 | I14: =IF($B14>$J$3, OFFSET(L14, - $J$3, 0), "") | J14: =IF($B14>$J$3, TREND(OFFSET($H$8,$J$3,0):$H$31,OFFSET($I$8,$J$3,0):$I$31,I14),"") | L14: 29243.136 | M14: =IF($B14>$O$3, OFFSET(Q14, - $O$3, 0), "") | N14: =IF($B14>$O$3, OFFSET(H14, - $O$3, 0), "") | O14: =IF($B14>$O$3, TREND(OFFSET($L$8,$O$3,0):$L$31,(OFFSET($M$8,$O$3,0):$N$31),M14:N14,$O$1),"") | Q14: 3564.3804 | R14: =IF($B14>$S$3, OFFSET(U14, - $S$3, 0), "") | S14: =IF($B14>$S$3, TREND(OFFSET($Q$8,$S$3,0):$Q$31,OFFSET($R$8,$S$3,0):$R$31,R14,$S$1),"") | U14: 3296150.8 | V14: =IF($B14>$W$3, OFFSET(D14, - $W$3, 0), "") | W14: =IF($B14>$W$3, TREND(OFFSET($U$8,$W$3,0):$U$31,OFFSET($V$8,$W$3,0):$V$31,V14),"")
B15: 8 | C15: 2009 | D15: =AR!D15 -> 5857652.2 | E15: =IF($B15>$F$3, OFFSET(H15, - $F$3, 0), "") -> 2560198.8 | F15: =IF($B15>$F$3, TREND(OFFSET($D$8,$F$3,0):$D$31,OFFSET($E$8,$F$3,0):$E$31,E15,$F$1),"") -> 5112363.4 | H15: 2993345.6 | I15: =IF($B15>$J$3, OFFSET(L15, - $J$3, 0), "") | J15: =IF($B15>$J$3, TREND(OFFSET($H$8,$J$3,0):$H$31,OFFSET($I$8,$J$3,0):$I$31,I15),"") | L15: 32827.13 | M15: =IF($B15>$O$3, OFFSET(Q15, - $O$3, 0), "") -> 3013.1798 | N15: =IF($B15>$O$3, OFFSET(H15, - $O$3, 0), "") -> 663998.76 | O15: =IF($B15>$O$3, TREND(OFFSET($L$8,$O$3,0):$L$31,(OFFSET($M$8,$O$3,0):$N$31),M15:N15,$O$1),"") -> 32243.793 | Q15: 3721.285 | R15: =IF($B15>$S$3, OFFSET(U15, - $S$3, 0), "") | S15: =IF($B15>$S$3, TREND(OFFSET($Q$8,$S$3,0):$Q$31,OFFSET($R$8,$S$3,0):$R$31,R15,$S$1),"") | U15: 3853809.6 | V15: =IF($B15>$W$3, OFFSET(D15, - $W$3, 0), "") | W15: =IF($B15>$W$3, TREND(OFFSET($U$8,$W$3,0):$U$31,OFFSET($V$8,$W$3,0):$V$31,V15),"")
B16: 9 | C16: 2010 | D16: =AR!D16 -> 6511019.6 | E16: =IF($B16>$F$3, OFFSET(H16, - $F$3, 0), "") -> 2993345.6 | F16: =IF($B16>$F$3, TREND(OFFSET($D$8,$F$3,0):$D$31,OFFSET($E$8,$F$3,0):$E$31,E16,$F$1),"") -> 5786128 | H16: 3292699.1 | I16: =IF($B16>$J$3, OFFSET(L16, - $J$3, 0), "") | J16: =IF($B16>$J$3, TREND(OFFSET($H$8,$J$3,0):$H$31,OFFSET($I$8,$J$3,0):$I$31,I16),"") | L16: 34417.519 | M16: =IF($B16>$O$3, OFFSET(Q16, - $O$3, 0), "") -> 3063.7504 | N16: =IF($B16>$O$3, OFFSET(H16, - $O$3, 0), "") -> 884858.7 | O16: =IF($B16>$O$3, TREND(OFFSET($L$8,$O$3,0):$L$31,(OFFSET($M$8,$O$3,0):$N$31),M16:N16,$O$1),"") -> 35511.613 | Q16: 3722.31 | R16: =IF($B16>$S$3, OFFSET(U16, - $S$3, 0), "") | S16: =IF($B16>$S$3, TREND(OFFSET($Q$8,$S$3,0):$Q$31,OFFSET($R$8,$S$3,0):$R$31,R16,$S$1),"") | U16: 4239214.9 | V16: =IF($B16>$W$3, OFFSET(D16, - $W$3, 0), "") | W16: =IF($B16>$W$3, TREND(OFFSET($U$8,$W$3,0):$U$31,OFFSET($V$8,$W$3,0):$V$31,V16),"")
B17: 10 | C17: 2011 | D17: =AR!D17 -> 7448243.4 | E17: =IF($B17>$F$3, OFFSET(H17, - $F$3, 0), "") -> 3292699.1 | F17: =IF($B17>$F$3, TREND(OFFSET($D$8,$F$3,0):$D$31,OFFSET($E$8,$F$3,0):$E$31,E17,$F$1),"") -> 6251775.8 | H17: 3631807.6 | I17: =IF($B17>$J$3, OFFSET(L17, - $J$3, 0), "") -> 7124.9669 | J17: =IF($B17>$J$3, TREND(OFFSET($H$8,$J$3,0):$H$31,OFFSET($I$8,$J$3,0):$I$31,I17),"") -> 4536275 | L17: 38027.271 | M17: =IF($B17>$O$3, OFFSET(Q17, - $O$3, 0), "") -> 3114.321 | N17: =IF($B17>$O$3, OFFSET(H17, - $O$3, 0), "") -> 1090317.1 | O17: =IF($B17>$O$3, TREND(OFFSET($L$8,$O$3,0):$L$31,(OFFSET($M$8,$O$3,0):$N$31),M17:N17,$O$1),"") -> 38644.433 | Q17: 3588.897 | R17: =IF($B17>$S$3, OFFSET(U17, - $S$3, 0), "") | S17: =IF($B17>$S$3, TREND(OFFSET($Q$8,$S$3,0):$Q$31,OFFSET($R$8,$S$3,0):$R$31,R17,$S$1),"") | U17: 4675803.2 | V17: =IF($B17>$W$3, OFFSET(D17, - $W$3, 0), "") | W17: =IF($B17>$W$3, TREND(OFFSET($U$8,$W$3,0):$U$31,OFFSET($V$8,$W$3,0):$V$31,V17),"")
B18: 11 | C18: 2012 | D18: =AR!D18 -> 8915955.3 | E18: =IF($B18>$F$3, OFFSET(H18, - $F$3, 0), "") -> 3631807.6 | F18: =IF($B18>$F$3, TREND(OFFSET($D$8,$F$3,0):$D$31,OFFSET($E$8,$F$3,0):$E$31,E18,$F$1),"") -> 6779262.8 | H18: 6188755.7 | I18: =IF($B18>$J$3, OFFSET(L18, - $J$3, 0), "") -> 9472.4629 | J18: =IF($B18>$J$3, TREND(OFFSET($H$8,$J$3,0):$H$31,OFFSET($I$8,$J$3,0):$I$31,I18),"") -> 5073228.9 | L18: 48913.794 | M18: =IF($B18>$O$3, OFFSET(Q18, - $O$3, 0), "") -> 3164.8915 | N18: =IF($B18>$O$3, OFFSET(H18, - $O$3, 0), "") -> 1303045.7 | O18: =IF($B18>$O$3, TREND(OFFSET($L$8,$O$3,0):$L$31,(OFFSET($M$8,$O$3,0):$N$31),M18:N18,$O$1),"") -> 41840.978 | Q18: 3517.73 | R18: =IF($B18>$S$3, OFFSET(U18, - $S$3, 0), "") | S18: =IF($B18>$S$3, TREND(OFFSET($Q$8,$S$3,0):$Q$31,OFFSET($R$8,$S$3,0):$R$31,R18,$S$1),"") | U18: 5864573.2 | V18: =IF($B18>$W$3, OFFSET(D18, - $W$3, 0), "") -> 1523670.1 | W18: =IF($B18>$W$3, TREND(OFFSET($U$8,$W$3,0):$U$31,OFFSET($V$8,$W$3,0):$V$31,V18),"") -> 4765469.7
B19: 12 | C19: 2013 | D19: =AR!D19 -> 10017462 | E19: =IF($B19>$F$3, OFFSET(H19, - $F$3, 0), "") -> 6188755.7 | F19: =IF($B19>$F$3, TREND(OFFSET($D$8,$F$3,0):$D$31,OFFSET($E$8,$F$3,0):$E$31,E19,$F$1),"") -> 10756624 | H19: 7066670.2 | I19: =IF($B19>$J$3, OFFSET(L19, - $J$3, 0), "") -> 10821.718 | J19: =IF($B19>$J$3, TREND(OFFSET($H$8,$J$3,0):$H$31,OFFSET($I$8,$J$3,0):$I$31,I19),"") -> 5381850.5 | L19: 55417.977 | M19: =IF($B19>$O$3, OFFSET(Q19, - $O$3, 0), "") -> 3262.6488 | N19: =IF($B19>$O$3, OFFSET(H19, - $O$3, 0), "") -> 1615629.4 | O19: =IF($B19>$O$3, TREND(OFFSET($L$8,$O$3,0):$L$31,(OFFSET($M$8,$O$3,0):$N$31),M19:N19,$O$1),"") -> 47155.573 | Q19: 3511.383 | R19: =IF($B19>$S$3, OFFSET(U19, - $S$3, 0), "") | S19: =IF($B19>$S$3, TREND(OFFSET($Q$8,$S$3,0):$Q$31,OFFSET($R$8,$S$3,0):$R$31,R19,$S$1),"") | U19: 6696500.4 | V19: =IF($B19>$W$3, OFFSET(D19, - $W$3, 0), "") -> 1899714.3 | W19: =IF($B19>$W$3, TREND(OFFSET($U$8,$W$3,0):$U$31,OFFSET($V$8,$W$3,0):$V$31,V19),"") -> 5350426.6
B20: 13 | C20: 2014 | D20: =AR!D20 -> 9925208.1 | E20: =IF($B20>$F$3, OFFSET(H20, - $F$3, 0), "") -> 7066670.2 | F20: =IF($B20>$F$3, TREND(OFFSET($D$8,$F$3,0):$D$31,OFFSET($E$8,$F$3,0):$E$31,E20,$F$1),"") -> 12122230 | H20: 7517411.3 | I20: =IF($B20>$J$3, OFFSET(L20, - $J$3, 0), "") -> 15014.028 | J20: =IF($B20>$J$3, TREND(OFFSET($H$8,$J$3,0):$H$31,OFFSET($I$8,$J$3,0):$I$31,I20),"") -> 6340777.4 | L20: 58446.403 | M20: =IF($B20>$O$3, OFFSET(Q20, - $O$3, 0), "") -> 3415.8645 | N20: =IF($B20>$O$3, OFFSET(H20, - $O$3, 0), "") -> 1992232.6 | O20: =IF($B20>$O$3, TREND(OFFSET($L$8,$O$3,0):$L$31,(OFFSET($M$8,$O$3,0):$N$31),M20:N20,$O$1),"") -> 54491.963 | Q20: 3511.895 | R20: =IF($B20>$S$3, OFFSET(U20, - $S$3, 0), "") | S20: =IF($B20>$S$3, TREND(OFFSET($Q$8,$S$3,0):$Q$31,OFFSET($R$8,$S$3,0):$R$31,R20,$S$1),"") | U20: 6933386.9 | V20: =IF($B20>$W$3, OFFSET(D20, - $W$3, 0), "") -> 2271976.8 | W20: =IF($B20>$W$3, TREND(OFFSET($U$8,$W$3,0):$U$31,OFFSET($V$8,$W$3,0):$V$31,V20),"") -> 5929501
B21: 14 | C21: 2015 | D21: =AR!D21 -> 10706582 | E21: =IF($B21>$F$3, OFFSET(H21, - $F$3, 0), "") -> 7517411.3 | F21: =IF($B21>$F$3, TREND(OFFSET($D$8,$F$3,0):$D$31,OFFSET($E$8,$F$3,0):$E$31,E21,$F$1),"") -> 12823362 | H21: 7806214.9 | I21: =IF($B21>$J$3, OFFSET(L21, - $J$3, 0), "") -> 18464.987 | J21: =IF($B21>$J$3, TREND(OFFSET($H$8,$J$3,0):$H$31,OFFSET($I$8,$J$3,0):$I$31,I21),"") -> 7130131.6 | L21: 57428.57 | M21: =IF($B21>$O$3, OFFSET(Q21, - $O$3, 0), "") -> 3564.3804 | N21: =IF($B21>$O$3, OFFSET(H21, - $O$3, 0), "") -> 2560198.8 | O21: =IF($B21>$O$3, TREND(OFFSET($L$8,$O$3,0):$L$31,(OFFSET($M$8,$O$3,0):$N$31),M21:N21,$O$1),"") -> 63381.93 | Q21: 3506.102 | R21: =IF($B21>$S$3, OFFSET(U21, - $S$3, 0), "") | S21: =IF($B21>$S$3, TREND(OFFSET($Q$8,$S$3,0):$Q$31,OFFSET($R$8,$S$3,0):$R$31,R21,$S$1),"") | U21: 7504676.3 | V21: =IF($B21>$W$3, OFFSET(D21, - $W$3, 0), "") -> 2745199.6 | W21: =IF($B21>$W$3, TREND(OFFSET($U$8,$W$3,0):$U$31,OFFSET($V$8,$W$3,0):$V$31,V21),"") -> 6665624.5
B22: 15 | C22: 2016 | D22: =AR!D22 -> 11852882 | E22: =IF($B22>$F$3, OFFSET(H22, - $F$3, 0), "") -> 7806214.9 | F22: =IF($B22>$F$3, TREND(OFFSET($D$8,$F$3,0):$D$31,OFFSET($E$8,$F$3,0):$E$31,E22,$F$1),"") -> 13272600 | H22: 8342022.6 | I22: =IF($B22>$J$3, OFFSET(L22, - $J$3, 0), "") -> 23149.292 | J22: =IF($B22>$J$3, TREND(OFFSET($H$8,$J$3,0):$H$31,OFFSET($I$8,$J$3,0):$I$31,I22),"") -> 8201595.1 | L22: 59750.309 | M22: =IF($B22>$O$3, OFFSET(Q22, - $O$3, 0), "") -> 3721.285 | N22: =IF($B22>$O$3, OFFSET(H22, - $O$3, 0), "") -> 2993345.6 | O22: =IF($B22>$O$3, TREND(OFFSET($L$8,$O$3,0):$L$31,(OFFSET($M$8,$O$3,0):$N$31),M22:N22,$O$1),"") -> 71311.101 | Q22: 3420.6927 | R22: =IF($B22>$S$3, OFFSET(U22, - $S$3, 0), "") | S22: =IF($B22>$S$3, TREND(OFFSET($Q$8,$S$3,0):$Q$31,OFFSET($R$8,$S$3,0):$R$31,R22,$S$1),"") | U22: 8005749.4 | V22: =IF($B22>$W$3, OFFSET(D22, - $W$3, 0), "") -> 3476075.5 | W22: =IF($B22>$W$3, TREND(OFFSET($U$8,$W$3,0):$U$31,OFFSET($V$8,$W$3,0):$V$31,V22),"") -> 7802541.3
B23: 16 | C23: 2017 | D23: =AR!D23 -> 12766003 | E23: =IF($B23>$F$3, OFFSET(H23, - $F$3, 0), "") -> 8342022.6 | F23: =IF($B23>$F$3, TREND(OFFSET($D$8,$F$3,0):$D$31,OFFSET($E$8,$F$3,0):$E$31,E23,$F$1),"") -> 14106054 | H23: 8435287.1 | I23: =IF($B23>$J$3, OFFSET(L23, - $J$3, 0), "") -> 29243.136 | J23: =IF($B23>$J$3, TREND(OFFSET($H$8,$J$3,0):$H$31,OFFSET($I$8,$J$3,0):$I$31,I23),"") -> 9595469.1 | L23: 71121.2 | M23: =IF($B23>$O$3, OFFSET(Q23, - $O$3, 0), "") -> 3722.31 | N23: =IF($B23>$O$3, OFFSET(H23, - $O$3, 0), "") -> 3292699.1 | O23: =IF($B23>$O$3, TREND(OFFSET($L$8,$O$3,0):$L$31,(OFFSET($M$8,$O$3,0):$N$31),M23:N23,$O$1),"") -> 73962.03 | Q23: 4608.7519 | R23: =IF($B23>$S$3, OFFSET(U23, - $S$3, 0), "") | S23: =IF($B23>$S$3, TREND(OFFSET($Q$8,$S$3,0):$Q$31,OFFSET($R$8,$S$3,0):$R$31,R23,$S$1),"") | U23: 8435287.1 | V23: =IF($B23>$W$3, OFFSET(D23, - $W$3, 0), "") -> 4183589 | W23: =IF($B23>$W$3, TREND(OFFSET($U$8,$W$3,0):$U$31,OFFSET($V$8,$W$3,0):$V$31,V23),"") -> 8903116.6
B24: 17 | C24: 2018 | D24: =AR!D24 -> 13515794 | E24: =IF($B24>$F$3, OFFSET(H24, - $F$3, 0), "") -> 8435287.1 | F24: =IF($B24>$F$3, TREND(OFFSET($D$8,$F$3,0):$D$31,OFFSET($E$8,$F$3,0):$E$31,E24,$F$1),"") -> 14251128 | H24: 8889867.7 | I24: =IF($B24>$J$3, OFFSET(L24, - $J$3, 0), "") -> 32827.13 | J24: =IF($B24>$J$3, TREND(OFFSET($H$8,$J$3,0):$H$31,OFFSET($I$8,$J$3,0):$I$31,I24),"") -> 10415253 | L24: 79509 | M24: =IF($B24>$O$3, OFFSET(Q24, - $O$3, 0), "") -> 3588.897 | N24: =IF($B24>$O$3, OFFSET(H24, - $O$3, 0), "") -> 3631807.6 | O24: =IF($B24>$O$3, TREND(OFFSET($L$8,$O$3,0):$L$31,(OFFSET($M$8,$O$3,0):$N$31),M24:N24,$O$1),"") -> 73420.644 | Q24: 4690.2311 | R24: =IF($B24>$S$3, OFFSET(U24, - $S$3, 0), "") | S24: =IF($B24>$S$3, TREND(OFFSET($Q$8,$S$3,0):$Q$31,OFFSET($R$8,$S$3,0):$R$31,R24,$S$1),"") | U24: 8889867.7 | V24: =IF($B24>$W$3, OFFSET(D24, - $W$3, 0), "") -> 5380452.4 | W24: =IF($B24>$W$3, TREND(OFFSET($U$8,$W$3,0):$U$31,OFFSET($V$8,$W$3,0):$V$31,V24),"") -> 10764902
... B31: 24 | C31: 2025 | D31: =AR!D31 -> 32463741 | E31: =IF($B31>$F$3, OFFSET(H31, - $F$3, 0), "") -> 20267550 | F31: =IF($B31>$F$3, TREND(OFFSET($D$8,$F$3,0):$D$31,OFFSET($E$8,$F$3,0):$E$31,E31,$F$1),"") -> 32656344 | H31: 18594505 | I31: =IF($B31>$J$3, OFFSET(L31, - $J$3, 0), "") -> 59750.309 | J31: =IF($B31>$J$3, TREND(OFFSET($H$8,$J$3,0):$H$31,OFFSET($I$8,$J$3,0):$I$31,I31),"") -> 16573520 | L31: 152647.44 | M31: =IF($B31>$O$3, OFFSET(Q31, - $O$3, 0), "") -> 4690.2311 | N31: =IF($B31>$O$3, OFFSET(H31, - $O$3, 0), "") -> 8889867.7 | O31: =IF($B31>$O$3, TREND(OFFSET($L$8,$O$3,0):$L$31,(OFFSET($M$8,$O$3,0):$N$31),M31:N31,$O$1),"") -> 148515.81 | Q31: 4559.6042 | R31: =IF($B31>$S$3, OFFSET(U31, - $S$3, 0), "") -> 3296150.8 | S31: =IF($B31>$S$3, TREND(OFFSET($Q$8,$S$3,0):$Q$31,OFFSET($R$8,$S$3,0):$R$31,R31,$S$1),"") -> 4542.3612 | U31: 22639157 | V31: =IF($B31>$W$3, OFFSET(D31, - $W$3, 0), "") -> 10706582 | W31: =IF($B31>$W$3, TREND(OFFSET($U$8,$W$3,0):$U$31,OFFSET($V$8,$W$3,0):$V$31,V31),"") -> 19049983
A32: горизонт | B32: 25 | C32: 2026 | D32: =F32 -> 30053905 | E32: =IF($B32>$F$3, OFFSET(H32, - $F$3, 0), "") -> 18594505 | F32: =IF($B32>$F$3, TREND(OFFSET($D$8,$F$3,0):$D$31,OFFSET($E$8,$F$3,0):$E$31,E32,$F$1),"") -> 30053905 | H32: =J32 -> 19174438 | I32: =IF($B32>$J$3, OFFSET(L32, - $J$3, 0), "") -> 71121.2 | J32: =IF($B32>$J$3, TREND(OFFSET($H$8,$J$3,0):$H$31,OFFSET($I$8,$J$3,0):$I$31,I32),"") -> 19174438 | L32: =O32 -> 153397.83 | M32: =IF($B32>$O$3, OFFSET(Q32, - $O$3, 0), "") -> 4692.8642 | N32: =IF($B32>$O$3, OFFSET(H32, - $O$3, 0), "") -> 9438926.1 | O32: =IF($B32>$O$3, TREND(OFFSET($L$8,$O$3,0):$L$31,(OFFSET($M$8,$O$3,0):$N$31),M32:N32,$O$1),"") -> 153397.83 | Q32: =S32 -> 4505.2073 | R32: =IF($B32>$S$3, OFFSET(U32, - $S$3, 0), "") -> 3853809.6 | S32: =IF($B32>$S$3, TREND(OFFSET($Q$8,$S$3,0):$Q$31,OFFSET($R$8,$S$3,0):$R$31,R32,$S$1),"") -> 4505.2073 | U32: =W32 -> 20833114 | V32: =IF($B32>$W$3, OFFSET(D32, - $W$3, 0), "") -> 11852882 | W32: =IF($B32>$W$3, TREND(OFFSET($U$8,$W$3,0):$U$31,OFFSET($V$8,$W$3,0):$V$31,V32),"") -> 20833114
B33: 26 | C33: 2027 | D33: =F33 -> 30955996 | E33: =IF($B33>$F$3, OFFSET(H33, - $F$3, 0), "") -> 19174438 | F33: =IF($B33>$F$3, TREND(OFFSET($D$8,$F$3,0):$D$31,OFFSET($E$8,$F$3,0):$E$31,E33,$F$1),"") -> 30955996 | H33: =J33 -> 21093019 | I33: =IF($B33>$J$3, OFFSET(L33, - $J$3, 0), "") -> 79509 | J33: =IF($B33>$J$3, TREND(OFFSET($H$8,$J$3,0):$H$31,OFFSET($I$8,$J$3,0):$I$31,I33),"") -> 21093019 | L33: =O33 -> 159257.11 | M33: =IF($B33>$O$3, OFFSET(Q33, - $O$3, 0), "") -> 4732.6019 | N33: =IF($B33>$O$3, OFFSET(H33, - $O$3, 0), "") -> 9987984.4 | O33: =IF($B33>$O$3, TREND(OFFSET($L$8,$O$3,0):$L$31,(OFFSET($M$8,$O$3,0):$N$31),M33:N33,$O$1),"") -> 159257.11 | Q33: =S33 -> 4479.5298 | R33: =IF($B33>$S$3, OFFSET(U33, - $S$3, 0), "") -> 4239214.9 | S33: =IF($B33>$S$3, TREND(OFFSET($Q$8,$S$3,0):$Q$31,OFFSET($R$8,$S$3,0):$R$31,R33,$S$1),"") -> 4479.5298 | U33: =W33 -> 22253523 | V33: =IF($B33>$W$3, OFFSET(D33, - $W$3, 0), "") -> 12766003 | W33: =IF($B33>$W$3, TREND(OFFSET($U$8,$W$3,0):$U$31,OFFSET($V$8,$W$3,0):$V$31,V33),"") -> 22253523
B34: 27 | C34: 2028 | D34: =F34 -> 33940371 | E34: =IF($B34>$F$3, OFFSET(H34, - $F$3, 0), "") -> 21093019 | F34: =IF($B34>$F$3, TREND(OFFSET($D$8,$F$3,0):$D$31,OFFSET($E$8,$F$3,0):$E$31,E34,$F$1),"") -> 33940371 | H34: =J34 -> 22347378 | I34: =IF($B34>$J$3, OFFSET(L34, - $J$3, 0), "") -> 84992.9 | J34: =IF($B34>$J$3, TREND(OFFSET($H$8,$J$3,0):$H$31,OFFSET($I$8,$J$3,0):$I$31,I34),"") -> 22347378 | L34: =O34 -> 165816.41 | M34: =IF($B34>$O$3, OFFSET(Q34, - $O$3, 0), "") -> 4651.6729 | N34: =IF($B34>$O$3, OFFSET(H34, - $O$3, 0), "") -> 10979480 | O34: =IF($B34>$O$3, TREND(OFFSET($L$8,$O$3,0):$L$31,(OFFSET($M$8,$O$3,0):$N$31),M34:N34,$O$1),"") -> 165816.41 | Q34: =S34 -> 4450.4422 | R34: =IF($B34>$S$3, OFFSET(U34, - $S$3, 0), "") -> 4675803.2 | S34: =IF($B34>$S$3, TREND(OFFSET($Q$8,$S$3,0):$Q$31,OFFSET($R$8,$S$3,0):$R$31,R34,$S$1),"") -> 4450.4422 | U34: =W34 -> 23419864 | V34: =IF($B34>$W$3, OFFSET(D34, - $W$3, 0), "") -> 13515794 | W34: =IF($B34>$W$3, TREND(OFFSET($U$8,$W$3,0):$U$31,OFFSET($V$8,$W$3,0):$V$31,V34),"") -> 23419864
B35: 28 | C35: 2029 | D35: =F35 -> 35891539 | E35: =IF($B35>$F$3, OFFSET(H35, - $F$3, 0), "") -> 22347378 | F35: =IF($B35>$F$3, TREND(OFFSET($D$8,$F$3,0):$D$31,OFFSET($E$8,$F$3,0):$E$31,E35,$F$1),"") -> 35891539 | H35: =J35 -> 23855449 | I35: =IF($B35>$J$3, OFFSET(L35, - $J$3, 0), "") -> 91586 | J35: =IF($B35>$J$3, TREND(OFFSET($H$8,$J$3,0):$H$31,OFFSET($I$8,$J$3,0):$I$31,I35),"") -> 23855449 | L35: =O35 -> 190265.73 | M35: =IF($B35>$O$3, OFFSET(Q35, - $O$3, 0), "") -> 4634.638 | N35: =IF($B35>$O$3, OFFSET(H35, - $O$3, 0), "") -> 13819986 | O35: =IF($B35>$O$3, TREND(OFFSET($L$8,$O$3,0):$L$31,(OFFSET($M$8,$O$3,0):$N$31),M35:N35,$O$1),"") -> 190265.73 | Q35: =S35 -> 4371.2407 | R35: =IF($B35>$S$3, OFFSET(U35, - $S$3, 0), "") -> 5864573.2 | S35: =IF($B35>$S$3, TREND(OFFSET($Q$8,$S$3,0):$Q$31,OFFSET($R$8,$S$3,0):$R$31,R35,$S$1),"") -> 4371.2407 | U35: =W35 -> 23574607 | V35: =IF($B35>$W$3, OFFSET(D35, - $W$3, 0), "") -> 13615272 | W35: =IF($B35>$W$3, TREND(OFFSET($U$8,$W$3,0):$U$31,OFFSET($V$8,$W$3,0):$V$31,V35),"") -> 23574607
B36: 29 | C36: 2030 | D36: =F36 -> 38237361 | E36: =IF($B36>$F$3, OFFSET(H36, - $F$3, 0), "") -> 23855449 | F36: =IF($B36>$F$3, TREND(OFFSET($D$8,$F$3,0):$D$31,OFFSET($E$8,$F$3,0):$E$31,E36,$F$1),"") -> 38237361 | H36: =J36 -> 25287191 | I36: =IF($B36>$J$3, OFFSET(L36, - $J$3, 0), "") -> 97845.4 | J36: =IF($B36>$J$3, TREND(OFFSET($H$8,$J$3,0):$H$31,OFFSET($I$8,$J$3,0):$I$31,I36),"") -> 25287191 | L36: =O36 -> 214884.19 | M36: =IF($B36>$O$3, OFFSET(Q36, - $O$3, 0), "") -> 4624.025 | N36: =IF($B36>$O$3, OFFSET(H36, - $O$3, 0), "") -> 16660494 | O36: =IF($B36>$O$3, TREND(OFFSET($L$8,$O$3,0):$L$31,(OFFSET($M$8,$O$3,0):$N$31),M36:N36,$O$1),"") -> 214884.19 | Q36: =S36 -> 4315.8138 | R36: =IF($B36>$S$3, OFFSET(U36, - $S$3, 0), "") -> 6696500.4 | S36: =IF($B36>$S$3, TREND(OFFSET($Q$8,$S$3,0):$Q$31,OFFSET($R$8,$S$3,0):$R$31,R36,$S$1),"") -> 4315.8138 | U36: =W36 -> 25019800 | V36: =IF($B36>$W$3, OFFSET(D36, - $W$3, 0), "") -> 14544326 | W36: =IF($B36>$W$3, TREND(OFFSET($U$8,$W$3,0):$U$31,OFFSET($V$8,$W$3,0):$V$31,V36),"") -> 25019800
B37: 30 | C37: 2031 | D37: =F37 -> 40464452 | E37: =IF($B37>$F$3, OFFSET(H37, - $F$3, 0), "") -> 25287191 | F37: =IF($B37>$F$3, TREND(OFFSET($D$8,$F$3,0):$D$31,OFFSET($E$8,$F$3,0):$E$31,E37,$F$1),"") -> 40464452 | H37: =J37 -> 27740852 | I37: =IF($B37>$J$3, OFFSET(L37, - $J$3, 0), "") -> 108572.5 | J37: =IF($B37>$J$3, TREND(OFFSET($H$8,$J$3,0):$H$31,OFFSET($I$8,$J$3,0):$I$31,I37),"") -> 27740852 | L37: =O37 -> 245108.17 | M37: =IF($B37>$O$3, OFFSET(Q37, - $O$3, 0), "") -> 4571.133 | N37: =IF($B37>$O$3, OFFSET(H37, - $O$3, 0), "") -> 20267550 | O37: =IF($B37>$O$3, TREND(OFFSET($L$8,$O$3,0):$L$31,(OFFSET($M$8,$O$3,0):$N$31),M37:N37,$O$1),"") -> 245108.17 | Q37: =S37 -> 4300.0312 | R37: =IF($B37>$S$3, OFFSET(U37, - $S$3, 0), "") -> 6933386.9 | S37: =IF($B37>$S$3, TREND(OFFSET($Q$8,$S$3,0):$Q$31,OFFSET($R$8,$S$3,0):$R$31,R37,$S$1),"") -> 4300.0312 | U37: =W37 -> 27916497 | V37: =IF($B37>$W$3, OFFSET(D37, - $W$3, 0), "") -> 16406490 | W37: =IF($B37>$W$3, TREND(OFFSET($U$8,$W$3,0):$U$31,OFFSET($V$8,$W$3,0):$V$31,V37),"") -> 27916497
B38: 31 | C38: 2032 | D38: =F38 -> 44281148 | E38: =IF($B38>$F$3, OFFSET(H38, - $F$3, 0), "") -> 27740852 | F38: =IF($B38>$F$3, TREND(OFFSET($D$8,$F$3,0):$D$31,OFFSET($E$8,$F$3,0):$E$31,E38,$F$1),"") -> 44281148 | H38: =J38 -> 31389125 | I38: =IF($B38>$J$3, OFFSET(L38, - $J$3, 0), "") -> 124522.3 | J38: =IF($B38>$J$3, TREND(OFFSET($H$8,$J$3,0):$H$31,OFFSET($I$8,$J$3,0):$I$31,I38),"") -> 31389125 | L38: =O38 -> 230139.74 | M38: =IF($B38>$O$3, OFFSET(Q38, - $O$3, 0), "") -> 4559.6042 | N38: =IF($B38>$O$3, OFFSET(H38, - $O$3, 0), "") -> 18594505 | O38: =IF($B38>$O$3, TREND(OFFSET($L$8,$O$3,0):$L$31,(OFFSET($M$8,$O$3,0):$N$31),M38:N38,$O$1),"") -> 230139.74 | Q38: =S38 -> 4261.9692 | R38: =IF($B38>$S$3, OFFSET(U38, - $S$3, 0), "") -> 7504676.3 | S38: =IF($B38>$S$3, TREND(OFFSET($Q$8,$S$3,0):$Q$31,OFFSET($R$8,$S$3,0):$R$31,R38,$S$1),"") -> 4261.9692 | U38: =W38 -> 33099808 | V38: =IF($B38>$W$3, OFFSET(D38, - $W$3, 0), "") -> 19738623 | W38: =IF($B38>$W$3, TREND(OFFSET($U$8,$W$3,0):$U$31,OFFSET($V$8,$W$3,0):$V$31,V38),"") -> 33099808
B39: 32 | C39: 2033 | D39: =F39 -> 49956078 | E39: =IF($B39>$F$3, OFFSET(H39, - $F$3, 0), "") -> 31389125 | F39: =IF($B39>$F$3, TREND(OFFSET($D$8,$F$3,0):$D$31,OFFSET($E$8,$F$3,0):$E$31,E39,$F$1),"") -> 49956078 | H39: =J39 -> 36266002 | I39: =IF($B39>$J$3, OFFSET(L39, - $J$3, 0), "") -> 145843.4 | J39: =IF($B39>$J$3, TREND(OFFSET($H$8,$J$3,0):$H$31,OFFSET($I$8,$J$3,0):$I$31,I39),"") -> 36266002 | L39: =O39 -> 233790.36 | M39: =IF($B39>$O$3, OFFSET(Q39, - $O$3, 0), "") -> 4505.2073 | N39: =IF($B39>$O$3, OFFSET(H39, - $O$3, 0), "") -> 19174438 | O39: =IF($B39>$O$3, TREND(OFFSET($L$8,$O$3,0):$L$31,(OFFSET($M$8,$O$3,0):$N$31),M39:N39,$O$1),"") -> 233790.36 | Q39: =S39 -> 4228.5854 | R39: =IF($B39>$S$3, OFFSET(U39, - $S$3, 0), "") -> 8005749.4 | S39: =IF($B39>$S$3, TREND(OFFSET($Q$8,$S$3,0):$Q$31,OFFSET($R$8,$S$3,0):$R$31,R39,$S$1),"") -> 4228.5854 | U39: =W39 -> 40258172 | V39: =IF($B39>$W$3, OFFSET(D39, - $W$3, 0), "") -> 24340433 | W39: =IF($B39>$W$3, TREND(OFFSET($U$8,$W$3,0):$U$31,OFFSET($V$8,$W$3,0):$V$31,V39),"") -> 40258172
B40: 33 | C40: 2034 | D40: =F40 -> 57542114 | E40: =IF($B40>$F$3, OFFSET(H40, - $F$3, 0), "") -> 36266002 | F40: =IF($B40>$F$3, TREND(OFFSET($D$8,$F$3,0):$D$31,OFFSET($E$8,$F$3,0):$E$31,E40,$F$1),"") -> 57542114 | H40: =J40 -> 37822322 | I40: =IF($B40>$J$3, OFFSET(L40, - $J$3, 0), "") -> 152647.44 | J40: =IF($B40>$J$3, TREND(OFFSET($H$8,$J$3,0):$H$31,OFFSET($I$8,$J$3,0):$I$31,I40),"") -> 37822322 | L40: =O40 -> 249931.07 | M40: =IF($B40>$O$3, OFFSET(Q40, - $O$3, 0), "") -> 4479.5298 | N40: =IF($B40>$O$3, OFFSET(H40, - $O$3, 0), "") -> 21093019 | O40: =IF($B40>$O$3, TREND(OFFSET($L$8,$O$3,0):$L$31,(OFFSET($M$8,$O$3,0):$N$31),M40:N40,$O$1),"") -> 249931.07 | Q40: =S40 -> 4199.9675 | R40: =IF($B40>$S$3, OFFSET(U40, - $S$3, 0), "") -> 8435287.1 | S40: =IF($B40>$S$3, TREND(OFFSET($Q$8,$S$3,0):$Q$31,OFFSET($R$8,$S$3,0):$R$31,R40,$S$1),"") -> 4199.9675 | U40: =W40 -> 47782106 | V40: =IF($B40>$W$3, OFFSET(D40, - $W$3, 0), "") -> 29177254 | W40: =IF($B40>$W$3, TREND(OFFSET($U$8,$W$3,0):$U$31,OFFSET($V$8,$W$3,0):$V$31,V40),"") -> 47782106
B41: 34 | C41: 2035 | D41: =F41 -> 59962988 | E41: =IF($B41>$F$3, OFFSET(H41, - $F$3, 0), "") -> 37822322 | F41: =IF($B41>$F$3, TREND(OFFSET($D$8,$F$3,0):$D$31,OFFSET($E$8,$F$3,0):$E$31,E41,$F$1),"") -> 59962988 | H41: =J41 -> 37993963 | I41: =IF($B41>$J$3, OFFSET(L41, - $J$3, 0), "") -> 153397.83 | J41: =IF($B41>$J$3, TREND(OFFSET($H$8,$J$3,0):$H$31,OFFSET($I$8,$J$3,0):$I$31,I41),"") -> 37993963 | L41: =O41 -> 260159.84 | M41: =IF($B41>$O$3, OFFSET(Q41, - $O$3, 0), "") -> 4450.4422 | N41: =IF($B41>$O$3, OFFSET(H41, - $O$3, 0), "") -> 22347378 | O41: =IF($B41>$O$3, TREND(OFFSET($L$8,$O$3,0):$L$31,(OFFSET($M$8,$O$3,0):$N$31),M41:N41,$O$1),"") -> 260159.84 | Q41: =S41 -> 4169.6812 | R41: =IF($B41>$S$3, OFFSET(U41, - $S$3, 0), "") -> 8889867.7 | S41: =IF($B41>$S$3, TREND(OFFSET($Q$8,$S$3,0):$Q$31,OFFSET($R$8,$S$3,0):$R$31,R41,$S$1),"") -> 4169.6812 | U41: =W41 -> 52894414 | V41: =IF($B41>$W$3, OFFSET(D41, - $W$3, 0), "") -> 32463741 | W41: =IF($B41>$W$3, TREND(OFFSET($U$8,$W$3,0):$U$31,OFFSET($V$8,$W$3,0):$V$31,V41),"") -> 52894414

Sheet Модель
F1: база с: | I1: Корреляция по модулю: | Y1: Связи по максимальной корреляции
F2: 2 | H2: {=TRANSPOSE(D10:H10)} -> ВВП | J2: =ABS(CORREL(OFFSET($D$10,$F2,0):$D$34,OFFSET(J$10,$F2,0):J$34)) -> #DIV/0! | K2: =ABS(CORREL(OFFSET($D$10,$F2,0):$D$34,OFFSET(K$10,$F2,0):K$34)) -> #DIV/0! | L2: =ABS(CORREL(OFFSET($D$10,$F2,0):$D$34,OFFSET(L$10,$F2,0):L$34)) -> #DIV/0! | M2: =ABS(CORREL(OFFSET($D$10,$F2,0):$D$34,OFFSET(M$10,$F2,0):M$34)) -> #DIV/0! | O2: =ABS(CORREL(OFFSET($D$10,$F2,0):$D$34,OFFSET(O$10,$F2,0):O$34)) -> #DIV/0! | P2: =ABS(CORREL(OFFSET($D$10,$F2,0):$D$34,OFFSET(P$10,$F2,0):P$34)) -> #DIV/0! | Q2: =ABS(CORREL(OFFSET($D$10,$F2,0):$D$34,OFFSET(Q$10,$F2,0):Q$34)) -> #DIV/0! | R2: =ABS(CORREL(OFFSET($D$10,$F2,0):$D$34,OFFSET(R$10,$F2,0):R$34)) -> #DIV/0! | T2: =ABS(CORREL(OFFSET($D$10,$F2,0):$D$34,OFFSET(T$10,$F2,0):T$34)) -> #DIV/0! | U2: =ABS(CORREL(OFFSET($D$10,$F2,0):$D$34,OFFSET(U$10,$F2,0):U$34)) -> #DIV/0! | V2: =ABS(CORREL(OFFSET($D$10,$F2,0):$D$34,OFFSET(V$10,$F2,0):V$34)) -> #DIV/0! | W2: =ABS(CORREL(OFFSET($D$10,$F2,0):$D$34,OFFSET(W$10,$F2,0):W$34)) -> #DIV/0!
F3: 2 | H3: ВДС | I3: =ABS(CORREL(OFFSET($E$10,$F3,0):$E$34,OFFSET(I$10,$F3,0):I$34)) -> #DIV/0! | K3: =ABS(CORREL(OFFSET($E$10,$F3,0):$E$34,OFFSET(K$10,$F3,0):K$34)) -> #DIV/0! | L3: =ABS(CORREL(OFFSET($E$10,$F3,0):$E$34,OFFSET(L$10,$F3,0):L$34)) -> #DIV/0! | M3: =ABS(CORREL(OFFSET($E$10,$F3,0):$E$34,OFFSET(M$10,$F3,0):M$34)) -> #DIV/0! | N3: =ABS(CORREL(OFFSET($E$10,$F3,0):$E$34,OFFSET(N$10,$F3,0):N$34)) -> #DIV/0! | P3: =ABS(CORREL(OFFSET($E$10,$F3,0):$E$34,OFFSET(P$10,$F3,0):P$34)) -> #DIV/0! | Q3: =ABS(CORREL(OFFSET($E$10,$F3,0):$E$34,OFFSET(Q$10,$F3,0):Q$34)) -> #DIV/0! | R3: =ABS(CORREL(OFFSET($E$10,$F3,0):$E$34,OFFSET(R$10,$F3,0):R$34)) -> #DIV/0! | S3: =ABS(CORREL(OFFSET($E$10,$F3,0):$E$34,OFFSET(S$10,$F3,0):S$34)) -> #DIV/0! | U3: =ABS(CORREL(OFFSET($E$10,$F3,0):$E$34,OFFSET(U$10,$F3,0):U$34)) -> #DIV/0! | V3: =ABS(CORREL(OFFSET($E$10,$F3,0):$E$34,OFFSET(V$10,$F3,0):V$34)) -> #DIV/0! | W3: =ABS(CORREL(OFFSET($E$10,$F3,0):$E$34,OFFSET(W$10,$F3,0):W$34)) -> #DIV/0!
