Workbook

Sheet Титул
B1: Занятие № | C1: 2
B2: группа | C2: ПМ-2541
B3: студент | C3: Петров ГА
B4: вариант | C4: 11 | D4: Всего по перечисленным видам деятельности
A6: 0 | B6: Авторизовать файл: | N6: ="Например: "&SUBSTITUTE(C2,"-","")&" "&RIGHT("0"&C1,2)&" "&SUBSTITUTE(SUBSTITUTE(C3,".","")," ","") -> Например: ПМ2541 02 ПетровГА
B7: - сохранить файл, дав ему название по шаблону: <Группа_без_тире> <номер_занятия_двумя_цифрами> <ФамилияИО>
B8: - исправить внутри файла группу и фамилию
B10: Тема: | C10: Получение интервального прогноза на основе вариантов трендовых моделей
B11: Задачи: | C11: - графическая модель
C12: - [обычная] модель тренда
C13: - взвешенные критерии
C14: - параметризация тренда по альтернативным МНК критериям
C15: - деление ряда на участки
A17: 1 | B17: В качестве исходных данных взять результат предыдущей работы (пять сопоставимых рядов макроэкономических показателей) - рис.1.
B18: Для детального анализа взять один из рядов, например ВВП.
A20: 2 | B20: Построение (точечного и интервального) прогнозов разными способами
A21: 2.1 | B21: Графически
B22: Добавив в таблицу прогнозные 5 лет, вывести ряд на график - рис.2.
B23: Используя панель рисования (Вставка - Фигуры), нарисовать канал ряда и тренд.
B24: Сделать вывод о типе тренда и прогнозных значениях на конец горизонта - рис.3.
B25: (Используя копию графика) Сделать вывод о возможном выделении краткосрочных тенденций - рис.3,1.
B26: Достоинством такого подхода является быстрота и наглядность при рассмотрении одного ряда. Если рядов много, требуется [математическая] формализация.
A28: 2.2 | B28: - [обычная] модель тренда | F28: Повторение бакалавриата
B29: Скопировать данные (ряда) на новый лист
B30: На графика вывести тренд(ы) определённого ранее типа. Сделать вывод, какой расчётный тренд соответствует графической модели - рис.4.
B31: (Если у выбранного тренда параметры уравнения на графике представлены в научном формате) Представить параметры уравнения тренда в числовом формате - рис.5.
B32: Рассчитать параметры уравнения тренда, используя функции MS Excel - (для полинома - рис.6) | K32: Для прочих трендов надо использовать ф.ОТРЕЗОК() и НАКЛОН().
B33: Рассчитать трендовые значения, используя функции MS Excel - (для полинома - рис.7) | K33: Для прочих трендов надо использовать: | O33: линейный - ф.ПРЕДСКАЗ() или ТЕНДЕНЦИЯ()
B34: Рассчитать ошибку тренда, её крайние значения - рис.8. | O34: экспоненциальный - ф.РОСТ()
B35: Рассчитать значения границ канала, добавив к тренду крайние значения ошибок. Вывести их на график. Записать вывод. - рис.9. | O35: логарифмический - ф.ТЕНДЕНЦИЯ (от логарифмов времён)
B36: В данном случае получаем более количественно определённые прогнозные значения (чем в графической модели).
B37: Недостаком канала [с параллельными границами] можно считать, что они опираются только на одно фактическое значение.
B38: Поэтому построим сначала границы канала, а затем тренд.
A40: 2.3 | B40: рассчёт тренда, как средней между границами
B41: Скопировать лист
B42: Переписать рассчёт трендовых значений путём ссылки на параметры - рис.10. | K42: Сами трендовые значения, естественно, поменяться не должны.
B43: Рассчитать сумму квадратов ошибок по ф.СУММКВ() - рис.11. | K43: Минимизация которой является критерием рассчёта параметров по МНК.
B44: Используя Данные-ПоискРешения, поставить и решить задачу параметризации по МНК - рис.12. | K44: В результате решения значения параметров измениться не должны.
B45: Сделать КОПИЮ ЛИСТА для последующего видоизменения в другие модели
B46: Скопировать полученные параметры на свободное место.
...

Sheet Данные для анализа
A1: № | B1: года | C1: ВВП | D1: ВДС | E1: ОФ | F1: З/п | G1: Численность
A2: 1 | B2: 2002 | C2: 1523670.1 | D2: 854871.15 | E2: 663998.76 | F2: 7124.9669 | G2: 3013.1798 | I2: План:
A3: 2 | B3: 2003 | C3: 1899714.3 | D3: 1139219.2 | E3: 884858.7 | F3: 9472.4629 | G3: 3063.7504 | I3: Для ВВП - базовая модель
A4: 3 | B4: 2004 | C4: 2271976.8 | D4: 1403738.5 | E4: 1090317.1 | F4: 10821.718 | G4: 3114.321 | I4: - графическая
A5: 4 | B5: 2005 | C5: 2745199.6 | D5: 1677617.8 | E5: 1303045.7 | F5: 15014.028 | G5: 3164.8915 | I5: - расчётная
A6: 5 | B6: 2006 | C6: 3476075.5 | D6: 2080056.5 | E6: 1615629.4 | F6: 18464.987 | G6: 3262.6488 | I6: Видоизменения базы:
A7: 6 | B7: 2007 | C7: 4183589 | D7: 2564917.6 | E7: 1992232.6 | F7: 23149.292 | G7: 3415.8645 | I7: - гирерпараметры - альтернативные значения
A8: 7 | B8: 2008 | C8: 5380452.4 | D8: 3296150.8 | E8: 2560198.8 | F8: 29243.136 | G8: 3564.3804
A9: 8 | B9: 2009 | C9: 5857652.2 | D9: 3853809.6 | E9: 2993345.6 | F9: 32827.13 | G9: 3721.285 | I9: Для остальных рядов - лучшую модель
A10: 9 | B10: 2010 | C10: 6511019.6 | D10: 4239214.9 | E10: 3292699.1 | F10: 34417.519 | G10: 3722.31
A11: 10 | B11: 2011 | C11: 7448243.4 | D11: 4675803.2 | E11: 3631807.6 | F11: 38027.271 | G11: 3588.897
A12: 11 | B12: 2012 | C12: 8915955.3 | D12: 5864573.2 | E12: 6188755.7 | F12: 48913.794 | G12: 3517.73
A13: 12 | B13: 2013 | C13: 10017462 | D13: 6696500.4 | E13: 7066670.2 | F13: 55417.977 | G13: 3511.383
A14: 13 | B14: 2014 | C14: 9925208.1 | D14: 6933386.9 | E14: 7517411.3 | F14: 58446.403 | G14: 3511.895
A15: 14 | B15: 2015 | C15: 10706582 | D15: 7504676.3 | E15: 7806214.9 | F15: 57428.57 | G15: 3506.102
A16: 15 | B16: 2016 | C16: 11852882 | D16: 8005749.4 | E16: 8342022.6 | F16: 59750.309 | G16: 3420.6927
A17: 16 | B17: 2017 | C17: 12766003 | D17: 8435287.1 | E17: 8435287.1 | F17: 71121.2 | G17: 4608.7519
A18: 17 | B18: 2018 | C18: 13515794 | D18: 8889867.7 | E18: 8889867.7 | F18: 79509 | G18: 4690.2311
A19: 18 | B19: 2019 | C19: 13615272 | D19: 9318440.2 | E19: 9438926.1 | F19: 84992.9 | G19: 4692.8642
A20: 19 | B20: 2020 | C20: 14544326 | D20: 9987984.4 | E20: 9987984.4 | F20: 91586 | G20: 4732.6019
A21: 20 | B21: 2021 | C21: 16406490 | D21: 12989467 | E21: 10979480 | F21: 97845.4 | G21: 4651.6729
... A24: 23 | B24: 2024 | C24: 29177254 | D24: 20267550 | E24: 20267550 | F24: 145843.4 | G24: 4571.133
A25: 24 | B25: 2025 | C25: 32463741 | D25: 22639157
A26: 25 | B26: 2026
A27: 26 | B27: 2027
A28: 27 | B28: 2028
A29: 28 | B29: 2029
A30: 29 | B30: 2030
A31: 30 | B31: 2031
A32: 31 | B32: 2032
A33: 32 | B33: 2033
A34: 33 | B34: 2034
A35: 34 | B35: 2035

Sheet База
A1: Гиперпараметры:
B2: вид: | C2: линейная
B3: база: | C3: все данные
B4: параметры: | C4: a= | D4: =INTERCEPT($C$16:$C$39,$A$16:$A$39) -> -2648754.7
C5: b= | D5: =SLOPE($C$16:$C$39,$A$16:$A$39) -> 1109512.4
B6: ошибка: | C6: разность
B7: критерий: | C7: сумма квадратов
B8: распределение: | C8: нормально ( 0 ) | D8: по стьюденту ( 1 ) | E8: 1
B9: надёжность дов.инт.: | C9: 1e-06
B10: постоянство ширины: | C10: постоянная | D10: квадратическое
B11: Талия канала: | D11: середина исх.данных
B12: ширина дов.интервал: | C12: =IF(E8=0, _xlfn.CONFIDENCE.NORM(C9,STDEVA(H16:H39),A39), _xlfn.CONFIDENCE.T(C9,STDEVA(H16:H39),A39) ) -> 4015225.3
A14: № | B14: года | C14: ВВП | D14: тренд | E14: довер.интервал | G14: тренд | H14: Ошибка | I14: Ошибка сорт.
A15: X | C15: Y | D15: Y^ | E15: низ | F15: верх | G15: ПРЕДСКАЗ() | H15: Err=Y - Y^ | I15: Err sort
A16: 1 | B16: 2002 | C16: ='Данные для анализа'!C2 -> 1523670.1 | D16: =$D$4 + $D$5*$A16 -> -1539242.3 | E16: =$D16 - $C$12*(1 + ($A16-$A$39/2)^2 / (STDEVA($A$16:$A$39))^2 )^0.5 -> -8964695.7 | F16: =$D16 + $C$12*(1 + ($A16-$A$39/2)^2 / (STDEVA($A$16:$A$39))^2 )^0.5 -> 5886211.1 | G16: =FORECAST($A16,$C$16:$C$39,$A$16:$A$39) -> -1539242.3 | H16: =C16 - D16 -> 3062912.4 | I16: =SMALL($H$16:$H$39,A16) -> -3887655.9
A17: 2 | B17: 2003 | C17: ='Данные для анализа'!C3 -> 1899714.3 | D17: =$D$4 + $D$5*$A17 -> -429729.86 | E17: =$D17 - $C$12*(1 + ($A17-$A$39/2)^2 / (STDEVA($A$16:$A$39))^2 )^0.5 -> -7384304.1 | F17: =$D17 + $C$12*(1 + ($A17-$A$39/2)^2 / (STDEVA($A$16:$A$39))^2 )^0.5 -> 6524844.4 | G17: =FORECAST($A17,$C$16:$C$39,$A$16:$A$39) -> -429729.86 | H17: =C17 - D17 -> 2329444.1 | I17: =SMALL($H$16:$H$39,A17) -> -3707197.2
A18: 3 | B18: 2004 | C18: ='Данные для анализа'!C4 -> 2271976.8 | D18: =$D$4 + $D$5*$A18 -> 679782.57 | E18: =$D18 - $C$12*(1 + ($A18-$A$39/2)^2 / (STDEVA($A$16:$A$39))^2 )^0.5 -> -5819427.4 | F18: =$D18 + $C$12*(1 + ($A18-$A$39/2)^2 / (STDEVA($A$16:$A$39))^2 )^0.5 -> 7178992.5 | G18: =FORECAST($A18,$C$16:$C$39,$A$16:$A$39) -> 679782.57 | H18: =C18 - D18 -> 1592194.2 | I18: =SMALL($H$16:$H$39,A18) -> -3135003.6
A19: 4 | B19: 2005 | C19: ='Данные для анализа'!C5 -> 2745199.6 | D19: =$D$4 + $D$5*$A19 -> 1789295 | E19: =$D19 - $C$12*(1 + ($A19-$A$39/2)^2 / (STDEVA($A$16:$A$39))^2 )^0.5 -> -4273562.3 | F19: =$D19 + $C$12*(1 + ($A19-$A$39/2)^2 / (STDEVA($A$16:$A$39))^2 )^0.5 -> 7852152.3 | G19: =FORECAST($A19,$C$16:$C$39,$A$16:$A$39) -> 1789295 | H19: =C19 - D19 -> 955904.62 | I19: =SMALL($H$16:$H$39,A19) -> -2697162.7
A20: 5 | B20: 2006 | C20: ='Данные для анализа'!C6 -> 3476075.5 | D20: =$D$4 + $D$5*$A20 -> 2898807.4 | E20: =$D20 - $C$12*(1 + ($A20-$A$39/2)^2 / (STDEVA($A$16:$A$39))^2 )^0.5 -> -2751115.4 | F20: =$D20 + $C$12*(1 + ($A20-$A$39/2)^2 / (STDEVA($A$16:$A$39))^2 )^0.5 -> 8548730.3 | G20: =FORECAST($A20,$C$16:$C$39,$A$16:$A$39) -> 2898807.4 | H20: =C20 - D20 -> 577268.1 | I20: =SMALL($H$16:$H$39,A20) -> -2337441.4
A21: 6 | B21: 2007 | C21: ='Данные для анализа'!C7 -> 4183589 | D21: =$D$4 + $D$5*$A21 -> 4008319.9 | E21: =$D21 - $C$12*(1 + ($A21-$A$39/2)^2 / (STDEVA($A$16:$A$39))^2 )^0.5 -> -1257598.8 | F21: =$D21 + $C$12*(1 + ($A21-$A$39/2)^2 / (STDEVA($A$16:$A$39))^2 )^0.5 -> 9274238.5 | G21: =FORECAST($A21,$C$16:$C$39,$A$16:$A$39) -> 4008319.9 | H21: =C21 - D21 -> 175269.17 | I21: =SMALL($H$16:$H$39,A21) -> -2177837.3
A22: 7 | B22: 2008 | C22: ='Данные для анализа'!C8 -> 5380452.4 | D22: =$D$4 + $D$5*$A22 -> 5117832.3 | E22: =$D22 - $C$12*(1 + ($A22-$A$39/2)^2 / (STDEVA($A$16:$A$39))^2 )^0.5 -> 200205.7 | F22: =$D22 + $C$12*(1 + ($A22-$A$39/2)^2 / (STDEVA($A$16:$A$39))^2 )^0.5 -> 10035459 | G22: =FORECAST($A22,$C$16:$C$39,$A$16:$A$39) -> 5117832.3 | H22: =C22 - D22 -> 262620.11 | I22: =SMALL($H$16:$H$39,A22) -> -2141050.1
A23: 8 | B23: 2009 | C23: ='Данные для анализа'!C9 -> 5857652.2 | D23: =$D$4 + $D$5*$A23 -> 6227344.8 | E23: =$D23 - $C$12*(1 + ($A23-$A$39/2)^2 / (STDEVA($A$16:$A$39))^2 )^0.5 -> 1614202.1 | F23: =$D23 + $C$12*(1 + ($A23-$A$39/2)^2 / (STDEVA($A$16:$A$39))^2 )^0.5 -> 10840487 | G23: =FORECAST($A23,$C$16:$C$39,$A$16:$A$39) -> 6227344.8 | H23: =C23 - D23 -> -369692.52 | I23: =SMALL($H$16:$H$39,A23) -> -1849698.8
A24: 9 | B24: 2010 | C24: ='Данные для анализа'!C10 -> 6511019.6 | D24: =$D$4 + $D$5*$A24 -> 7336857.2 | E24: =$D24 - $C$12*(1 + ($A24-$A$39/2)^2 / (STDEVA($A$16:$A$39))^2 )^0.5 -> 2975206.1 | F24: =$D24 + $C$12*(1 + ($A24-$A$39/2)^2 / (STDEVA($A$16:$A$39))^2 )^0.5 -> 11698508 | G24: =FORECAST($A24,$C$16:$C$39,$A$16:$A$39) -> 7336857.2 | H24: =C24 - D24 -> -825837.61 | I24: =SMALL($H$16:$H$39,A24) -> -998126.18
A25: 10 | B25: 2011 | C25: ='Данные для анализа'!C11 -> 7448243.4 | D25: =$D$4 + $D$5*$A25 -> 8446369.6 | E25: =$D25 - $C$12*(1 + ($A25-$A$39/2)^2 / (STDEVA($A$16:$A$39))^2 )^0.5 -> 4273625.1 | F25: =$D25 + $C$12*(1 + ($A25-$A$39/2)^2 / (STDEVA($A$16:$A$39))^2 )^0.5 -> 12619114 | G25: =FORECAST($A25,$C$16:$C$39,$A$16:$A$39) -> 8446369.6 | H25: =C25 - D25 -> -998126.18 | I25: =SMALL($H$16:$H$39,A25) -> -912383.82
A26: 11 | B26: 2012 | C26: ='Данные для анализа'!C12 -> 8915955.3 | D26: =$D$4 + $D$5*$A26 -> 9555882.1 | E26: =$D26 - $C$12*(1 + ($A26-$A$39/2)^2 / (STDEVA($A$16:$A$39))^2 )^0.5 -> 5500703.3 | F26: =$D26 + $C$12*(1 + ($A26-$A$39/2)^2 / (STDEVA($A$16:$A$39))^2 )^0.5 -> 13611061 | G26: =FORECAST($A26,$C$16:$C$39,$A$16:$A$39) -> 9555882.1 | H26: =C26 - D26 -> -639926.73 | I26: =SMALL($H$16:$H$39,A26) -> -825837.61
A27: 12 | B27: 2013 | C27: ='Данные для анализа'!C13 -> 10017462 | D27: =$D$4 + $D$5*$A27 -> 10665394 | E27: =$D27 - $C$12*(1 + ($A27-$A$39/2)^2 / (STDEVA($A$16:$A$39))^2 )^0.5 -> 6650169.2 | F27: =$D27 + $C$12*(1 + ($A27-$A$39/2)^2 / (STDEVA($A$16:$A$39))^2 )^0.5 -> 14680620 | G27: =FORECAST($A27,$C$16:$C$39,$A$16:$A$39) -> 10665394 | H27: =C27 - D27 -> -647932.66 | I27: =SMALL($H$16:$H$39,A27) -> -647932.66
... A39: 24 | B39: 2025 | C39: ='Данные для анализа'!C25 -> 32463741 | D39: =$D$4 + $D$5*$A39 -> 23979544 | E39: =$D39 - $C$12*(1 + ($A39-$A$39/2)^2 / (STDEVA($A$16:$A$39))^2 )^0.5 -> 16070467 | F39: =$D39 + $C$12*(1 + ($A39-$A$39/2)^2 / (STDEVA($A$16:$A$39))^2 )^0.5 -> 31888620 | G39: =FORECAST($A39,$C$16:$C$39,$A$16:$A$39) -> 23979544 | H39: =C39 - D39 -> 8484197.2 | I39: =SMALL($H$16:$H$39,A39) -> 8484197.2
A40: 25 | B40: 2026 | D40: =$D$4 + $D$5*$A40 -> 25089056 | E40: =$D40 - $C$12*(1 + ($A40-$A$39/2)^2 / (STDEVA($A$16:$A$39))^2 )^0.5 -> 16685812 | F40: =$D40 + $C$12*(1 + ($A40-$A$39/2)^2 / (STDEVA($A$16:$A$39))^2 )^0.5 -> 33492300 | G40: =FORECAST($A40,$C$16:$C$39,$A$16:$A$39) -> 25089056
A41: 26 | B41: 2027 | D41: =$D$4 + $D$5*$A41 -> 26198569 | E41: =$D41 - $C$12*(1 + ($A41-$A$39/2)^2 / (STDEVA($A$16:$A$39))^2 )^0.5 -> 17292368 | F41: =$D41 + $C$12*(1 + ($A41-$A$39/2)^2 / (STDEVA($A$16:$A$39))^2 )^0.5 -> 35104769 | G41: =FORECAST($A41,$C$16:$C$39,$A$16:$A$39) -> 26198569
A42: 27 | B42: 2028 | D42: =$D$4 + $D$5*$A42 -> 27308081 | E42: =$D42 - $C$12*(1 + ($A42-$A$39/2)^2 / (STDEVA($A$16:$A$39))^2 )^0.5 -> 17891543 | F42: =$D42 + $C$12*(1 + ($A42-$A$39/2)^2 / (STDEVA($A$16:$A$39))^2 )^0.5 -> 36724619 | G42: =FORECAST($A42,$C$16:$C$39,$A$16:$A$39) -> 27308081
A43: 28 | B43: 2029 | D43: =$D$4 + $D$5*$A43 -> 28417593 | E43: =$D43 - $C$12*(1 + ($A43-$A$39/2)^2 / (STDEVA($A$16:$A$39))^2 )^0.5 -> 18484475 | F43: =$D43 + $C$12*(1 + ($A43-$A$39/2)^2 / (STDEVA($A$16:$A$39))^2 )^0.5 -> 38350712 | G43: =FORECAST($A43,$C$16:$C$39,$A$16:$A$39) -> 28417593
A44: 29 | B44: 2030 | D44: =$D$4 + $D$5*$A44 -> 29527106 | E44: =$D44 - $C$12*(1 + ($A44-$A$39/2)^2 / (STDEVA($A$16:$A$39))^2 )^0.5 -> 19072088 | F44: =$D44 + $C$12*(1 + ($A44-$A$39/2)^2 / (STDEVA($A$16:$A$39))^2 )^0.5 -> 39982124 | G44: =FORECAST($A44,$C$16:$C$39,$A$16:$A$39) -> 29527106
A45: 30 | B45: 2031 | D45: =$D$4 + $D$5*$A45 -> 30636618 | E45: =$D45 - $C$12*(1 + ($A45-$A$39/2)^2 / (STDEVA($A$16:$A$39))^2 )^0.5 -> 19655142 | F45: =$D45 + $C$12*(1 + ($A45-$A$39/2)^2 / (STDEVA($A$16:$A$39))^2 )^0.5 -> 41618094 | G45: =FORECAST($A45,$C$16:$C$39,$A$16:$A$39) -> 30636618
A46: 31 | B46: 2032 | D46: =$D$4 + $D$5*$A46 -> 31746131 | E46: =$D46 - $C$12*(1 + ($A46-$A$39/2)^2 / (STDEVA($A$16:$A$39))^2 )^0.5 -> 20234262 | F46: =$D46 + $C$12*(1 + ($A46-$A$39/2)^2 / (STDEVA($A$16:$A$39))^2 )^0.5 -> 43258000 | G46: =FORECAST($A46,$C$16:$C$39,$A$16:$A$39) -> 31746131
A47: 32 | B47: 2033 | D47: =$D$4 + $D$5*$A47 -> 32855643 | E47: =$D47 - $C$12*(1 + ($A47-$A$39/2)^2 / (STDEVA($A$16:$A$39))^2 )^0.5 -> 20809967 | F47: =$D47 + $C$12*(1 + ($A47-$A$39/2)^2 / (STDEVA($A$16:$A$39))^2 )^0.5 -> 44901319 | G47: =FORECAST($A47,$C$16:$C$39,$A$16:$A$39) -> 32855643
A48: 33 | B48: 2034 | D48: =$D$4 + $D$5*$A48 -> 33965156 | E48: =$D48 - $C$12*(1 + ($A48-$A$39/2)^2 / (STDEVA($A$16:$A$39))^2 )^0.5 -> 21382693 | F48: =$D48 + $C$12*(1 + ($A48-$A$39/2)^2 / (STDEVA($A$16:$A$39))^2 )^0.5 -> 46547619 | G48: =FORECAST($A48,$C$16:$C$39,$A$16:$A$39) -> 33965156
A49: 34 | B49: 2035 | D49: =$D$4 + $D$5*$A49 -> 35074668 | E49: =$D49 - $C$12*(1 + ($A49-$A$39/2)^2 / (STDEVA($A$16:$A$39))^2 )^0.5 -> 21952804 | F49: =$D49 + $C$12*(1 + ($A49-$A$39/2)^2 / (STDEVA($A$16:$A$39))^2 )^0.5 -> 48196533 | G49: =FORECAST($A49,$C$16:$C$39,$A$16:$A$39) -> 35074668

Sheet Ошибки
A1: Гиперпараметры: | I1: Гиперпараметры: | Q1: Гиперпараметры:
B2: вид: | C2: линейная | J2: вид: | K2: линейная | R2: вид: | S2: линейная
B3: база: | C3: все данные | D3: Искомые параметры | J3: база: | K3: все данные | L3: Искомые параметры | R3: база: | S3: все данные | T3: Искомые параметры
B4: параметры: | C4: a= | D4: 0 | J4: параметры: | K4: a= | L4: 356860.02 | R4: параметры: | S4: a= | T4: 395756.63
C5: b= | D5: 947343.78 | K5: b= | L5: 854661.63 | S5: b= | T5: 784609.45
B6: ошибка: | C6: разность | J6: ошибка: | K6: отношение | R6: ошибка: | S6: логарифм
B7: критерий: | C7: сумма квадратов | G7: =SUMSQ(G16:G39) -> 2.4427516e+14 | J7: критерий: | K7: сумма квадратов | O7: {=SUMSQ(O16:O39-1)} -> 1.1429692 | R7: критерий: | S7: сумма квадратов | W7: {=SUMSQ(W16:W39-1)} -> 0.0036181196
B8: распределение: | C8: нормально ( 0 ) | D8: по стьюденту ( 1 ) | E8: 1 | G8: цель ->min | J8: распределение: | K8: нормально ( 0 ) | L8: по стьюденту ( 1 ) | M8: 1 | O8: цель ->min | R8: распределение: | S8: нормально ( 0 ) | T8: по стьюденту ( 1 ) | U8: 1 | W8: цель ->min
B9: надёжность дов.инт.: | C9: 1e-06 | J9: надёжность дов.инт.: | K9: 1e-14 | R9: надёжность дов.инт.: | S9: 1e-10
B10: постоянство ширины: | C10: постоянная | D10: квадратическое | J10: постоянство ширины: | K10: постоянная | R10: постоянство ширины: | S10: постоянная
B11: Талия канала: | D11: середина исх.данных | J11: Талия канала: | R11: Талия канала:
B12: ширина дов.интервал: | C12: =IF(E8=0, _xlfn.CONFIDENCE.NORM(C9,STDEVA(G16:G39),A39), _xlfn.CONFIDENCE.T(C9,STDEVA(G16:G39),A39) ) -> 4301549.3 | J12: ширина дов.интервал: | K12: =IF(M8=0, _xlfn.CONFIDENCE.NORM(K9,STDEVA(O16:O39),I39), _xlfn.CONFIDENCE.T(K9,STDEVA(O16:O39),I39) ) -> 0.77206028 | R12: ширина дов.интервал: | S12: =IF(U8=0, _xlfn.CONFIDENCE.NORM(S9,STDEVA(W16:W39),Q39), _xlfn.CONFIDENCE.T(S9,STDEVA(W16:W39),Q39) ) -> 0.028461393
A14: № | B14: года | C14: ВВП | D14: тренд | E14: довер.интервал | G14: Ошибка | I14: № | J14: года | K14: ВВП | L14: тренд | M14: довер.интервал | O14: Относ. Ошибка | Q14: № | R14: года | S14: ВВП | T14: тренд | U14: довер.интервал | W14: лог. Ошибка
A15: X | C15: Y | D15: Y^ | E15: низ | F15: верх | G15: Err=Y - Y^ | I15: X | K15: Y | L15: Y^ | M15: низ | N15: верх | O15: Err=Y / Y^ | Q15: X | S15: Y | T15: Y^ | U15: низ | V15: верх | W15: Err= log (Y ; Y^)
A16: 1 | B16: 2002 | C16: ='Данные для анализа'!C2 -> 1523670.1 | D16: =$D$4 + $D$5*$A16 -> 947343.78 | E16: =$D16 - $C$12*(1 + ($A16-$A$39/2)^2 / (STDEVA($A$16:$A$39))^2 )^0.5 -> -7007615.5 | F16: =$D16 + $C$12*(1 + ($A16-$A$39/2)^2 / (STDEVA($A$16:$A$39))^2 )^0.5 -> 8902303.1 | G16: =C16 - D16 -> 576326.35 | I16: 1 | J16: 2002 | K16: =C16 -> 1523670.1 | L16: =$L$4 + $L$5*$A16 -> 1211521.7 | M16: =$L16 / $K$12 -> 1569206 | N16: =$L16 * $K$12 -> 935367.74 | O16: =K16 / L16 -> 1.2576499 | Q16: 1 | R16: 2002 | S16: =K16 -> 1523670.1 | T16: =$T$4 + $T$5*$A16 -> 1180366.1 | U16: =$T16^(1+$S$12) -> 1757255 | V16: =$T16^(1-$S$12) -> 792863.94 | W16: =LOG(S16, T16) -> 1.0182599
A17: 2 | B17: 2003 | C17: ='Данные для анализа'!C3 -> 1899714.3 | D17: =$D$4 + $D$5*$A17 -> 1894687.6 | E17: =$D17 - $C$12*(1 + ($A17-$A$39/2)^2 / (STDEVA($A$16:$A$39))^2 )^0.5 -> -5555814.4 | F17: =$D17 + $C$12*(1 + ($A17-$A$39/2)^2 / (STDEVA($A$16:$A$39))^2 )^0.5 -> 9345189.6 | G17: =C17 - D17 -> 5026.7244 | I17: 2 | J17: 2003 | K17: =C17 -> 1899714.3 | L17: =$L$4 + $L$5*$A17 -> 2066183.3 | M17: =$L17 / $K$12 -> 2676194.3 | N17: =$L17 * $K$12 -> 1595218 | O17: =K17 / L17 -> 0.91943164 | Q17: 2 | R17: 2003 | S17: =K17 -> 1899714.3 | T17: =$T$4 + $T$5*$A17 -> 1964975.5 | U17: =$T17 ^ (1+$S$12) -> 2968074.9 | V17: =$T17^(1-$S$12) -> 1300886.6 | W17: =LOG(S17, T17) -> 0.99766915
A18: 3 | B18: 2004 | C18: ='Данные для анализа'!C4 -> 2271976.8 | D18: =$D$4 + $D$5*$A18 -> 2842031.3 | E18: =$D18 - $C$12*(1 + ($A18-$A$39/2)^2 / (STDEVA($A$16:$A$39))^2 )^0.5 -> -4120634.5 | F18: =$D18 + $C$12*(1 + ($A18-$A$39/2)^2 / (STDEVA($A$16:$A$39))^2 )^0.5 -> 9804697.2 | G18: =C18 - D18 -> -570054.53 | I18: 3 | J18: 2004 | K18: =C18 -> 2271976.8 | L18: =$L$4 + $L$5*$A18 -> 2920844.9 | M18: =$L18 / $K$12 -> 3783182.5 | N18: =$L18 * $K$12 -> 2255068.3 | O18: =K18 / L18 -> 0.77784917 | Q18: 3 | R18: 2004 | S18: =K18 -> 2271976.8 | T18: =$T$4 + $T$5*$A18 -> 2749585 | U18: =$T18 ^ (1+$S$12) -> 4193123.6 | V18: =$T18^(1-$S$12) -> 1803003.8 | W18: =LOG(S18, T18) -> 0.98713157
A19: 4 | B19: 2005 | C19: ='Данные для анализа'!C5 -> 2745199.6 | D19: =$D$4 + $D$5*$A19 -> 3789375.1 | E19: =$D19 - $C$12*(1 + ($A19-$A$39/2)^2 / (STDEVA($A$16:$A$39))^2 )^0.5 -> -2705821.9 | F19: =$D19 + $C$12*(1 + ($A19-$A$39/2)^2 / (STDEVA($A$16:$A$39))^2 )^0.5 -> 10284572 | G19: =C19 - D19 -> -1044175.5 | I19: 4 | J19: 2005 | K19: =C19 -> 2745199.6 | L19: =$L$4 + $L$5*$A19 -> 3775506.6 | M19: =$L19 / $K$12 -> 4890170.7 | N19: =$L19 * $K$12 -> 2914918.6 | O19: =K19 / L19 -> 0.72710763 | Q19: 4 | R19: 2005 | S19: =K19 -> 2745199.6 | T19: =$T$4 + $T$5*$A19 -> 3534194.4 | U19: =$T19 ^ (1+$S$12) -> 5428300.8 | V19: =$T19^(1-$S$12) -> 2301001.8 | W19: =LOG(S19, T19) -> 0.98324502
A20: 5 | B20: 2006 | C20: ='Данные для анализа'!C6 -> 3476075.5 | D20: =$D$4 + $D$5*$A20 -> 4736718.9 | E20: =$D20 - $C$12*(1 + ($A20-$A$39/2)^2 / (STDEVA($A$16:$A$39))^2 )^0.5 -> -1316097.5 | F20: =$D20 + $C$12*(1 + ($A20-$A$39/2)^2 / (STDEVA($A$16:$A$39))^2 )^0.5 -> 10789535 | G20: =C20 - D20 -> -1260643.3 | I20: 5 | J20: 2006 | K20: =C20 -> 3476075.5 | L20: =$L$4 + $L$5*$A20 -> 4630168.2 | M20: =$L20 / $K$12 -> 5997158.9 | N20: =$L20 * $K$12 -> 3574768.9 | O20: =K20 / L20 -> 0.75074498 | Q20: 5 | R20: 2006 | S20: =K20 -> 3476075.5 | T20: =$T$4 + $T$5*$A20 -> 4318803.9 | U20: =$T20 ^ (1+$S$12) -> 6671372.2 | V20: =$T20^(1-$S$12) -> 2795836.6 | W20: =LOG(S20, T20) -> 0.98579215
A21: 6 | B21: 2007 | C21: ='Данные для анализа'!C7 -> 4183589 | D21: =$D$4 + $D$5*$A21 -> 5684062.7 | E21: =$D21 - $C$12*(1 + ($A21-$A$39/2)^2 / (STDEVA($A$16:$A$39))^2 )^0.5 -> 42633.603 | F21: =$D21 + $C$12*(1 + ($A21-$A$39/2)^2 / (STDEVA($A$16:$A$39))^2 )^0.5 -> 11325492 | G21: =C21 - D21 -> -1500473.6 | I21: 6 | J21: 2007 | K21: =C21 -> 4183589 | L21: =$L$4 + $L$5*$A21 -> 5484829.8 | M21: =$L21 / $K$12 -> 7104147.2 | N21: =$L21 * $K$12 -> 4234619.2 | O21: =K21 / L21 -> 0.7627564 | Q21: 6 | R21: 2007 | S21: =K21 -> 4183589 | T21: =$T$4 + $T$5*$A21 -> 5103413.3 | U21: =$T21 ^ (1+$S$12) -> 7920923.2 | V21: =$T21^(1-$S$12) -> 3288105 | W21: =LOG(S21, T21) -> 0.98713275
A22: 7 | B22: 2008 | C22: ='Данные для анализа'!C8 -> 5380452.4 | D22: =$D$4 + $D$5*$A22 -> 6631406.5 | E22: =$D22 - $C$12*(1 + ($A22-$A$39/2)^2 / (STDEVA($A$16:$A$39))^2 )^0.5 -> 1363106 | F22: =$D22 + $C$12*(1 + ($A22-$A$39/2)^2 / (STDEVA($A$16:$A$39))^2 )^0.5 -> 11899707 | G22: =C22 - D22 -> -1250954 | I22: 7 | J22: 2008 | K22: =C22 -> 5380452.4 | L22: =$L$4 + $L$5*$A22 -> 6339491.5 | M22: =$L22 / $K$12 -> 8211135.4 | N22: =$L22 * $K$12 -> 4894469.5 | O22: =K22 / L22 -> 0.84871988 | Q22: 7 | R22: 2008 | S22: =K22 -> 5380452.4 | T22: =$T$4 + $T$5*$A22 -> 5888022.8 | U22: =$T22 ^ (1+$S$12) -> 9175975.5 | V22: =$T22^(1-$S$12) -> 3778215.4 | W22: =LOG(S22, T22) -> 0.99421701
A23: 8 | B23: 2009 | C23: ='Данные для анализа'!C9 -> 5857652.2 | D23: =$D$4 + $D$5*$A23 -> 7578750.2 | E23: =$D23 - $C$12*(1 + ($A23-$A$39/2)^2 / (STDEVA($A$16:$A$39))^2 )^0.5 -> 2636646.3 | F23: =$D23 + $C$12*(1 + ($A23-$A$39/2)^2 / (STDEVA($A$16:$A$39))^2 )^0.5 -> 12520854 | G23: =C23 - D23 -> -1721098 | I23: 8 | J23: 2009 | K23: =C23 -> 5857652.2 | L23: =$L$4 + $L$5*$A23 -> 7194153.1 | M23: =$L23 / $K$12 -> 9318123.6 | N23: =$L23 * $K$12 -> 5554319.8 | O23: =K23 / L23 -> 0.81422402 | Q23: 8 | R23: 2009 | S23: =K23 -> 5857652.2 | T23: =$T$4 + $T$5*$A23 -> 6672632.2 | U23: =$T23 ^ (1+$S$12) -> 10435811 | V23: =$T23^(1-$S$12) -> 4266464.9 | W23: =LOG(S23, T23) -> 0.99170997
A24: 9 | B24: 2010 | C24: ='Данные для анализа'!C10 -> 6511019.6 | D24: =$D$4 + $D$5*$A24 -> 8526094 | E24: =$D24 - $C$12*(1 + ($A24-$A$39/2)^2 / (STDEVA($A$16:$A$39))^2 )^0.5 -> 3853415.4 | F24: =$D24 + $C$12*(1 + ($A24-$A$39/2)^2 / (STDEVA($A$16:$A$39))^2 )^0.5 -> 13198773 | G24: =C24 - D24 -> -2015074.4 | I24: 9 | J24: 2010 | K24: =C24 -> 6511019.6 | L24: =$L$4 + $L$5*$A24 -> 8048814.7 | M24: =$L24 / $K$12 -> 10425112 | N24: =$L24 * $K$12 -> 6214170.1 | O24: =K24 / L24 -> 0.80894142 | Q24: 9 | R24: 2010 | S24: =K24 -> 6511019.6 | T24: =$T$4 + $T$5*$A24 -> 7457241.6 | U24: =$T24 ^ (1+$S$12) -> 11699879 | V24: =$T24^(1-$S$12) -> 4753079.4 | W24: =LOG(S24, T24) -> 0.99142546
A25: 10 | B25: 2011 | C25: ='Данные для анализа'!C11 -> 7448243.4 | D25: =$D$4 + $D$5*$A25 -> 9473437.8 | E25: =$D25 - $C$12*(1 + ($A25-$A$39/2)^2 / (STDEVA($A$16:$A$39))^2 )^0.5 -> 5003136.6 | F25: =$D25 + $C$12*(1 + ($A25-$A$39/2)^2 / (STDEVA($A$16:$A$39))^2 )^0.5 -> 13943739 | G25: =C25 - D25 -> -2025194.3 | I25: 10 | J25: 2011 | K25: =C25 -> 7448243.4 | L25: =$L$4 + $L$5*$A25 -> 8903476.4 | M25: =$L25 / $K$12 -> 11532100 | N25: =$L25 * $K$12 -> 6874020.4 | O25: =K25 / L25 -> 0.83655453 | Q25: 10 | R25: 2011 | S25: =K25 -> 7448243.4 | T25: =$T$4 + $T$5*$A25 -> 8241851.1 | U25: =$T25 ^ (1+$S$12) -> 12967745 | V25: =$T25^(1-$S$12) -> 5238236 | W25: =LOG(S25, T25) -> 0.99364217
A26: 11 | B26: 2012 | C26: ='Данные для анализа'!C12 -> 8915955.3 | D26: =$D$4 + $D$5*$A26 -> 10420782 | E26: =$D26 - $C$12*(1 + ($A26-$A$39/2)^2 / (STDEVA($A$16:$A$39))^2 )^0.5 -> 6076429.7 | F26: =$D26 + $C$12*(1 + ($A26-$A$39/2)^2 / (STDEVA($A$16:$A$39))^2 )^0.5 -> 14765133 | G26: =C26 - D26 -> -1504826.2 | I26: 11 | J26: 2012 | K26: =C26 -> 8915955.3 | L26: =$L$4 + $L$5*$A26 -> 9758138 | M26: =$L26 / $K$12 -> 12639088 | N26: =$L26 * $K$12 -> 7533870.7 | O26: =K26 / L26 -> 0.91369433 | Q26: 11 | R26: 2012 | S26: =K26 -> 8915955.3 | T26: =$T$4 + $T$5*$A26 -> 9026460.5 | U26: =$T26 ^ (1+$S$12) -> 14239056 | V26: =$T26^(1-$S$12) -> 5722077.9 | W26: =LOG(S26, T26) -> 0.99923088
A27: 12 | B27: 2013 | C27: ='Данные для анализа'!C13 -> 10017462 | D27: =$D$4 + $D$5*$A27 -> 11368125 | E27: =$D27 - $C$12*(1 + ($A27-$A$39/2)^2 / (STDEVA($A$16:$A$39))^2 )^0.5 -> 7066576 | F27: =$D27 + $C$12*(1 + ($A27-$A$39/2)^2 / (STDEVA($A$16:$A$39))^2 )^0.5 -> 15669675 | G27: =C27 - D27 -> -1350663.5 | I27: 12 | J27: 2013 | K27: =C27 -> 10017462 | L27: =$L$4 + $L$5*$A27 -> 10612800 | M27: =$L27 / $K$12 -> 13746077 | N27: =$L27 * $K$12 -> 8193721 | O27: =K27 / L27 -> 0.94390379 | Q27: 12 | R27: 2013 | S27: =K27 -> 10017462 | T27: =$T$4 + $T$5*$A27 -> 9811070 | U27: =$T27 ^ (1+$S$12) -> 15513520 | V27: =$T27^(1-$S$12) -> 6204722.8 | W27: =LOG(S27, T27) -> 1.0012931
A28: 13 | B28: 2014 | C28: ='Данные для анализа'!C14 -> 9925208.1 | D28: =$D$4 + $D$5*$A28 -> 12315469 | E28: =$D28 - $C$12*(1 + ($A28-$A$39/2)^2 / (STDEVA($A$16:$A$39))^2 )^0.5 -> 7971117.2 | F28: =$D28 + $C$12*(1 + ($A28-$A$39/2)^2 / (STDEVA($A$16:$A$39))^2 )^0.5 -> 16659821 | G28: =C28 - D28 -> -2390261 | I28: 13 | J28: 2014 | K28: =C28 -> 9925208.1 | L28: =$L$4 + $L$5*$A28 -> 11467461 | M28: =$L28 / $K$12 -> 14853065 | N28: =$L28 * $K$12 -> 8853571.3 | O28: =K28 / L28 -> 0.8655105 | Q28: 13 | R28: 2014 | S28: =K28 -> 9925208.1 | T28: =$T$4 + $T$5*$A28 -> 10595679 | U28: =$T28 ^ (1+$S$12) -> 16790892 | V28: =$T28^(1-$S$12) -> 6686269.2 | W28: =LOG(S28, T28) -> 0.99595891
... A39: 24 | B39: 2025 | C39: ='Данные для анализа'!C25 -> 32463741 | D39: =$D$4 + $D$5*$A39 -> 22736251 | E39: =$D39 - $C$12*(1 + ($A39-$A$39/2)^2 / (STDEVA($A$16:$A$39))^2 )^0.5 -> 14263181 | F39: =$D39 + $C$12*(1 + ($A39-$A$39/2)^2 / (STDEVA($A$16:$A$39))^2 )^0.5 -> 31209320 | G39: =C39 - D39 -> 9727490.2 | I39: 24 | J39: 2025 | K39: =C39 -> 32463741 | L39: =$L$4 + $L$5*$A39 -> 20868739 | M39: =$L39 / $K$12 -> 27029935 | N39: =$L39 * $K$12 -> 16111925 | O39: =K39 / L39 -> 1.5556158 | Q39: 24 | R39: 2025 | S39: =K39 -> 32463741 | T39: =$T$4 + $T$5*$A39 -> 19226383 | U39: =$T39 ^ (1+$S$12) -> 30988993 | V39: =$T39^(1-$S$12) -> 11928552 | W39: =LOG(S39, T39) -> 1.0312334
A40: 25 | B40: 2026 | D40: =$D$4 + $D$5*$A40 -> 23683594 | E40: =$D40 - $C$12*(1 + ($A40-$A$39/2)^2 / (STDEVA($A$16:$A$39))^2 )^0.5 -> 14681119 | F40: =$D40 + $C$12*(1 + ($A40-$A$39/2)^2 / (STDEVA($A$16:$A$39))^2 )^0.5 -> 32686070 | I40: 25 | J40: 2026 | L40: =$L$4 + $L$5*$A40 -> 21723401 | M40: =$L40 / $K$12 -> 28136923 | N40: =$L40 * $K$12 -> 16771775 | Q40: 25 | R40: 2026 | T40: =$T$4 + $T$5*$A40 -> 20010993 | U40: =$T40 ^ (1+$S$12) -> 32290362 | V40: =$T40^(1-$S$12) -> 12401218
A41: 26 | B41: 2027 | D41: =$D$4 + $D$5*$A41 -> 24630938 | E41: =$D41 - $C$12*(1 + ($A41-$A$39/2)^2 / (STDEVA($A$16:$A$39))^2 )^0.5 -> 15089640 | F41: =$D41 + $C$12*(1 + ($A41-$A$39/2)^2 / (STDEVA($A$16:$A$39))^2 )^0.5 -> 34172236 | I41: 26 | J41: 2027 | L41: =$L$4 + $L$5*$A41 -> 22578063 | M41: =$L41 / $K$12 -> 29243912 | N41: =$L41 * $K$12 -> 17431625 | Q41: 26 | R41: 2027 | T41: =$T$4 + $T$5*$A41 -> 20795602 | U41: =$T41 ^ (1+$S$12) -> 33593184 | V41: =$T41^(1-$S$12) -> 12873358
A42: 27 | B42: 2028 | D42: =$D$4 + $D$5*$A42 -> 25578282 | E42: =$D42 - $C$12*(1 + ($A42-$A$39/2)^2 / (STDEVA($A$16:$A$39))^2 )^0.5 -> 15490255 | F42: =$D42 + $C$12*(1 + ($A42-$A$39/2)^2 / (STDEVA($A$16:$A$39))^2 )^0.5 -> 35666309 | I42: 27 | J42: 2028 | L42: =$L$4 + $L$5*$A42 -> 23432724 | M42: =$L42 / $K$12 -> 30350900 | N42: =$L42 * $K$12 -> 18091475 | Q42: 27 | R42: 2028 | T42: =$T$4 + $T$5*$A42 -> 21580212 | U42: =$T42 ^ (1+$S$12) -> 34897406 | V42: =$T42^(1-$S$12) -> 13344990
A43: 28 | B43: 2029 | D43: =$D$4 + $D$5*$A43 -> 26525626 | E43: =$D43 - $C$12*(1 + ($A43-$A$39/2)^2 / (STDEVA($A$16:$A$39))^2 )^0.5 -> 15884180 | F43: =$D43 + $C$12*(1 + ($A43-$A$39/2)^2 / (STDEVA($A$16:$A$39))^2 )^0.5 -> 37167071 | I43: 28 | J43: 2029 | L43: =$L$4 + $L$5*$A43 -> 24287386 | M43: =$L43 / $K$12 -> 31457888 | N43: =$L43 * $K$12 -> 18751326 | Q43: 28 | R43: 2029 | T43: =$T$4 + $T$5*$A43 -> 22364821 | U43: =$T43 ^ (1+$S$12) -> 36202978 | V43: =$T43^(1-$S$12) -> 13816135
A44: 29 | B44: 2030 | D44: =$D$4 + $D$5*$A44 -> 27472970 | E44: =$D44 - $C$12*(1 + ($A44-$A$39/2)^2 / (STDEVA($A$16:$A$39))^2 )^0.5 -> 16272409 | F44: =$D44 + $C$12*(1 + ($A44-$A$39/2)^2 / (STDEVA($A$16:$A$39))^2 )^0.5 -> 38673530 | I44: 29 | J44: 2030 | L44: =$L$4 + $L$5*$A44 -> 25142047 | M44: =$L44 / $K$12 -> 32564876 | N44: =$L44 * $K$12 -> 19411176 | Q44: 29 | R44: 2030 | T44: =$T$4 + $T$5*$A44 -> 23149431 | U44: =$T44 ^ (1+$S$12) -> 37509855 | V44: =$T44^(1-$S$12) -> 14286809
A45: 30 | B45: 2031 | D45: =$D$4 + $D$5*$A45 -> 28420313 | E45: =$D45 - $C$12*(1 + ($A45-$A$39/2)^2 / (STDEVA($A$16:$A$39))^2 )^0.5 -> 16655753 | F45: =$D45 + $C$12*(1 + ($A45-$A$39/2)^2 / (STDEVA($A$16:$A$39))^2 )^0.5 -> 40184874 | I45: 30 | J45: 2031 | L45: =$L$4 + $L$5*$A45 -> 25996709 | M45: =$L45 / $K$12 -> 33671865 | N45: =$L45 * $K$12 -> 20071026 | Q45: 30 | R45: 2031 | T45: =$T$4 + $T$5*$A45 -> 23934040 | U45: =$T45 ^ (1+$S$12) -> 38817994 | V45: =$T45^(1-$S$12) -> 14757029
A46: 31 | B46: 2032 | D46: =$D$4 + $D$5*$A46 -> 29367657 | E46: =$D46 - $C$12*(1 + ($A46-$A$39/2)^2 / (STDEVA($A$16:$A$39))^2 )^0.5 -> 17034882 | F46: =$D46 + $C$12*(1 + ($A46-$A$39/2)^2 / (STDEVA($A$16:$A$39))^2 )^0.5 -> 41700432 | I46: 31 | J46: 2032 | L46: =$L$4 + $L$5*$A46 -> 26851371 | M46: =$L46 / $K$12 -> 34778853 | N46: =$L46 * $K$12 -> 20730877 | Q46: 31 | R46: 2032 | T46: =$T$4 + $T$5*$A46 -> 24718649 | U46: =$T46 ^ (1+$S$12) -> 40127354 | V46: =$T46^(1-$S$12) -> 15226811
A47: 32 | B47: 2033 | D47: =$D$4 + $D$5*$A47 -> 30315001 | E47: =$D47 - $C$12*(1 + ($A47-$A$39/2)^2 / (STDEVA($A$16:$A$39))^2 )^0.5 -> 17410353 | F47: =$D47 + $C$12*(1 + ($A47-$A$39/2)^2 / (STDEVA($A$16:$A$39))^2 )^0.5 -> 43219649 | I47: 32 | J47: 2033 | L47: =$L$4 + $L$5*$A47 -> 27706032 | M47: =$L47 / $K$12 -> 35885841 | N47: =$L47 * $K$12 -> 21390727 | Q47: 32 | R47: 2033 | T47: =$T$4 + $T$5*$A47 -> 25503259 | U47: =$T47 ^ (1+$S$12) -> 41437898 | V47: =$T47^(1-$S$12) -> 15696168
A48: 33 | B48: 2034 | D48: =$D$4 + $D$5*$A48 -> 31262345 | E48: =$D48 - $C$12*(1 + ($A48-$A$39/2)^2 / (STDEVA($A$16:$A$39))^2 )^0.5 -> 17782631 | F48: =$D48 + $C$12*(1 + ($A48-$A$39/2)^2 / (STDEVA($A$16:$A$39))^2 )^0.5 -> 44742058 | I48: 33 | J48: 2034 | L48: =$L$4 + $L$5*$A48 -> 28560694 | M48: =$L48 / $K$12 -> 36992829 | N48: =$L48 * $K$12 -> 22050577 | Q48: 33 | R48: 2034 | T48: =$T$4 + $T$5*$A48 -> 26287868 | U48: =$T48 ^ (1+$S$12) -> 42749589 | V48: =$T48^(1-$S$12) -> 16165115
A49: 34 | B49: 2035 | D49: =$D$4 + $D$5*$A49 -> 32209688 | E49: =$D49 - $C$12*(1 + ($A49-$A$39/2)^2 / (STDEVA($A$16:$A$39))^2 )^0.5 -> 18152109 | F49: =$D49 + $C$12*(1 + ($A49-$A$39/2)^2 / (STDEVA($A$16:$A$39))^2 )^0.5 -> 46267268 | I49: 34 | J49: 2035 | L49: =$L$4 + $L$5*$A49 -> 29415356 | M49: =$L49 / $K$12 -> 38099817 | N49: =$L49 * $K$12 -> 22710428 | Q49: 34 | R49: 2035 | T49: =$T$4 + $T$5*$A49 -> 27072478 | U49: =$T49 ^ (1+$S$12) -> 44062396 | V49: =$T49^(1-$S$12) -> 16633663

Sheet NPV
A1: Гиперпараметры:
B2: вид: | C2: линейная
B3: база: | C3: все данные
B4: параметры: | C4: a= | F4: =INTERCEPT($E$16:$E$39,$A$16:$A$39) -> 734520.76
C5: b= | F5: =SLOPE($E$16:$E$39,$A$16:$A$39) -> 1062493.7
B6: ошибка: | C6: разность | D6: ставка приведения
B7: критерий: | C7: взвешенная сумма квадратов | D7: -0.03
B8: распределение: | C8: нормально ( 0 ) | F8: по стьюденту ( 1 ) | G8: 1
B9: надёжность дов.инт.: | C9: 1e-06
B10: постоянство ширины: | C10: постоянная | F10: квадратическое
B11: Талия канала: | F11: середина исх.данных
B12: ширина дов.интервал: | C12: =IF(G8=0, _xlfn.CONFIDENCE.NORM(C9,STDEVA(I16:I39),A39), _xlfn.CONFIDENCE.T(C9,STDEVA(I16:I39),A39) ) -> 3103043.8
A14: № | B14: года | C14: ВВП | D14: диск.множитель | E14: NPV | F14: тренд NPV | G14: довер.интервал NPV | I14: Ошибка NPV | J14: тренд ВВП | K14: довер.интервал ВВП
A15: X | C15: Y | D15: q- | E15: P = Y * q- | F15: NPV^ | G15: низ | H15: верх | I15: Err=Y - Y^ | J15: Y^=NPV^ / q- | K15: низ | L15: верх
A16: 1 | B16: 2002 | C16: ='Данные для анализа'!C2 -> 1523670.1 | D16: =(1+$D$7)^ ( - ($A$39-A16)) -> 2.0148843 | E16: =C16*D16 -> 3070019 | F16: =$F$4 + $F$5*$A16 -> 1797014.5 | G16: =$F16 - $C$12*(1 + ($A16-$A$39/2)^2 / (STDEVA($A$16:$A$39))^2 )^0.5 -> -3941519.6 | H16: =$F16 + $C$12*(1 + ($A16-$A$39/2)^2 / (STDEVA($A$16:$A$39))^2 )^0.5 -> 7535548.5 | I16: =E16 - F16 -> 1273004.5 | J16: =F16 / $D16 -> 891869.82 | K16: =G16 / $D16 -> -1956201.5 | L16: =H16 / $D16 -> 3739941.1
A17: 2 | B17: 2003 | C17: ='Данные для анализа'!C3 -> 1899714.3 | D17: =(1+$D$7)^ ( - ($A$39-A17)) -> 1.9544378 | E17: =C17*D17 -> 3712873.3 | F17: =$F$4 + $F$5*$A17 -> 2859508.2 | G17: =$F17 - $C$12*(1 + ($A17-$A$39/2)^2 / (STDEVA($A$16:$A$39))^2 )^0.5 -> -2515121.4 | H17: =$F17 + $C$12*(1 + ($A17-$A$39/2)^2 / (STDEVA($A$16:$A$39))^2 )^0.5 -> 8234137.8 | I17: =E17 - F17 -> 853365.13 | J17: =F17 / D17 -> 1463084.8 | K17: =G17 / $D17 -> -1286877.2 | L17: =H17 / $D17 -> 4213046.8
A18: 3 | B18: 2004 | C18: ='Данные для анализа'!C4 -> 2271976.8 | D18: =(1+$D$7)^ ( - ($A$39-A18)) -> 1.8958046 | E18: =C18*D18 -> 4307224.2 | F18: =$F$4 + $F$5*$A18 -> 3922001.9 | G18: =$F18 - $C$12*(1 + ($A18-$A$39/2)^2 / (STDEVA($A$16:$A$39))^2 )^0.5 -> -1100713.3 | H18: =$F18 + $C$12*(1 + ($A18-$A$39/2)^2 / (STDEVA($A$16:$A$39))^2 )^0.5 -> 8944717.2 | I18: =E18 - F18 -> 385222.22 | J18: =F18 / D18 -> 2068779.6 | K18: =G18 / $D18 -> -580604.82 | L18: =H18 / $D18 -> 4718164
A19: 4 | B19: 2005 | C19: ='Данные для анализа'!C5 -> 2745199.6 | D19: =(1+$D$7)^ ( - ($A$39-A19)) -> 1.8389305 | E19: =C19*D19 -> 5048231.3 | F19: =$F$4 + $F$5*$A19 -> 4984495.7 | G19: =$F19 - $C$12*(1 + ($A19-$A$39/2)^2 / (STDEVA($A$16:$A$39))^2 )^0.5 -> 299002.22 | H19: =$F19 + $C$12*(1 + ($A19-$A$39/2)^2 / (STDEVA($A$16:$A$39))^2 )^0.5 -> 9669989.1 | I19: =E19 - F19 -> 63735.653 | J19: =F19 / D19 -> 2710540.5 | K19: =G19 / $D19 -> 162595.71 | L19: =H19 / $D19 -> 5258485.4
A20: 5 | B20: 2006 | C20: ='Данные для анализа'!C6 -> 3476075.5 | D20: =(1+$D$7)^ ( - ($A$39-A20)) -> 1.7837626 | E20: =C20*D20 -> 6200493.5 | F20: =$F$4 + $F$5*$A20 -> 6046989.4 | G20: =$F20 - $C$12*(1 + ($A20-$A$39/2)^2 / (STDEVA($A$16:$A$39))^2 )^0.5 -> 1680619.7 | H20: =$F20 + $C$12*(1 + ($A20-$A$39/2)^2 / (STDEVA($A$16:$A$39))^2 )^0.5 -> 10413359 | I20: =E20 - F20 -> 153504.1 | J20: =F20 / D20 -> 3390019.2 | K20: =G20 / $D20 -> 942176.77 | L20: =H20 / $D20 -> 5837861.6
A21: 6 | B21: 2007 | C21: ='Данные для анализа'!C7 -> 4183589 | D21: =(1+$D$7)^ ( - ($A$39-A21)) -> 1.7302497 | E21: =C21*D21 -> 7238653.7 | F21: =$F$4 + $F$5*$A21 -> 7109483.1 | G21: =$F21 - $C$12*(1 + ($A21-$A$39/2)^2 / (STDEVA($A$16:$A$39))^2 )^0.5 -> 3039879.3 | H21: =$F21 + $C$12*(1 + ($A21-$A$39/2)^2 / (STDEVA($A$16:$A$39))^2 )^0.5 -> 11179087 | I21: =E21 - F21 -> 129170.59 | J21: =F21 / D21 -> 4108934.7 | K21: =G21 / $D21 -> 1756902.1 | L21: =H21 / $D21 -> 6460967.4
A22: 7 | B22: 2008 | C22: ='Данные для анализа'!C8 -> 5380452.4 | D22: =(1+$D$7)^ ( - ($A$39-A22)) -> 1.6783422 | E22: =C22*D22 -> 9030240.4 | F22: =$F$4 + $F$5*$A22 -> 8171976.8 | G22: =$F22 - $C$12*(1 + ($A22-$A$39/2)^2 / (STDEVA($A$16:$A$39))^2 )^0.5 -> 4371539.8 | H22: =$F22 + $C$12*(1 + ($A22-$A$39/2)^2 / (STDEVA($A$16:$A$39))^2 )^0.5 -> 11972414 | I22: =E22 - F22 -> 858263.58 | J22: =F22 / D22 -> 4869076.6 | K22: =G22 / $D22 -> 2604677.3 | L22: =H22 / $D22 -> 7133476
A23: 8 | B23: 2009 | C23: ='Данные для анализа'!C9 -> 5857652.2 | D23: =(1+$D$7)^ ( - ($A$39-A23)) -> 1.6279919 | E23: =C23*D23 -> 9536210.7 | F23: =$F$4 + $F$5*$A23 -> 9234470.6 | G23: =$F23 - $C$12*(1 + ($A23-$A$39/2)^2 / (STDEVA($A$16:$A$39))^2 )^0.5 -> 5669344.6 | H23: =$F23 + $C$12*(1 + ($A23-$A$39/2)^2 / (STDEVA($A$16:$A$39))^2 )^0.5 -> 12799597 | I23: =E23 - F23 -> 301740.1 | J23: =F23 / D23 -> 5672307.3 | K23: =G23 / $D23 -> 3482415.6 | L23: =H23 / $D23 -> 7862198.9
A24: 9 | B24: 2010 | C24: ='Данные для анализа'!C10 -> 6511019.6 | D24: =(1+$D$7)^ ( - ($A$39-A24)) -> 1.5791522 | E24: =C24*D24 -> 10281891 | F24: =$F$4 + $F$5*$A24 -> 10296964 | G24: =$F24 - $C$12*(1 + ($A24-$A$39/2)^2 / (STDEVA($A$16:$A$39))^2 )^0.5 -> 6926195.9 | H24: =$F24 + $C$12*(1 + ($A24-$A$39/2)^2 / (STDEVA($A$16:$A$39))^2 )^0.5 -> 13667733 | I24: =E24 - F24 -> -15073.474 | J24: =F24 / D24 -> 6520564.9 | K24: =G24 / $D24 -> 4386021.8 | L24: =H24 / $D24 -> 8655108
A25: 10 | B25: 2011 | C25: ='Данные для анализа'!C11 -> 7448243.4 | D25: =(1+$D$7)^ ( - ($A$39-A25)) -> 1.5317776 | E25: =C25*D25 -> 11409053 | F25: =$F$4 + $F$5*$A25 -> 11359458 | G25: =$F25 - $C$12*(1 + ($A25-$A$39/2)^2 / (STDEVA($A$16:$A$39))^2 )^0.5 -> 8134680.3 | H25: =$F25 + $C$12*(1 + ($A25-$A$39/2)^2 / (STDEVA($A$16:$A$39))^2 )^0.5 -> 14584236 | I25: =E25 - F25 -> 49594.62 | J25: =F25 / D25 -> 7415866.3 | K25: =G25 / $D25 -> 5310614.4 | L25: =H25 / $D25 -> 9521118.2
A26: 11 | B26: 2012 | C26: ='Данные для анализа'!C12 -> 8915955.3 | D26: =(1+$D$7)^ ( - ($A$39-A26)) -> 1.4858243 | E26: =C26*D26 -> 13247543 | F26: =$F$4 + $F$5*$A26 -> 12421952 | G26: =$F26 - $C$12*(1 + ($A26-$A$39/2)^2 / (STDEVA($A$16:$A$39))^2 )^0.5 -> 9288031.1 | H26: =$F26 + $C$12*(1 + ($A26-$A$39/2)^2 / (STDEVA($A$16:$A$39))^2 )^0.5 -> 15555872 | I26: =E26 - F26 -> 825591.29 | J26: =F26 / D26 -> 8360310 | K26: =G26 / $D26 -> 6251096.5 | L26: =H26 / $D26 -> 10469524
A27: 12 | B27: 2013 | C27: ='Данные для анализа'!C13 -> 10017462 | D27: =(1+$D$7)^ ( - ($A$39-A27)) -> 1.4412496 | E27: =C27*D27 -> 14437663 | F27: =$F$4 + $F$5*$A27 -> 13484445 | G27: =$F27 - $C$12*(1 + ($A27-$A$39/2)^2 / (STDEVA($A$16:$A$39))^2 )^0.5 -> 10381402 | H27: =$F27 + $C$12*(1 + ($A27-$A$39/2)^2 / (STDEVA($A$16:$A$39))^2 )^0.5 -> 16587489 | I27: =E27 - F27 -> 953217.05 | J27: =F27 / D27 -> 9356079.5 | K27: =G27 / $D27 -> 7203056.2 | L27: =H27 / $D27 -> 11509103
A28: 13 | B28: 2014 | C28: ='Данные для анализа'!C14 -> 9925208.1 | D28: =(1+$D$7)^ ( - ($A$39-A28)) -> 1.3980121 | E28: =C28*D28 -> 13875561 | F28: =$F$4 + $F$5*$A28 -> 14546939 | G28: =$F28 - $C$12*(1 + ($A28-$A$39/2)^2 / (STDEVA($A$16:$A$39))^2 )^0.5 -> 11413019 | H28: =$F28 + $C$12*(1 + ($A28-$A$39/2)^2 / (STDEVA($A$16:$A$39))^2 )^0.5 -> 17680860 | I28: =E28 - F28 -> -671378.4 | J28: =F28 / D28 -> 10405446 | K28: =G28 / $D28 -> 8163748.2 | L28: =H28 / $D28 -> 12647144
... A39: 24 | B39: 2025 | C39: ='Данные для анализа'!C25 -> 32463741 | D39: =(1+$D$7)^ ( - ($A$39-A39)) -> 1 | E39: =C39*D39 -> 32463741 | F39: =$F$4 + $F$5*$A39 -> 26234370 | G39: =$F39 - $C$12*(1 + ($A39-$A$39/2)^2 / (STDEVA($A$16:$A$39))^2 )^0.5 -> 20122083 | H39: =$F39 + $C$12*(1 + ($A39-$A$39/2)^2 / (STDEVA($A$16:$A$39))^2 )^0.5 -> 32346658 | I39: =E39 - F39 -> 6229370.7 | J39: =F39 / D39 -> 26234370 | K39: =G39 / $D39 -> 20122083 | L39: =H39 / $D39 -> 32346658
A40: 25 | B40: 2026 | D40: =(1+$D$7)^ ( - ($A$39-A40)) -> 0.97 | F40: =$F$4 + $F$5*$A40 -> 27296864 | G40: =$F40 - $C$12*(1 + ($A40-$A$39/2)^2 / (STDEVA($A$16:$A$39))^2 )^0.5 -> 20802674 | H40: =$F40 + $C$12*(1 + ($A40-$A$39/2)^2 / (STDEVA($A$16:$A$39))^2 )^0.5 -> 33791054 | J40: =F40 / D40 -> 28141097 | K40: =G40 / $D40 -> 21446056 | L40: =H40 / $D40 -> 34836138
A41: 26 | B41: 2027 | D41: =(1+$D$7)^ ( - ($A$39-A41)) -> 0.9409 | F41: =$F$4 + $F$5*$A41 -> 28359358 | G41: =$F41 - $C$12*(1 + ($A41-$A$39/2)^2 / (STDEVA($A$16:$A$39))^2 )^0.5 -> 21476473 | H41: =$F41 + $C$12*(1 + ($A41-$A$39/2)^2 / (STDEVA($A$16:$A$39))^2 )^0.5 -> 35242242 | J41: =F41 / D41 -> 30140671 | K41: =G41 / $D41 -> 22825458 | L41: =H41 / $D41 -> 37455885
A42: 27 | B42: 2028 | D42: =(1+$D$7)^ ( - ($A$39-A42)) -> 0.912673 | F42: =$F$4 + $F$5*$A42 -> 29421851 | G42: =$F42 - $C$12*(1 + ($A42-$A$39/2)^2 / (STDEVA($A$16:$A$39))^2 )^0.5 -> 22144568 | H42: =$F42 + $C$12*(1 + ($A42-$A$39/2)^2 / (STDEVA($A$16:$A$39))^2 )^0.5 -> 36699134 | J42: =F42 / D42 -> 32237013 | K42: =G42 / $D42 -> 24263420 | L42: =H42 / $D42 -> 40210606
A43: 28 | B43: 2029 | D43: =(1+$D$7)^ ( - ($A$39-A43)) -> 0.88529281 | F43: =$F$4 + $F$5*$A43 -> 30484345 | G43: =$F43 - $C$12*(1 + ($A43-$A$39/2)^2 / (STDEVA($A$16:$A$39))^2 )^0.5 -> 22807839 | H43: =$F43 + $C$12*(1 + ($A43-$A$39/2)^2 / (STDEVA($A$16:$A$39))^2 )^0.5 -> 38160852 | J43: =F43 / D43 -> 34434195 | K43: =G43 / $D43 -> 25763045 | L43: =H43 / $D43 -> 43105345
A44: 29 | B44: 2030 | D44: =(1+$D$7)^ ( - ($A$39-A44)) -> 0.85873403 | F44: =$F$4 + $F$5*$A44 -> 31546839 | G44: =$F44 - $C$12*(1 + ($A44-$A$39/2)^2 / (STDEVA($A$16:$A$39))^2 )^0.5 -> 23466999 | H44: =$F44 + $C$12*(1 + ($A44-$A$39/2)^2 / (STDEVA($A$16:$A$39))^2 )^0.5 -> 39626679 | J44: =F44 / D44 -> 36736449 | K44: =G44 / $D44 -> 27327436 | L44: =H44 / $D44 -> 46145462
A45: 30 | B45: 2031 | D45: =(1+$D$7)^ ( - ($A$39-A45)) -> 0.832972 | F45: =$F$4 + $F$5*$A45 -> 32609333 | G45: =$F45 - $C$12*(1 + ($A45-$A$39/2)^2 / (STDEVA($A$16:$A$39))^2 )^0.5 -> 24122635 | H45: =$F45 + $C$12*(1 + ($A45-$A$39/2)^2 / (STDEVA($A$16:$A$39))^2 )^0.5 -> 41096030 | J45: =F45 / D45 -> 39148173 | K45: =G45 / $D45 -> 28959719 | L45: =H45 / $D45 -> 49336628
A46: 31 | B46: 2032 | D46: =(1+$D$7)^ ( - ($A$39-A46)) -> 0.80798284 | F46: =$F$4 + $F$5*$A46 -> 33671826 | G46: =$F46 - $C$12*(1 + ($A46-$A$39/2)^2 / (STDEVA($A$16:$A$39))^2 )^0.5 -> 24775231 | H46: =$F46 + $C$12*(1 + ($A46-$A$39/2)^2 / (STDEVA($A$16:$A$39))^2 )^0.5 -> 42568421 | J46: =F46 / D46 -> 41673937 | K46: =G46 / $D46 -> 30663066 | L46: =H46 / $D46 -> 52684808
A47: 32 | B47: 2033 | D47: =(1+$D$7)^ ( - ($A$39-A47)) -> 0.78374336 | F47: =$F$4 + $F$5*$A47 -> 34734320 | G47: =$F47 - $C$12*(1 + ($A47-$A$39/2)^2 / (STDEVA($A$16:$A$39))^2 )^0.5 -> 25425188 | H47: =$F47 + $C$12*(1 + ($A47-$A$39/2)^2 / (STDEVA($A$16:$A$39))^2 )^0.5 -> 44043451 | J47: =F47 / D47 -> 44318487 | K47: =G47 / $D47 -> 32440707 | L47: =H47 / $D47 -> 56196268
A48: 33 | B48: 2034 | D48: =(1+$D$7)^ ( - ($A$39-A48)) -> 0.76023106 | F48: =$F$4 + $F$5*$A48 -> 35796814 | G48: =$F48 - $C$12*(1 + ($A48-$A$39/2)^2 / (STDEVA($A$16:$A$39))^2 )^0.5 -> 26072843 | H48: =$F48 + $C$12*(1 + ($A48-$A$39/2)^2 / (STDEVA($A$16:$A$39))^2 )^0.5 -> 45520785 | J48: =F48 / D48 -> 47086755 | K48: =G48 / $D48 -> 34295945 | L48: =H48 / $D48 -> 59877565
A49: 34 | B49: 2035 | D49: =(1+$D$7)^ ( - ($A$39-A49)) -> 0.73742413 | F49: =$F$4 + $F$5*$A49 -> 36859307 | G49: =$F49 - $C$12*(1 + ($A49-$A$39/2)^2 / (STDEVA($A$16:$A$39))^2 )^0.5 -> 26718477 | H49: =$F49 + $C$12*(1 + ($A49-$A$39/2)^2 / (STDEVA($A$16:$A$39))^2 )^0.5 -> 47000138 | J49: =F49 / D49 -> 49983864 | K49: =G49 / $D49 -> 36232170 | L49: =H49 / $D49 -> 63735558

Sheet ВДС
A1: Гиперпараметры:
B2: вид: | C2: линейная
B3: база: | C3: все данные
B4: параметры: | C4: a= | D4: =INTERCEPT($C$16:$C$39,$A$16:$A$39) -> -2309816.7
C5: b= | D5: =SLOPE($C$16:$C$39,$A$16:$A$39) -> 801806.33
B6: ошибка: | C6: разность
B7: критерий: | C7: сумма квадратов
B8: распределение: | C8: нормально ( 0 ) | D8: по стьюденту ( 1 ) | E8: 1
B9: надёжность дов.инт.: | C9: 1e-06
B10: постоянство ширины: | C10: постоянная | D10: квадратическое
B11: Талия канала: | D11: середина исх.данных
B12: ширина дов.интервал: | C12: =IF(E8=0, _xlfn.CONFIDENCE.NORM(C9,STDEVA(H16:H39),A39), _xlfn.CONFIDENCE.T(C9,STDEVA(H16:H39),A39) ) -> 2794929
A14: № | B14: года | C14: ='Данные для анализа'!D1 -> ВДС | D14: тренд | E14: довер.интервал | G14: тренд | H14: Ошибка | I14: Ошибка сорт.
A15: X | C15: Y | D15: Y^ | E15: низ | F15: верх | G15: ПРЕДСКАЗ() | H15: Err=Y - Y^ | I15: Err sort
A16: 1 | B16: 2002 | C16: ='Данные для анализа'!D2 -> 854871.15 | D16: =$D$4 + $D$5*$A16 -> -1508010.3 | E16: =$D16 - $C$12*(1 + ($A16-$A$39/2)^2 / (STDEVA($A$16:$A$39))^2 )^0.5 -> -6676740.1 | F16: =$D16 + $C$12*(1 + ($A16-$A$39/2)^2 / (STDEVA($A$16:$A$39))^2 )^0.5 -> 3660719.5 | G16: =FORECAST($A16,$C$16:$C$39,$A$16:$A$39) -> -1508010.3 | H16: =C16 - D16 -> 2362881.5 | I16: =SMALL($H$16:$H$39,A16) -> -2936519.2
A17: 2 | B17: 2003 | C17: ='Данные для анализа'!D3 -> 1139219.2 | D17: =$D$4 + $D$5*$A17 -> -706204.01 | E17: =$D17 - $C$12*(1 + ($A17-$A$39/2)^2 / (STDEVA($A$16:$A$39))^2 )^0.5 -> -5547163 | F17: =$D17 + $C$12*(1 + ($A17-$A$39/2)^2 / (STDEVA($A$16:$A$39))^2 )^0.5 -> 4134755 | G17: =FORECAST($A17,$C$16:$C$39,$A$16:$A$39) -> -706204.01 | H17: =C17 - D17 -> 1845423.3 | I17: =SMALL($H$16:$H$39,A17) -> -2804257.1
A18: 3 | B18: 2004 | C18: ='Данные для анализа'!D4 -> 1403738.5 | D18: =$D$4 + $D$5*$A18 -> 95602.319 | E18: =$D18 - $C$12*(1 + ($A18-$A$39/2)^2 / (STDEVA($A$16:$A$39))^2 )^0.5 -> -4428385.5 | F18: =$D18 + $C$12*(1 + ($A18-$A$39/2)^2 / (STDEVA($A$16:$A$39))^2 )^0.5 -> 4619590.1 | G18: =FORECAST($A18,$C$16:$C$39,$A$16:$A$39) -> 95602.319 | H18: =C18 - D18 -> 1308136.2 | I18: =SMALL($H$16:$H$39,A18) -> -2431023.3
A19: 4 | B19: 2005 | C19: ='Данные для анализа'!D5 -> 1677617.8 | D19: =$D$4 + $D$5*$A19 -> 897408.65 | E19: =$D19 - $C$12*(1 + ($A19-$A$39/2)^2 / (STDEVA($A$16:$A$39))^2 )^0.5 -> -3322841.6 | F19: =$D19 + $C$12*(1 + ($A19-$A$39/2)^2 / (STDEVA($A$16:$A$39))^2 )^0.5 -> 5117658.9 | G19: =FORECAST($A19,$C$16:$C$39,$A$16:$A$39) -> 897408.65 | H19: =C19 - D19 -> 780209.14 | I19: =SMALL($H$16:$H$39,A19) -> -2083797.5
A20: 5 | B20: 2006 | C20: ='Данные для анализа'!D6 -> 2080056.5 | D20: =$D$4 + $D$5*$A20 -> 1699215 | E20: =$D20 - $C$12*(1 + ($A20-$A$39/2)^2 / (STDEVA($A$16:$A$39))^2 )^0.5 -> -2233598.7 | F20: =$D20 + $C$12*(1 + ($A20-$A$39/2)^2 / (STDEVA($A$16:$A$39))^2 )^0.5 -> 5632028.7 | G20: =FORECAST($A20,$C$16:$C$39,$A$16:$A$39) -> 1699215 | H20: =C20 - D20 -> 380841.51 | I20: =SMALL($H$16:$H$39,A20) -> -1711528.9
A21: 6 | B21: 2007 | C21: ='Данные для анализа'!D7 -> 2564917.6 | D21: =$D$4 + $D$5*$A21 -> 2501021.3 | E21: =$D21 - $C$12*(1 + ($A21-$A$39/2)^2 / (STDEVA($A$16:$A$39))^2 )^0.5 -> -1164493.7 | F21: =$D21 + $C$12*(1 + ($A21-$A$39/2)^2 / (STDEVA($A$16:$A$39))^2 )^0.5 -> 6166536.3 | G21: =FORECAST($A21,$C$16:$C$39,$A$16:$A$39) -> 2501021.3 | H21: =C21 - D21 -> 63896.31 | I21: =SMALL($H$16:$H$39,A21) -> -1410795.7
A22: 7 | B22: 2008 | C22: ='Данные для анализа'!D8 -> 3296150.8 | D22: =$D$4 + $D$5*$A22 -> 3302827.6 | E22: =$D22 - $C$12*(1 + ($A22-$A$39/2)^2 / (STDEVA($A$16:$A$39))^2 )^0.5 -> -120247.29 | F22: =$D22 + $C$12*(1 + ($A22-$A$39/2)^2 / (STDEVA($A$16:$A$39))^2 )^0.5 -> 6725902.6 | G22: =FORECAST($A22,$C$16:$C$39,$A$16:$A$39) -> 3302827.6 | H22: =C22 - D22 -> -6676.8118 | I22: =SMALL($H$16:$H$39,A22) -> -1180278.7
A23: 8 | B23: 2009 | C23: ='Данные для анализа'!D9 -> 3853809.6 | D23: =$D$4 + $D$5*$A23 -> 4104634 | E23: =$D23 - $C$12*(1 + ($A23-$A$39/2)^2 / (STDEVA($A$16:$A$39))^2 )^0.5 -> 893505.05 | F23: =$D23 + $C$12*(1 + ($A23-$A$39/2)^2 / (STDEVA($A$16:$A$39))^2 )^0.5 -> 7315762.9 | G23: =FORECAST($A23,$C$16:$C$39,$A$16:$A$39) -> 4104634 | H23: =C23 - D23 -> -250824.42 | I23: =SMALL($H$16:$H$39,A23) -> -1032443.5
A24: 9 | B24: 2010 | C24: ='Данные для анализа'!D10 -> 4239214.9 | D24: =$D$4 + $D$5*$A24 -> 4906440.3 | E24: =$D24 - $C$12*(1 + ($A24-$A$39/2)^2 / (STDEVA($A$16:$A$39))^2 )^0.5 -> 1870370.3 | F24: =$D24 + $C$12*(1 + ($A24-$A$39/2)^2 / (STDEVA($A$16:$A$39))^2 )^0.5 -> 7942510.3 | G24: =FORECAST($A24,$C$16:$C$39,$A$16:$A$39) -> 4906440.3 | H24: =C24 - D24 -> -667225.36 | I24: =SMALL($H$16:$H$39,A24) -> -736843.1
A25: 10 | B25: 2011 | C25: ='Данные для анализа'!D11 -> 4675803.2 | D25: =$D$4 + $D$5*$A25 -> 5708246.6 | E25: =$D25 - $C$12*(1 + ($A25-$A$39/2)^2 / (STDEVA($A$16:$A$39))^2 )^0.5 -> 2803671.2 | F25: =$D25 + $C$12*(1 + ($A25-$A$39/2)^2 / (STDEVA($A$16:$A$39))^2 )^0.5 -> 8612822 | G25: =FORECAST($A25,$C$16:$C$39,$A$16:$A$39) -> 5708246.6 | H25: =C25 - D25 -> -1032443.5 | I25: =SMALL($H$16:$H$39,A25) -> -667225.36
A26: 11 | B26: 2012 | C26: ='Данные для анализа'!D12 -> 5864573.2 | D26: =$D$4 + $D$5*$A26 -> 6510053 | E26: =$D26 - $C$12*(1 + ($A26-$A$39/2)^2 / (STDEVA($A$16:$A$39))^2 )^0.5 -> 3687313.1 | F26: =$D26 + $C$12*(1 + ($A26-$A$39/2)^2 / (STDEVA($A$16:$A$39))^2 )^0.5 -> 9332792.9 | G26: =FORECAST($A26,$C$16:$C$39,$A$16:$A$39) -> 6510053 | H26: =C26 - D26 -> -645479.73 | I26: =SMALL($H$16:$H$39,A26) -> -645479.73
A27: 12 | B27: 2013 | C27: ='Данные для анализа'!D13 -> 6696500.4 | D27: =$D$4 + $D$5*$A27 -> 7311859.3 | E27: =$D27 - $C$12*(1 + ($A27-$A$39/2)^2 / (STDEVA($A$16:$A$39))^2 )^0.5 -> 4516930.3 | F27: =$D27 + $C$12*(1 + ($A27-$A$39/2)^2 / (STDEVA($A$16:$A$39))^2 )^0.5 -> 10106788 | G27: =FORECAST($A27,$C$16:$C$39,$A$16:$A$39) -> 7311859.3 | H27: =C27 - D27 -> -615358.93 | I27: =SMALL($H$16:$H$39,A27) -> -615358.93
... A39: 24 | B39: 2025 | C39: ='Данные для анализа'!D25 -> 22639157 | D39: =$D$4 + $D$5*$A39 -> 16933535 | E39: =$D39 - $C$12*(1 + ($A39-$A$39/2)^2 / (STDEVA($A$16:$A$39))^2 )^0.5 -> 11428164 | F39: =$D39 + $C$12*(1 + ($A39-$A$39/2)^2 / (STDEVA($A$16:$A$39))^2 )^0.5 -> 22438907 | G39: =FORECAST($A39,$C$16:$C$39,$A$16:$A$39) -> 16933535 | H39: =C39 - D39 -> 5705621.9 | I39: =SMALL($H$16:$H$39,A39) -> 5705621.9
A40: 25 | B40: 2026 | D40: =$D$4 + $D$5*$A40 -> 17735342 | E40: =$D40 - $C$12*(1 + ($A40-$A$39/2)^2 / (STDEVA($A$16:$A$39))^2 )^0.5 -> 11885989 | F40: =$D40 + $C$12*(1 + ($A40-$A$39/2)^2 / (STDEVA($A$16:$A$39))^2 )^0.5 -> 23584695 | G40: =FORECAST($A40,$C$16:$C$39,$A$16:$A$39) -> 17735342
A41: 26 | B41: 2027 | D41: =$D$4 + $D$5*$A41 -> 18537148 | E41: =$D41 - $C$12*(1 + ($A41-$A$39/2)^2 / (STDEVA($A$16:$A$39))^2 )^0.5 -> 12337696 | F41: =$D41 + $C$12*(1 + ($A41-$A$39/2)^2 / (STDEVA($A$16:$A$39))^2 )^0.5 -> 24736600 | G41: =FORECAST($A41,$C$16:$C$39,$A$16:$A$39) -> 18537148
A42: 27 | B42: 2028 | D42: =$D$4 + $D$5*$A42 -> 19338954 | E42: =$D42 - $C$12*(1 + ($A42-$A$39/2)^2 / (STDEVA($A$16:$A$39))^2 )^0.5 -> 12784265 | F42: =$D42 + $C$12*(1 + ($A42-$A$39/2)^2 / (STDEVA($A$16:$A$39))^2 )^0.5 -> 25893644 | G42: =FORECAST($A42,$C$16:$C$39,$A$16:$A$39) -> 19338954
A43: 28 | B43: 2029 | D43: =$D$4 + $D$5*$A43 -> 20140761 | E43: =$D43 - $C$12*(1 + ($A43-$A$39/2)^2 / (STDEVA($A$16:$A$39))^2 )^0.5 -> 13226488 | F43: =$D43 + $C$12*(1 + ($A43-$A$39/2)^2 / (STDEVA($A$16:$A$39))^2 )^0.5 -> 27055033 | G43: =FORECAST($A43,$C$16:$C$39,$A$16:$A$39) -> 20140761
A44: 29 | B44: 2030 | D44: =$D$4 + $D$5*$A44 -> 20942567 | E44: =$D44 - $C$12*(1 + ($A44-$A$39/2)^2 / (STDEVA($A$16:$A$39))^2 )^0.5 -> 13665010 | F44: =$D44 + $C$12*(1 + ($A44-$A$39/2)^2 / (STDEVA($A$16:$A$39))^2 )^0.5 -> 28220124 | G44: =FORECAST($A44,$C$16:$C$39,$A$16:$A$39) -> 20942567
A45: 30 | B45: 2031 | D45: =$D$4 + $D$5*$A45 -> 21744373 | E45: =$D45 - $C$12*(1 + ($A45-$A$39/2)^2 / (STDEVA($A$16:$A$39))^2 )^0.5 -> 14100357 | F45: =$D45 + $C$12*(1 + ($A45-$A$39/2)^2 / (STDEVA($A$16:$A$39))^2 )^0.5 -> 29388389 | G45: =FORECAST($A45,$C$16:$C$39,$A$16:$A$39) -> 21744373
A46: 31 | B46: 2032 | D46: =$D$4 + $D$5*$A46 -> 22546180 | E46: =$D46 - $C$12*(1 + ($A46-$A$39/2)^2 / (STDEVA($A$16:$A$39))^2 )^0.5 -> 14532967 | F46: =$D46 + $C$12*(1 + ($A46-$A$39/2)^2 / (STDEVA($A$16:$A$39))^2 )^0.5 -> 30559393 | G46: =FORECAST($A46,$C$16:$C$39,$A$16:$A$39) -> 22546180
A47: 32 | B47: 2033 | D47: =$D$4 + $D$5*$A47 -> 23347986 | E47: =$D47 - $C$12*(1 + ($A47-$A$39/2)^2 / (STDEVA($A$16:$A$39))^2 )^0.5 -> 14963199 | F47: =$D47 + $C$12*(1 + ($A47-$A$39/2)^2 / (STDEVA($A$16:$A$39))^2 )^0.5 -> 31732773 | G47: =FORECAST($A47,$C$16:$C$39,$A$16:$A$39) -> 23347986
A48: 33 | B48: 2034 | D48: =$D$4 + $D$5*$A48 -> 24149792 | E48: =$D48 - $C$12*(1 + ($A48-$A$39/2)^2 / (STDEVA($A$16:$A$39))^2 )^0.5 -> 15391357 | F48: =$D48 + $C$12*(1 + ($A48-$A$39/2)^2 / (STDEVA($A$16:$A$39))^2 )^0.5 -> 32908227 | G48: =FORECAST($A48,$C$16:$C$39,$A$16:$A$39) -> 24149792
A49: 34 | B49: 2035 | D49: =$D$4 + $D$5*$A49 -> 24951599 | E49: =$D49 - $C$12*(1 + ($A49-$A$39/2)^2 / (STDEVA($A$16:$A$39))^2 )^0.5 -> 15817695 | F49: =$D49 + $C$12*(1 + ($A49-$A$39/2)^2 / (STDEVA($A$16:$A$39))^2 )^0.5 -> 34085502 | G49: =FORECAST($A49,$C$16:$C$39,$A$16:$A$39) -> 24951599

Sheet ОФ
A1: Гиперпараметры:
B2: вид: | C2: линейная | D2: полином 2
B3: база: | C3: все данные
A4: 3 | B4: параметры: | C4: a= | D4: =INDEX(LINEST($C$17:$C$39,$A$17:$A$39^{1,2}),A4) -> 881411.94
A5: 2 | C5: b= | D5: =INDEX(LINEST($C$17:$C$39,$A$17:$A$39^{1,2}),A5) -> 22801.049
A6: 1 | C6: c= | D6: =INDEX(LINEST($C$17:$C$39,$A$17:$A$39^{1,2}),A6) -> 29801.854
B7: ошибка: | C7: разность
B8: критерий: | C8: сумма квадратов
B11: постоянство ширины: | C11: постоянная | E11: Предельные ошибки
E12: мин | F12: макс
E13: =MIN($H$17:$H$39) -> -2278695.2 | F13: =MAX($H$17:$H$39) -> 3096532.7
A15: № | B15: года | C15: ='Данные для анализа'!E1 -> ОФ | D15: тренд | E15: довер.интервал | G15: тренд | H15: Ошибка | I15: Ошибка сорт.
A16: X | C16: Y | D16: Y^ | E16: низ | F16: верх | G16: Тенденция() | H16: Err=Y - Y^ | I16: Err sort
A17: 1 | B17: 2002 | C17: ='Данные для анализа'!E2 -> 663998.76 | D17: =$D$4 + $D$5*$A17 + $D$6*A17^2 -> 934014.84 | E17: =$D17+ E$13 -> -1344680.3 | F17: =$D17+ F$13 -> 4030547.5 | G17: =TREND($C$17:$C$39,$A$17:$A$39^{1,2},$A17^{1,2}) -> 934014.84 | H17: =C17 - D17 -> -270016.08 | I17: =SMALL($H$17:$H$40,A17) -> -2278695.2
A18: 2 | B18: 2003 | C18: ='Данные для анализа'!E3 -> 884858.7 | D18: =$D$4 + $D$5*$A18 + $D$6*A18^2 -> 1046221.5 | E18: =$D18+ E$13 -> -1232473.7 | F18: =$D18+ F$13 -> 4142754.1 | G18: =TREND($C$17:$C$39,$A$17:$A$39^{1,2},$A18^{1,2}) -> 1046221.5 | H18: =C18 - D18 -> -161362.75 | I18: =SMALL($H$17:$H$40,A18) -> -2085116.9
A19: 3 | B19: 2004 | C19: ='Данные для анализа'!E4 -> 1090317.1 | D19: =$D$4 + $D$5*$A19 + $D$6*A19^2 -> 1218031.8 | E19: =$D19+ E$13 -> -1060663.4 | F19: =$D19+ F$13 -> 4314564.4 | G19: =TREND($C$17:$C$39,$A$17:$A$39^{1,2},$A19^{1,2}) -> 1218031.8 | H19: =C19 - D19 -> -127714.67 | I19: =SMALL($H$17:$H$40,A19) -> -1508705.6
A20: 4 | B20: 2005 | C20: ='Данные для анализа'!E5 -> 1303045.7 | D20: =$D$4 + $D$5*$A20 + $D$6*A20^2 -> 1449445.8 | E20: =$D20+ E$13 -> -829249.37 | F20: =$D20+ F$13 -> 4545978.5 | G20: =TREND($C$17:$C$39,$A$17:$A$39^{1,2},$A20^{1,2}) -> 1449445.8 | H20: =C20 - D20 -> -146400.15 | I20: =SMALL($H$17:$H$40,A20) -> -991897.99
A21: 5 | B21: 2006 | C21: ='Данные для анализа'!E6 -> 1615629.4 | D21: =$D$4 + $D$5*$A21 + $D$6*A21^2 -> 1740463.5 | E21: =$D21+ E$13 -> -538231.63 | F21: =$D21+ F$13 -> 4836996.2 | G21: =TREND($C$17:$C$39,$A$17:$A$39^{1,2},$A21^{1,2}) -> 1740463.5 | H21: =C21 - D21 -> -124834.17 | I21: =SMALL($H$17:$H$40,A21) -> -682865.25
A22: 6 | B22: 2007 | C22: ='Данные для анализа'!E7 -> 1992232.6 | D22: =$D$4 + $D$5*$A22 + $D$6*A22^2 -> 2091085 | E22: =$D22+ E$13 -> -187610.18 | F22: =$D22+ F$13 -> 5187617.7 | G22: =TREND($C$17:$C$39,$A$17:$A$39^{1,2},$A22^{1,2}) -> 2091085 | H22: =C22 - D22 -> -98852.434 | I22: =SMALL($H$17:$H$40,A22) -> -457800.27
A23: 7 | B23: 2008 | C23: ='Данные для анализа'!E8 -> 2560198.8 | D23: =$D$4 + $D$5*$A23 + $D$6*A23^2 -> 2501310.1 | E23: =$D23+ E$13 -> 222614.98 | F23: =$D23+ F$13 -> 5597842.8 | G23: =TREND($C$17:$C$39,$A$17:$A$39^{1,2},$A23^{1,2}) -> 2501310.1 | H23: =C23 - D23 -> 58888.646 | I23: =SMALL($H$17:$H$40,A23) -> -440216.34
A24: 8 | B24: 2009 | C24: ='Данные для анализа'!E9 -> 2993345.6 | D24: =$D$4 + $D$5*$A24 + $D$6*A24^2 -> 2971139 | E24: =$D24+ E$13 -> 692443.84 | F24: =$D24+ F$13 -> 6067671.7 | G24: =TREND($C$17:$C$39,$A$17:$A$39^{1,2},$A24^{1,2}) -> 2971139 | H24: =C24 - D24 -> 22206.583 | I24: =SMALL($H$17:$H$40,A24) -> -270016.08
A25: 9 | B25: 2010 | C25: ='Данные для анализа'!E10 -> 3292699.1 | D25: =$D$4 + $D$5*$A25 + $D$6*A25^2 -> 3500571.6 | E25: =$D25+ E$13 -> 1221876.4 | F25: =$D25+ F$13 -> 6597104.3 | G25: =TREND($C$17:$C$39,$A$17:$A$39^{1,2},$A25^{1,2}) -> 3500571.6 | H25: =C25 - D25 -> -207872.45 | I25: =SMALL($H$17:$H$40,A25) -> -207872.45
A26: 10 | B26: 2011 | C26: ='Данные для анализа'!E11 -> 3631807.6 | D26: =$D$4 + $D$5*$A26 + $D$6*A26^2 -> 4089607.9 | E26: =$D26+ E$13 -> 1810912.7 | F26: =$D26+ F$13 -> 7186140.5 | G26: =TREND($C$17:$C$39,$A$17:$A$39^{1,2},$A26^{1,2}) -> 4089607.9 | H26: =C26 - D26 -> -457800.27 | I26: =SMALL($H$17:$H$40,A26) -> -161362.75
A27: 11 | B27: 2012 | C27: ='Данные для анализа'!E12 -> 6188755.7 | D27: =$D$4 + $D$5*$A27 + $D$6*A27^2 -> 4738247.9 | E27: =$D27+ E$13 -> 2459552.7 | F27: =$D27+ F$13 -> 7834780.5 | G27: =TREND($C$17:$C$39,$A$17:$A$39^{1,2},$A27^{1,2}) -> 4738247.9 | H27: =C27 - D27 -> 1450507.9 | I27: =SMALL($H$17:$H$40,A27) -> -146400.15
A28: 12 | B28: 2013 | C28: ='Данные для анализа'!E13 -> 7066670.2 | D28: =$D$4 + $D$5*$A28 + $D$6*A28^2 -> 5446491.6 | E28: =$D28+ E$13 -> 3167796.4 | F28: =$D28+ F$13 -> 8543024.2 | G28: =TREND($C$17:$C$39,$A$17:$A$39^{1,2},$A28^{1,2}) -> 5446491.6 | H28: =C28 - D28 -> 1620178.7 | I28: =SMALL($H$17:$H$40,A28) -> -127714.67
... A39: 23 | B39: 2024 | C39: ='Данные для анализа'!E24 -> 20267550 | D39: =$D$4 + $D$5*$A39 + $D$6*A39^2 -> 17171017 | E39: =$D39+ E$13 -> 14892322 | F39: =$D39+ F$13 -> 20267550 | G39: =TREND($C$17:$C$39,$A$17:$A$39^{1,2},$A39^{1,2}) -> 17171017 | H39: =C39 - D39 -> 3096532.7 | I39: =SMALL($H$17:$H$40,A39) -> 3096532.7
A40: 24 | B40: 2025 | D40: =$D$4 + $D$5*$A40 + $D$6*A40^2 -> 18594505 | E40: =$D40+ E$13 -> 16315810 | F40: =$D40+ F$13 -> 21691038 | G40: =TREND($C$17:$C$39,$A$17:$A$39^{1,2},$A40^{1,2}) -> 18594505
A41: 25 | B41: 2026 | D41: =$D$4 + $D$5*$A41 + $D$6*A41^2 -> 20077597 | E41: =$D41+ E$13 -> 17798902 | F41: =$D41+ F$13 -> 23174130 | G41: =TREND($C$17:$C$39,$A$17:$A$39^{1,2},$A41^{1,2}) -> 20077597
A42: 26 | B42: 2027 | D42: =$D$4 + $D$5*$A42 + $D$6*A42^2 -> 21620293 | E42: =$D42+ E$13 -> 19341598 | F42: =$D42+ F$13 -> 24716825 | G42: =TREND($C$17:$C$39,$A$17:$A$39^{1,2},$A42^{1,2}) -> 21620293
A43: 27 | B43: 2028 | D43: =$D$4 + $D$5*$A43 + $D$6*A43^2 -> 23222592 | E43: =$D43+ E$13 -> 20943897 | F43: =$D43+ F$13 -> 26319125 | G43: =TREND($C$17:$C$39,$A$17:$A$39^{1,2},$A43^{1,2}) -> 23222592
A44: 28 | B44: 2029 | D44: =$D$4 + $D$5*$A44 + $D$6*A44^2 -> 24884495 | E44: =$D44+ E$13 -> 22605800 | F44: =$D44+ F$13 -> 27981028 | G44: =TREND($C$17:$C$39,$A$17:$A$39^{1,2},$A44^{1,2}) -> 24884495
A45: 29 | B45: 2030 | D45: =$D$4 + $D$5*$A45 + $D$6*A45^2 -> 26606002 | E45: =$D45+ E$13 -> 24327307 | F45: =$D45+ F$13 -> 29702535 | G45: =TREND($C$17:$C$39,$A$17:$A$39^{1,2},$A45^{1,2}) -> 26606002
A46: 30 | B46: 2031 | D46: =$D$4 + $D$5*$A46 + $D$6*A46^2 -> 28387112 | E46: =$D46+ E$13 -> 26108417 | F46: =$D46+ F$13 -> 31483645 | G46: =TREND($C$17:$C$39,$A$17:$A$39^{1,2},$A46^{1,2}) -> 28387112
A47: 31 | B47: 2032 | D47: =$D$4 + $D$5*$A47 + $D$6*A47^2 -> 30227827 | E47: =$D47+ E$13 -> 27949131 | F47: =$D47+ F$13 -> 33324359 | G47: =TREND($C$17:$C$39,$A$17:$A$39^{1,2},$A47^{1,2}) -> 30227827
A48: 32 | B48: 2033 | D48: =$D$4 + $D$5*$A48 + $D$6*A48^2 -> 32128144 | E48: =$D48+ E$13 -> 29849449 | F48: =$D48+ F$13 -> 35224677 | G48: =TREND($C$17:$C$39,$A$17:$A$39^{1,2},$A48^{1,2}) -> 32128144
A49: 33 | B49: 2034 | D49: =$D$4 + $D$5*$A49 + $D$6*A49^2 -> 34088066 | E49: =$D49+ E$13 -> 31809371 | F49: =$D49+ F$13 -> 37184599 | G49: =TREND($C$17:$C$39,$A$17:$A$39^{1,2},$A49^{1,2}) -> 34088066
